Workbook

Sheet W20
B3: 46146 | E3: Logistics | G3: Debox | I3: Blast Chiller in KG | K3: Plating Holding | M3: Plating (Tuesday) | O3: Sleeving | R3: Comments if problems
D4: Work Order | E4: Staged | F4: Comment | G4: Planned | H4: Actual | I4: Planned | J4: Actual | K4: Planned | L4: Actual | M4: Planned | N4: Actual | O4: 6440 | P4: Planned | Q4: Actual
A5: Day | B5: Rezept | C5: FV0472A - Indian Butter Chicken | M5: 6102 | O5: DE | P5: ='Planting KW 20'!I3
A6: Monday | B6: Sub | M6: Amount for 590kg | O6: NOR | P6: ='Planting KW 20'!G3
C7: Diced chicken - Butter Chicken Batch - BA | D7: 20-32 | E7: FALSE | F7: 590kg | I7: =O4*('MSKU INPUT (KW20)'!E438)/1000 | J7: =69+73+74+74 | L7: =69+73+74+74 | O7: BNL | P7: ='Planting KW 20'!E3
C8: Cauliflower rice - Cilantro and Lime Cauliflower Rice - BA | D8: 20-31 | E8: FALSE | I8: =O4*('MSKU INPUT (KW20)'!E470/1000) | J8: =29+29+29+28+22+26+27+20+9+30+24+26+26+25+30+28+14 | L8: =29+29+29+28+22+26+27+20+9+30+24+26+26+25+30+28+14
C9: Roasted Green Onions | D9: 20-33 | E9: FALSE | F9: 45kg | I9: =O4*('MSKU INPUT (KW20)'!E561/1000) | J9: =46+49 | L9: =46+49
C10: Sauce - Butter Chicken sauce | D10: 20-34 | E10: FALSE | I10: =O4*'MSKU INPUT (KW20)'!E560/1000 | J10: =108+109+93+107+107+106+106 | L10: =108+109+93+107+107+106+106
B12: 46146 | E12: Logistics | G12: Debox | I12: Blast Chiller | K12: Plating Holding | M12: Plating (Tuesday) | O12: Sleeving | R12: Comments if problems
D13: Work Order | E13: Staged | F13: Comment | G13: Planned | H13: Actual | I13: Planned | J13: Actual | K13: Planned | L13: Actual | M13: Planned | N13: Actual | O13: 1826 | P13: Planned | Q13: Actual
A14: Day | B14: Rezept | C14: FV0846A - Stroganoff-Style Beef Burger | M14: 1826 | O14: DE | P14: 521.77635
A15: Monday | B15: Sub | C15: Beef Burger Master EU | D15: 20-35 | E15: FALSE | I15: =O13*('MSKU INPUT (KW20)'!AG631/1000) | J15: 320 | L15: =93+81+78+68 | O15: NOR | P15: 463.99429
C16: Green Beans CUT 1-1/2 - Fresh - Less Salt | D16: 20-26 | E16: FALSE | I16: =O13*'MSKU INPUT (KW20)'!E594/1000 | J16: =30+20+16+27 | L16: =61+60+58+38 | O16: BNL | P16: 858.04187
C17: Herb-Parmesan Butter | D17: 20-27 | E17: FALSE | I17: =O13*('MSKU INPUT (KW20)'!E607/1000) | J17: 28 | L17: 61
C18: Loaded Roasted Sliced Mushrooms 1/2 green onion | D18: 20-28 | E18: FALSE | I18: =O13*'MSKU INPUT (KW20)'!E599/1000 | J18: =27+32+9+28+30 | L18: =58+63+23+60+61
C19: Roasted Green Onions | D19: 20-29 | E19: FALSE | F19: 12kg | I19: =O13*('MSKU INPUT (KW20)'!E593/1000) | J19: 10 | L19: 29
C20: Sauce for Beef Stroganoff - 1/2 garlic- No wine | D20: 20-30 | E20: FALSE | I20: =O13*'MSKU INPUT (KW20)'!E612/1000 | J20: =102+103 | L20: =102+103
B23: 46147 | E23: Logistics | G23: Debox | I23: Blast Chiller | K23: Plating Holding | M23: Plating (Wednesday) | O23: Sleeving | R23: Comments if problems
D24: Work Order | E24: Staged | F24: Comment | G24: Planned | H24: Actual | I24: Planned | J24: Actual | K24: Planned | L24: Actual | M24: Planned | N24: Actual | P24: Planned | Q24: Actual
A25: Day | B25: Rezept | C25: FV0281A - Baja Salmon | M25: ='Planting KW 20'!N5 | O25: DE | P25: ='Planting KW 20'!I5
A26: Tuesday | B26: Sub | O26: NOR | P26: ='Planting KW 20'!G5
C27: Mexican Cauliflower Rice | D27: 20-17 | E27: FALSE | I27: =('MSKU INPUT (KW20)'!E188/1000)*(M25) | O27: BNL | P27: ='Planting KW 20'!E5
C28: Salmon - BAJA Salmon - Batch | D28: 20-18 | E28: FALSE | I28: =((SUM('MSKU INPUT (KW20)'!AE197:AE208)*Median('MSKU INPUT (KW20)'!AD197:AD208))/1000)*M25
C29: Compound butter - Chili-Garlic Butter - master batch | D29: 20-16 | E29: FALSE | I29: ='MSKU INPUT (KW20)'!E209/1000*M25
C30: Sauce - Cilantro Sour Cream | D30: 20-19 | E30: FALSE | I30: ='MSKU INPUT (KW20)'!E220/1000*M25
C31: Broccoli - S&P Broccoli FLORETS - less salt | D31: 20-14 | E31: FALSE | I31: ='MSKU INPUT (KW20)'!E219/1000*M25
B33: 46147 | E33: Logistics | G33: Debox | I33: Blast Chiller | K33: Plating Holding | M33: Plating (Wednesday) | O33: Sleeving | R33: Comments if problems
D34: Work Order | E34: Staged | F34: Comment | G34: Planned | H34: Actual | I34: Planned | J34: Actual | K34: Planned | L34: Actual | M34: Planned | N34: Actual | P34: Planned | Q34: Actual
A35: Day | B35: Rezept | C35: FV0333A - Tuscan Shrimp | M35: ='Planting KW 20'!N6 | O35: DE | P35: ='Planting KW 20'!I6
A36: Tuesday | B36: Sub | E36: FALSE | O36: NOR | P36: ='Planting KW 20'!G6
C37: Tuscan Shrimp batch | D37: 20-23 | E37: FALSE | I37: ='MSKU INPUT (KW20)'!AG313/1000*M35 | O37: BNL | P37: ='Planting KW 20'!E6
C38: Creamed Kale - Cream Cheese | D38: 20-21 | E38: FALSE | I38: ='MSKU INPUT (KW20)'!E311/1000*M35
C39: Sauce - Tuscan Shrimp Butter Sauce | D39: 20-22 | E39: FALSE | I39: ='MSKU INPUT (KW20)'!E323/1000*M35
C40: Zucchini/Pepper/Onion Mix for Tuscan Shrimp - 1/2 Diced | D40: 20-24 | E40: FALSE | I40: ='MSKU INPUT (KW20)'!E334/1000*M35
B42: 46148 | E42: Logistics | G42: Debox | I42: Blast Chiller | K42: Plating Holding | M42: Plating (Thursday) | O42: Sleeving | R42: Comments if problems
D43: Work Order | E43: Staged | F43: Comment | G43: Planned | H43: Actual | I43: Planned | J43: Actual | K43: Planned | L43: Actual | M43: Planned | N43: Actual | P43: Planned | Q43: Actual
A44: Day | B44: Rezept | C44: FV0035A - Salmon with pesto | M44: ='Planting KW 20'!N3 | O44: DE | P44: ='Planting KW 20'!I7
A45: Wendsday | B45: Sub | E45: FALSE | O45: NOR | P45: ='Planting KW 20'!G7
C46: Salmon - garlic seasoning | D46: 20-53 | E46: FALSE | O46: BNL | P46: ='Planting KW 20'!E7
C47: Compound butter - Sun-Dried Tomato | D47: 20-56 | E47: FALSE
...

Sheet Input 

Sheet MSKU INPUT (KW20)
A1: Recipe Name | B1: Recipe ID | C1: Sub-Recipe 1 Name | D1: Sub-Recipe 1 ID | E1: Sub-Recipe 1 Quantity | F1: Sub-Recipe 1 UOM | G1: Sub-Recipe 1 Recipe Categories | H1: Sub-Recipe 2 Name | I1: Sub-Recipe 2 ID | J1: Sub-Recipe 2 Quantity | K1: Sub-Recipe 2 UOM | L1: Sub-Recipe 2 Recipe Categories | M1: Sub-Recipe 3 Name | N1: Sub-Recipe 3 ID | O1: Sub-Recipe 3 Quantity | P1: Sub-Recipe 3 UOM | Q1: Sub-Recipe 3 Recipe Categories | R1: Sub-Recipe 4 Name | S1: Sub-Recipe 4 ID | T1: Sub-Recipe 4 Quantity | U1: Sub-Recipe 4 UOM | V1: Sub-Recipe 4 Recipe Categories | W1: Ingredient | X1: Ingredient ID | Y1: Gross Ingredient Qty | Z1: Net Ingredient Qty | AA1: Ingredient UOM | AB1: Ingredient Allergen Type | AC1: Sub Allergen Type | AD1: Sub-Recipe Yield % | AE1: Qty Converted to Weight | AF1: Qty Unit
A2: FV0024A - Chicken in tomato cream sauce [BNL] | B2: REC-013938-4-007 | C2: Sauce - Sun-Dried Tomato Sauce - Less Salt | D2: SUB-013571-4-001 | E2: 140 | F2: grams | G2: BLAST CHILLER, BRAISER, IMMERSION BLENDER, SPICE PORTIONING | W2: FA-DE Cheese, Parmesan, Grated /Käse, Parmesan, gerieben | X2: DAI-00-139127-3 | Y2: 14,55 | Z2: 14,55 | AA2: grams | AB2: MILCH (EINSCHLIESSLICH LAKTOSE) | AD2: 0.88017 | AE2: 14.55 | AF2: grams
A3: FV0024A - Chicken in tomato cream sauce [BNL] | B3: REC-013938-4-007 | C3: Sauce - Sun-Dried Tomato Sauce - Less Salt | D3: SUB-013571-4-001 | E3: 140 | F3: grams | G3: BLAST CHILLER, BRAISER, IMMERSION BLENDER, SPICE PORTIONING | W3: FA-DE Oil, Olive /Öl, Olivenöl | X3: PRO-00-139277-5 | Y3: 8,29 | Z3: 8,29 | AA3: grams | AD3: 0.88017 | AE3: 8.29 | AF3: grams
A4: FV0024A - Chicken in tomato cream sauce [BNL] | B4: REC-013938-4-007 | C4: Sauce - Sun-Dried Tomato Sauce - Less Salt | D4: SUB-013571-4-001 | E4: 140 | F4: grams | G4: BLAST CHILLER, BRAISER, IMMERSION BLENDER, SPICE PORTIONING | W4: FA-DE Stock, Chicken, Reduced/Brühe, Huhn, Reduziert | X4: PRO-00-139288-5 | Y4: 1,63 | Z4: 1,63 | AA4: grams | AD4: 0.88017 | AE4: 1.63 | AF4: grams
A5: FV0024A - Chicken in tomato cream sauce [BNL] | B5: REC-013938-4-007 | C5: Sauce - Sun-Dried Tomato Sauce - Less Salt | D5: SUB-013571-4-001 | E5: 140 | F5: grams | G5: BLAST CHILLER, BRAISER, IMMERSION BLENDER, SPICE PORTIONING | W5: FA-DE Garlic, IQF, Diced 4 mm /Knoblauch, IQF, gewürfelt 4 mm | X5: PHF-00-139237-1 | Y5: 3,31 | Z5: 3,31 | AA5: grams | AB5: SCHWEFELDIOXIDE UND SULFITE | AD5: 0.88017 | AE5: 3.31 | AF5: grams
A6: FV0024A - Chicken in tomato cream sauce [BNL] | B6: REC-013938-4-007 | C6: Sauce - Sun-Dried Tomato Sauce - Less Salt | D6: SUB-013571-4-001 | E6: 140 | F6: grams | G6: BLAST CHILLER, BRAISER, IMMERSION BLENDER, SPICE PORTIONING | H6: Hydrated Sun-Dried Tomatoes | I6: SUB-013501-4-001 | J6: 14.53 | K6: grams | L6: BRAISER | W6: FA-DE Tomatoes, Sun - Dried Julienned /Tomaten, sonnengetrocknete Julienne | X6: PRO-00-139296-5 | Y6: 8,07 | Z6: 8,07 | AA6: grams | AD6: 0.90001 | AE6: 8.07 | AF6: grams
A7: FV0024A - Chicken in tomato cream sauce [BNL] | B7: REC-013938-4-007 | C7: Sauce - Sun-Dried Tomato Sauce - Less Salt | D7: SUB-013571-4-001 | E7: 140 | F7: grams | G7: BLAST CHILLER, BRAISER, IMMERSION BLENDER, SPICE PORTIONING | H7: Hydrated Sun-Dried Tomatoes | I7: SUB-013501-4-001 | J7: 14.53 | K7: grams | L7: BRAISER | U7: =SUM(Z2:Z11) | W7: FA-DE Water / Wasser | X7: OTH-00-144038-5 | Y7: 8,07 | Z7: 8,07 | AA7: grams | AD7: 0.90001 | AE7: 8.07 | AF7: grams
A8: FV0024A - Chicken in tomato cream sauce [BNL] | B8: REC-013938-4-007 | C8: Sauce - Sun-Dried Tomato Sauce - Less Salt | D8: SUB-013571-4-001 | E8: 140 | F8: grams | G8: BLAST CHILLER, BRAISER, IMMERSION BLENDER, SPICE PORTIONING | W8: FA-DE Spinach, Fresh, Stem Off /Spinat, frisch, ohne Stiel | X8: PHF-00-139225-3 | Y8: 11,64 | Z8: 11,64 | AA8: grams | AD8: 0.88017 | AE8: 11.64 | AF8: grams
A9: FV0024A - Chicken in tomato cream sauce [BNL] | B9: REC-013938-4-007 | C9: Sauce - Sun-Dried Tomato Sauce - Less Salt | D9: SUB-013571-4-001 | E9: 140 | F9: grams | G9: BLAST CHILLER, BRAISER, IMMERSION BLENDER, SPICE PORTIONING | W9: FA-DE Spice, Sea Salt /Gewürze, Meersalz | X9: SPI-00-139378-5 | Y9: 0,07 | Z9: 0,07 | AA9: grams | AD9: 0.88017 | AE9: 0.07 | AF9: grams
A10: FV0024A - Chicken in tomato cream sauce [BNL] | B10: REC-013938-4-007 | C10: Sauce - Sun-Dried Tomato Sauce - Less Salt | D10: SUB-013571-4-001 | E10: 140 | F10: grams | G10: BLAST CHILLER, BRAISER, IMMERSION BLENDER, SPICE PORTIONING | W10: FA-DE Onion, Spanish, Diced 5mm /Zwiebel, Spanisch, gewürfelt 5 mm | X10: PHF-00-139212-3 | Y10: 14,55 | Z10: 14,55 | AA10: grams | AD10: 0.88017 | AE10: 14.55 | AF10: grams
A11: FV0024A - Chicken in tomato cream sauce [BNL] | B11: REC-013938-4-007 | C11: Sauce - Sun-Dried Tomato Sauce - Less Salt | D11: SUB-013571-4-001 | E11: 140 | F11: grams | G11: BLAST CHILLER, BRAISER, IMMERSION BLENDER, SPICE PORTIONING | W11: FA-DE Heavy Cream 20% /Sahne 20% | X11: DAI-00-139137-3 | Y11: 90,49 | Z11: 90,49 | AA11: grams | AB11: MILCH (EINSCHLIESSLICH LAKTOSE) | AD11: 0.88017 | AE11: 90.49 | AF11: grams
A12: FV0024A - Chicken in tomato cream sauce [BNL] | B12: REC-013938-4-007 | C12: Chicken breast - Sun-Dried Tomato Chicken Batch - Grilled 160g | D12: SUB-013572-4-001 | E12: 1 | F12: each | G12: BLAST CHILLER, GRILL, MARINADE, OVEN | W12: FA-DE Spice, Black Pepper, Ground /Gewürz, schwarzer Pfeffer, gemahlen | X12: SPI-00-139334-5 | Y12: 0,14 | Z12: 0,14 | AA12: grams | AD12: 0.7011 | AE12: 0.14 | AF12: grams
A13: FV0024A - Chicken in tomato cream sauce [BNL] | B13: REC-013938-4-007 | C13: Chicken breast - Sun-Dried Tomato Chicken Batch - Grilled 160g | D13: SUB-013572-4-001 | E13: 1 | F13: each | G13: BLAST CHILLER, GRILL, MARINADE, OVEN | W13: FA-DE Spice, Oregano Dry /Gewürz, Oregano trocken | X13: SPI-00-139372-5 | Y13: 0,14 | Z13: 0,14 | AA13: grams | AD13: 0.7011 | AE13: 0.14 | AF13: grams
A14: FV0024A - Chicken in tomato cream sauce [BNL] | B14: REC-013938-4-007 | C14: Chicken breast - Sun-Dried Tomato Chicken Batch - Grilled 160g | D14: SUB-013572-4-001 | E14: 1 | F14: each | G14: BLAST CHILLER, GRILL, MARINADE, OVEN | W14: FA-DE Spice, Onion Granulated /Gewürze, Zwiebeln granuliert | X14: SPI-00-139370-5 | Y14: 0,23 | Z14: 0,23 | AA14: grams | AD14: 0.7011 | AE14: 0.23 | AF14: grams
A15: FV0024A - Chicken in tomato cream sauce [BNL] | B15: REC-013938-4-007 | C15: Chicken breast - Sun-Dried Tomato Chicken Batch - Grilled 160g | D15: SUB-013572-4-001 | E15: 1 | F15: each | G15: BLAST CHILLER, GRILL, MARINADE, OVEN | W15: FA-DE Spice, Crushed Red Pepper Flakes /Gewürz, zerkleinerte rote Pfefferflocken | X15: SPI-00-139344-5 | Y15: 0,09 | Z15: 0,09 | AA15: grams | AD15: 0.7011 | AE15: 0.09 | AF15: grams
A16: FV0024A - Chicken in tomato cream sauce [BNL] | B16: REC-013938-4-007 | C16: Chicken breast - Sun-Dried Tomato Chicken Batch - Grilled 160g | D16: SUB-013572-4-001 | E16: 1 | F16: each | G16: BLAST CHILLER, GRILL, MARINADE, OVEN | W16: FA-DE Spice, Garlic Granulated /Gewürz, Knoblauch granuliert | X16: SPI-00-139353-5 | Y16: 0,43 | Z16: 0,43 | AA16: grams | AD16: 0.7011 | AE16: 0.43 | AF16: grams
A17: FV0024A - Chicken in tomato cream sauce [BNL] | B17: REC-013938-4-007 | C17: Chicken breast - Sun-Dried Tomato Chicken Batch - Grilled 160g | D17: SUB-013572-4-001 | E17: 1 | F17: each | G17: BLAST CHILLER, GRILL, MARINADE, OVEN | W17: FA-DE Vinegar, Red Wine /Essig, Rotwein | X17: PRO-00-139301-5 | Y17: 2,3 | Z17: 2,3 | AA17: grams | AD17: 0.7011 | AE17: 2.3 | AF17: grams
A18: FV0024A - Chicken in tomato cream sauce [BNL] | B18: REC-013938-4-007 | C18: Chicken breast - Sun-Dried Tomato Chicken Batch - Grilled 160g | D18: SUB-013572-4-001 | E18: 1 | F18: each | G18: BLAST CHILLER, GRILL, MARINADE, OVEN | H18: Chicken Breast - BRINED 160g | I18: SUB-013527-4-001 | J18: 160 | K18: grams | L18: BRINE | W18: FA-DE Chicken, Breast, B/S - 160g/Hähnchen, Brust, B/S – 160 g | X18: PTN-00-139317-3 | Y18: 160 | Z18: 160 | AA18: grams | AD18: 0.4978 | AE18: 160 | AF18: grams
A19: FV0024A - Chicken in tomato cream sauce [BNL] | B19: REC-013938-4-007 | C19: Chicken breast - Sun-Dried Tomato Chicken Batch - Grilled 160g | D19: SUB-013572-4-001 | E19: 1 | F19: each | G19: BLAST CHILLER, GRILL, MARINADE, OVEN | H19: Chicken Breast - BRINED 160g | I19: SUB-013527-4-001 | J19: 160 | K19: grams | L19: BRINE | W19: FA-DE Water / Wasser | X19: OTH-00-144038-5 | Y19: 160 | Z19: 160 | AA19: grams | AD19: 0.4978 | AE19: 160 | AF19: grams
A20: FV0024A - Chicken in tomato cream sauce [BNL] | B20: REC-013938-4-007 | C20: Chicken breast - Sun-Dried Tomato Chicken Batch - Grilled 160g | D20: SUB-013572-4-001 | E20: 1 | F20: each | G20: BLAST CHILLER, GRILL, MARINADE, OVEN | H20: Chicken Breast - BRINED 160g | I20: SUB-013527-4-001 | J20: 160 | K20: grams | L20: BRINE | W20: FA-DE Spice, Sea Salt /Gewürze, Meersalz | X20: SPI-00-139378-5 | Y20: 1,41 | Z20: 1,41 | AA20: grams | AD20: 0.4978 | AE20: 1.41 | AF20: grams
A21: FV0024A - Chicken in tomato cream sauce [BNL] | B21: REC-013938-4-007 | C21: Chicken breast - Sun-Dried Tomato Chicken Batch - Grilled 160g | D21: SUB-013572-4-001 | E21: 1 | F21: each | G21: BLAST CHILLER, GRILL, MARINADE, OVEN | W21: FA-DE Parsley, Chopped /Petersilie, gehackt | X21: PHF-00-139215-3 | Y21: 0,46 | Z21: 0,46 | AA21: grams | AD21: 0.7011 | AE21: 0.46 | AF21: grams
A22: FV0024A - Chicken in tomato cream sauce [BNL] | B22: REC-013938-4-007 | C22: Chicken breast - Sun-Dried Tomato Chicken Batch - Grilled 160g | D22: SUB-013572-4-001 | E22: 1 | F22: each | G22: BLAST CHILLER, GRILL, MARINADE, OVEN | W22: FA-DE Oil, Olive /Öl, Olivenöl | X22: PRO-00-139277-5 | Y22: 6,8 | Z22: 6,8 | AA22: grams | AD22: 0.7011 | AE22: 6.8 | AF22: grams
A23: FV0024A - Chicken in tomato cream sauce [BNL] | B23: REC-013938-4-007 | C23: Chicken breast - Sun-Dried Tomato Chicken Batch - Grilled 160g | D23: SUB-013572-4-001 | E23: 1 | F23: each | G23: BLAST CHILLER, GRILL, MARINADE, OVEN | H23: Basil - Picked Basil Leaves | I23: SUB-013424-4-001 | J23: 0.57 | K23: grams | L23: DEBOX, STAGING | W23: FA-DE Basil, Fresh /Basilikum, frisch | X23: PHF-00-139175-3 | Y23: 1,02 | Z23: 1,02 | AA23: grams | AD23: 0.55986 | AE23: 1.02 | AF23: grams
A24: FV0024A - Chicken in tomato cream sauce [BNL] | B24: REC-013938-4-007 | C24: Cooked Courgette Noodles - No Salt | D24: SUB-013573-4-001 | E24: 100 | F24: grams | G24: BLAST CHILLER, HAND MARINADE, OVEN | W24: FA-DE Oil, Olive /Öl, Olivenöl | X24: PRO-00-139277-5 | Y24: 8,07 | Z24: 8,07 | AA24: grams | AD24: 0.68363 | AE24: 8.07 | AF24: grams
A25: FV0024A - Chicken in tomato cream sauce [BNL] | B25: REC-013938-4-007 | C25: Cooked Courgette Noodles - No Salt | D25: SUB-013573-4-001 | E25: 100 | F25: grams | G25: BLAST CHILLER, HAND MARINADE, OVEN | W25: FA-DE Zucchini, Spiralized Noodles /Zucchini, Spiralnudeln | X25: PHF-00-139230-3 | Y25: 138,21 | Z25: 138,21 | AA25: grams | AD25: 0.68363 | AE25: 138.21 | AF25: grams
A26: FV0024A - Chicken in tomato cream sauce [DE] | B26: REC-013938-4-005 | C26: Sauce - Sun-Dried Tomato Sauce - Less Salt | D26: SUB-013571-4-001 | E26: 140 | F26: grams | G26: BLAST CHILLER, BRAISER, IMMERSION BLENDER, SPICE PORTIONING | W26: FA-DE Cheese, Parmesan, Grated /Käse, Parmesan, gerieben | X26: DAI-00-139127-3 | Y26: 14,55 | Z26: 14,55 | AA26: grams | AB26: MILCH (EINSCHLIESSLICH LAKTOSE) | AD26: 0.88017 | AE26: 14.55 | AF26: grams
A27: FV0024A - Chicken in tomato cream sauce [DE] | B27: REC-013938-4-005 | C27: Sauce - Sun-Dried Tomato Sauce - Less Salt | D27: SUB-013571-4-001 | E27: 140 | F27: grams | G27: BLAST CHILLER, BRAISER, IMMERSION BLENDER, SPICE PORTIONING | W27: FA-DE Oil, Olive /Öl, Olivenöl | X27: PRO-00-139277-5 | Y27: 8,29 | Z27: 8,29 | AA27: grams | AD27: 0.88017 | AE27: 8.29 | AF27: grams
A28: FV0024A - Chicken in tomato cream sauce [DE] | B28: REC-013938-4-005 | C28: Sauce - Sun-Dried Tomato Sauce - Less Salt | D28: SUB-013571-4-001 | E28: 140 | F28: grams | G28: BLAST CHILLER, BRAISER, IMMERSION BLENDER, SPICE PORTIONING | W28: FA-DE Stock, Chicken, Reduced/Brühe, Huhn, Reduziert | X28: PRO-00-139288-5 | Y28: 1,63 | Z28: 1,63 | AA28: grams | AD28: 0.88017 | AE28: 1.63 | AF28: grams
A29: FV0024A - Chicken in tomato cream sauce [DE] | B29: REC-013938-4-005 | C29: Sauce - Sun-Dried Tomato Sauce - Less Salt | D29: SUB-013571-4-001 | E29: 140 | F29: grams | G29: BLAST CHILLER, BRAISER, IMMERSION BLENDER, SPICE PORTIONING | W29: FA-DE Garlic, IQF, Diced 4 mm /Knoblauch, IQF, gewürfelt 4 mm | X29: PHF-00-139237-1 | Y29: 3,31 | Z29: 3,31 | AA29: grams | AB29: SCHWEFELDIOXIDE UND SULFITE | AD29: 0.88017 | AE29: 3.31 | AF29: grams
A30: FV0024A - Chicken in tomato cream sauce [DE] | B30: REC-013938-4-005 | C30: Sauce - Sun-Dried Tomato Sauce - Less Salt | D30: SUB-013571-4-001 | E30: 140 | F30: grams | G30: BLAST CHILLER, BRAISER, IMMERSION BLENDER, SPICE PORTIONING | H30: Hydrated Sun-Dried Tomatoes | I30: SUB-013501-4-001 | J30: 14.53 | K30: grams | L30: BRAISER | W30: FA-DE Tomatoes, Sun - Dried Julienned /Tomaten, sonnengetrocknete Julienne | X30: PRO-00-139296-5 | Y30: 8,07 | Z30: 8,07 | AA30: grams | AD30: 0.90001 | AE30: 8.07 | AF30: grams
A31: FV0024A - Chicken in tomato cream sauce [DE] | B31: REC-013938-4-005 | C31: Sauce - Sun-Dried Tomato Sauce - Less Salt | D31: SUB-013571-4-001 | E31: 140 | F31: grams | G31: BLAST CHILLER, BRAISER, IMMERSION BLENDER, SPICE PORTIONING | H31: Hydrated Sun-Dried Tomatoes | I31: SUB-013501-4-001 | J31: 14.53 | K31: grams | L31: BRAISER | W31: FA-DE Water / Wasser | X31: OTH-00-144038-5 | Y31: 8,07 | Z31: 8,07 | AA31: grams | AD31: 0.90001 | AE31: 8.07 | AF31: grams
A32: FV0024A - Chicken in tomato cream sauce [DE] | B32: REC-013938-4-005 | C32: Sauce - Sun-Dried Tomato Sauce - Less Salt | D32: SUB-013571-4-001 | E32: 140 | F32: grams | G32: BLAST CHILLER, BRAISER, IMMERSION BLENDER, SPICE PORTIONING | W32: FA-DE Spinach, Fresh, Stem Off /Spinat, frisch, ohne Stiel | X32: PHF-00-139225-3 | Y32: 11,64 | Z32: 11,64 | AA32: grams | AD32: 0.88017 | AE32: 11.64 | AF32: grams
A33: FV0024A - Chicken in tomato cream sauce [DE] | B33: REC-013938-4-005 | C33: Sauce - Sun-Dried Tomato Sauce - Less Salt | D33: SUB-013571-4-001 | E33: 140 | F33: grams | G33: BLAST CHILLER, BRAISER, IMMERSION BLENDER, SPICE PORTIONING | W33: FA-DE Spice, Sea Salt /Gewürze, Meersalz | X33: SPI-00-139378-5 | Y33: 0,07 | Z33: 0,07 | AA33: grams | AD33: 0.88017 | AE33: 0.07 | AF33: grams
A34: FV0024A - Chicken in tomato cream sauce [DE] | B34: REC-013938-4-005 | C34: Sauce - Sun-Dried Tomato Sauce - Less Salt | D34: SUB-013571-4-001 | E34: 140 | F34: grams | G34: BLAST CHILLER, BRAISER, IMMERSION BLENDER, SPICE PORTIONING | W34: FA-DE Onion, Spanish, Diced 5mm /Zwiebel, Spanisch, gewürfelt 5 mm | X34: PHF-00-139212-3 | Y34: 14,55 | Z34: 14,55 | AA34: grams | AD34: 0.88017 | AE34: 14.55 | AF34: grams
A35: FV0024A - Chicken in tomato cream sauce [DE] | B35: REC-013938-4-005 | C35: Sauce - Sun-Dried Tomato Sauce - Less Salt | D35: SUB-013571-4-001 | E35: 140 | F35: grams | G35: BLAST CHILLER, BRAISER, IMMERSION BLENDER, SPICE PORTIONING | W35: FA-DE Heavy Cream 20% /Sahne 20% | X35: DAI-00-139137-3 | Y35: 90,49 | Z35: 90,49 | AA35: grams | AB35: MILCH (EINSCHLIESSLICH LAKTOSE) | AD35: 0.88017 | AE35: 90.49 | AF35: grams
A36: FV0024A - Chicken in tomato cream sauce [DE] | B36: REC-013938-4-005 | C36: Chicken breast - Sun-Dried Tomato Chicken Batch - Grilled 160g | D36: SUB-013572-4-001 | E36: 1 | F36: each | G36: BLAST CHILLER, GRILL, MARINADE, OVEN | W36: FA-DE Spice, Black Pepper, Ground /Gewürz, schwarzer Pfeffer, gemahlen | X36: SPI-00-139334-5 | Y36: 0,14 | Z36: 0,14 | AA36: grams | AD36: 0.7011 | AE36: 0.14 | AF36: grams
A37: FV0024A - Chicken in tomato cream sauce [DE] | B37: REC-013938-4-005 | C37: Chicken breast - Sun-Dried Tomato Chicken Batch - Grilled 160g | D37: SUB-013572-4-001 | E37: 1 | F37: each | G37: BLAST CHILLER, GRILL, MARINADE, OVEN | W37: FA-DE Spice, Oregano Dry /Gewürz, Oregano trocken | X37: SPI-00-139372-5 | Y37: 0,14 | Z37: 0,14 | AA37: grams | AD37: 0.7011 | AE37: 0.14 | AF37: grams
A38: FV0024A - Chicken in tomato cream sauce [DE] | B38: REC-013938-4-005 | C38: Chicken breast - Sun-Dried Tomato Chicken Batch - Grilled 160g | D38: SUB-013572-4-001 | E38: 1 | F38: each | G38: BLAST CHILLER, GRILL, MARINADE, OVEN | W38: FA-DE Spice, Onion Granulated /Gewürze, Zwiebeln granuliert | X38: SPI-00-139370-5 | Y38: 0,23 | Z38: 0,23 | AA38: grams | AD38: 0.7011 | AE38: 0.23 | AF38: grams
A39: FV0024A - Chicken in tomato cream sauce [DE] | B39: REC-013938-4-005 | C39: Chicken breast - Sun-Dried Tomato Chicken Batch - Grilled 160g | D39: SUB-013572-4-001 | E39: 1 | F39: each | G39: BLAST CHILLER, GRILL, MARINADE, OVEN | W39: FA-DE Spice, Crushed Red Pepper Flakes /Gewürz, zerkleinerte rote Pfefferflocken | X39: SPI-00-139344-5 | Y39: 0,09 | Z39: 0,09 | AA39: grams | AD39: 0.7011 | AE39: 0.09 | AF39: grams
A40: FV0024A - Chicken in tomato cream sauce [DE] | B40: REC-013938-4-005 | C40: Chicken breast - Sun-Dried Tomato Chicken Batch - Grilled 160g | D40: SUB-013572-4-001 | E40: 1 | F40: each | G40: BLAST CHILLER, GRILL, MARINADE, OVEN | W40: FA-DE Spice, Garlic Granulated /Gewürz, Knoblauch granuliert | X40: SPI-00-139353-5 | Y40: 0,43 | Z40: 0,43 | AA40: grams | AD40: 0.7011 | AE40: 0.43 | AF40: grams
...

Sheet Planting KW 20
A1: =IFERROR(__xludf.DUMMYFUNCTION("IMPORTRANGE(""https://docs.google.com/spreadsheets/d/13lZfV1HAcVuOAxd9-xHCEsxO0wHmPnJNl9NuoURpM6U/edit?gid=1819627895#gid=1819627895"",""Plating!A:BB"")"),"") | R1: =IFERROR(__xludf.DUMMYFUNCTION("""COMPUTED_VALUE"""),"Avg. plates/h")
A2: =IFERROR(__xludf.DUMMYFUNCTION("""COMPUTED_VALUE"""),"Plating Day") | B2: =IFERROR(__xludf.DUMMYFUNCTION("""COMPUTED_VALUE"""),"Recipe Name") | C2: =IFERROR(__xludf.DUMMYFUNCTION("""COMPUTED_VALUE"""),"Total Amount") | D2: =IFERROR(__xludf.DUMMYFUNCTION("""COMPUTED_VALUE"""),"Runtime/h") | E2: =IFERROR(__xludf.DUMMYFUNCTION("""COMPUTED_VALUE"""),"BENL") | F2: =IFERROR(__xludf.DUMMYFUNCTION("""COMPUTED_VALUE"""),"Runtime/h") | G2: =IFERROR(__xludf.DUMMYFUNCTION("""COMPUTED_VALUE"""),"NORD") | H2: =IFERROR(__xludf.DUMMYFUNCTION("""COMPUTED_VALUE"""),"Runtime/h") | I2: =IFERROR(__xludf.DUMMYFUNCTION("""COMPUTED_VALUE"""),"DE") | J2: =IFERROR(__xludf.DUMMYFUNCTION("""COMPUTED_VALUE"""),"Customer Order Forecast") | K2: =IFERROR(__xludf.DUMMYFUNCTION("""COMPUTED_VALUE"""),"Runs") | N2: =IFERROR(__xludf.DUMMYFUNCTION("""COMPUTED_VALUE"""),0.1) | O2: =IFERROR(__xludf.DUMMYFUNCTION("""COMPUTED_VALUE"""),0.15) | R2: =IFERROR(__xludf.DUMMYFUNCTION("""COMPUTED_VALUE"""),20.0)
A3: =IFERROR(__xludf.DUMMYFUNCTION("""COMPUTED_VALUE"""),"Tuesday") | B3: =IFERROR(__xludf.DUMMYFUNCTION("""COMPUTED_VALUE"""),"FV0472A - Indian Butter Chicken") | C3: =IFERROR(__xludf.DUMMYFUNCTION("""COMPUTED_VALUE"""),6102.0) | D3: =IFERROR(__xludf.DUMMYFUNCTION("""COMPUTED_VALUE"""),5.085) | E3: =IFERROR(__xludf.DUMMYFUNCTION("""COMPUTED_VALUE"""),2497.0) | F3: =IFERROR(__xludf.DUMMYFUNCTION("""COMPUTED_VALUE"""),2.0808333333333335) | G3: =IFERROR(__xludf.DUMMYFUNCTION("""COMPUTED_VALUE"""),1534.0) | H3: =IFERROR(__xludf.DUMMYFUNCTION("""COMPUTED_VALUE"""),1.2783333333333333) | I3: =IFERROR(__xludf.DUMMYFUNCTION("""COMPUTED_VALUE"""),1483.0) | J3: =IFERROR(__xludf.DUMMYFUNCTION("""COMPUTED_VALUE"""),5514.0) | K3: =IFERROR(__xludf.DUMMYFUNCTION("""COMPUTED_VALUE"""),"1. Run") | L3: =IFERROR(__xludf.DUMMYFUNCTION("""COMPUTED_VALUE"""),"Salmon with pesto") | M3: =IFERROR(__xludf.DUMMYFUNCTION("""COMPUTED_VALUE"""),5688.0) | N3: =IFERROR(__xludf.DUMMYFUNCTION("""COMPUTED_VALUE"""),6256.8) | O3: =IFERROR(__xludf.DUMMYFUNCTION("""COMPUTED_VALUE"""),6541.2)
A4: =IFERROR(__xludf.DUMMYFUNCTION("""COMPUTED_VALUE"""),"Tuesday") | B4: =IFERROR(__xludf.DUMMYFUNCTION("""COMPUTED_VALUE"""),"FV0846A - Stroganoff-Style Beef Burger") | C4: =IFERROR(__xludf.DUMMYFUNCTION("""COMPUTED_VALUE"""),1826.0) | D4: =IFERROR(__xludf.DUMMYFUNCTION("""COMPUTED_VALUE"""),1.5216666666666667) | E4: =IFERROR(__xludf.DUMMYFUNCTION("""COMPUTED_VALUE"""),858.0418748512967) | F4: =IFERROR(__xludf.DUMMYFUNCTION("""COMPUTED_VALUE"""),0.7150348957094139) | G4: =IFERROR(__xludf.DUMMYFUNCTION("""COMPUTED_VALUE"""),463.994289793005) | H4: =IFERROR(__xludf.DUMMYFUNCTION("""COMPUTED_VALUE"""),0.3866619081608375) | I4: =IFERROR(__xludf.DUMMYFUNCTION("""COMPUTED_VALUE"""),521.776350226029) | J4: =IFERROR(__xludf.DUMMYFUNCTION("""COMPUTED_VALUE"""),1843.8125148703307) | K4: =IFERROR(__xludf.DUMMYFUNCTION("""COMPUTED_VALUE"""),"1. Run") | L4: =IFERROR(__xludf.DUMMYFUNCTION("""COMPUTED_VALUE"""),"Indian style butter chicken") | M4: =IFERROR(__xludf.DUMMYFUNCTION("""COMPUTED_VALUE"""),5600.0) | N4: =IFERROR(__xludf.DUMMYFUNCTION("""COMPUTED_VALUE"""),6160.0) | O4: =IFERROR(__xludf.DUMMYFUNCTION("""COMPUTED_VALUE"""),6440.0)
A5: =IFERROR(__xludf.DUMMYFUNCTION("""COMPUTED_VALUE"""),"Wednesday") | B5: =IFERROR(__xludf.DUMMYFUNCTION("""COMPUTED_VALUE"""),"FV0281A - Baja Salmon") | C5: =IFERROR(__xludf.DUMMYFUNCTION("""COMPUTED_VALUE"""),7222.0) | D5: =IFERROR(__xludf.DUMMYFUNCTION("""COMPUTED_VALUE"""),6.0183333333333335) | E5: =IFERROR(__xludf.DUMMYFUNCTION("""COMPUTED_VALUE"""),3992.0) | F5: =IFERROR(__xludf.DUMMYFUNCTION("""COMPUTED_VALUE"""),3.3266666666666667) | G5: =IFERROR(__xludf.DUMMYFUNCTION("""COMPUTED_VALUE"""),1720.0) | H5: =IFERROR(__xludf.DUMMYFUNCTION("""COMPUTED_VALUE"""),1.4333333333333333) | I5: =IFERROR(__xludf.DUMMYFUNCTION("""COMPUTED_VALUE"""),1583.0) | J5: =IFERROR(__xludf.DUMMYFUNCTION("""COMPUTED_VALUE"""),7295.0) | K5: =IFERROR(__xludf.DUMMYFUNCTION("""COMPUTED_VALUE"""),"1. Run") | L5: =IFERROR(__xludf.DUMMYFUNCTION("""COMPUTED_VALUE"""),"Spicy citrus salmon") | M5: =IFERROR(__xludf.DUMMYFUNCTION("""COMPUTED_VALUE"""),7352.0) | N5: =IFERROR(__xludf.DUMMYFUNCTION("""COMPUTED_VALUE"""),8087.2) | O5: =IFERROR(__xludf.DUMMYFUNCTION("""COMPUTED_VALUE"""),8454.8)
A6: =IFERROR(__xludf.DUMMYFUNCTION("""COMPUTED_VALUE"""),"Wednesday") | B6: =IFERROR(__xludf.DUMMYFUNCTION("""COMPUTED_VALUE"""),"FV0333A - Tuscan Shrimp") | C6: =IFERROR(__xludf.DUMMYFUNCTION("""COMPUTED_VALUE"""),2525.0) | D6: =IFERROR(__xludf.DUMMYFUNCTION("""COMPUTED_VALUE"""),2.1041666666666665) | E6: =IFERROR(__xludf.DUMMYFUNCTION("""COMPUTED_VALUE"""),1138.0) | F6: =IFERROR(__xludf.DUMMYFUNCTION("""COMPUTED_VALUE"""),0.9483333333333334) | G6: =IFERROR(__xludf.DUMMYFUNCTION("""COMPUTED_VALUE"""),712.0) | H6: =IFERROR(__xludf.DUMMYFUNCTION("""COMPUTED_VALUE"""),0.5933333333333334) | I6: =IFERROR(__xludf.DUMMYFUNCTION("""COMPUTED_VALUE"""),700.0) | J6: =IFERROR(__xludf.DUMMYFUNCTION("""COMPUTED_VALUE"""),2550.0) | K6: =IFERROR(__xludf.DUMMYFUNCTION("""COMPUTED_VALUE"""),"1. Run") | L6: =IFERROR(__xludf.DUMMYFUNCTION("""COMPUTED_VALUE"""),"Tuscan Shrimp") | M6: =IFERROR(__xludf.DUMMYFUNCTION("""COMPUTED_VALUE"""),2815.0) | N6: =IFERROR(__xludf.DUMMYFUNCTION("""COMPUTED_VALUE"""),3096.5) | O6: =IFERROR(__xludf.DUMMYFUNCTION("""COMPUTED_VALUE"""),3237.25)
A7: =IFERROR(__xludf.DUMMYFUNCTION("""COMPUTED_VALUE"""),"Thursday") | B7: =IFERROR(__xludf.DUMMYFUNCTION("""COMPUTED_VALUE"""),"FV0035A - Salmon with pesto") | C7: =IFERROR(__xludf.DUMMYFUNCTION("""COMPUTED_VALUE"""),6256.8) | D7: =IFERROR(__xludf.DUMMYFUNCTION("""COMPUTED_VALUE"""),5.214) | E7: =IFERROR(__xludf.DUMMYFUNCTION("""COMPUTED_VALUE"""),2572.0) | F7: =IFERROR(__xludf.DUMMYFUNCTION("""COMPUTED_VALUE"""),2.1433333333333335) | G7: =IFERROR(__xludf.DUMMYFUNCTION("""COMPUTED_VALUE"""),1553.0) | H7: =IFERROR(__xludf.DUMMYFUNCTION("""COMPUTED_VALUE"""),1.2941666666666667) | I7: =IFERROR(__xludf.DUMMYFUNCTION("""COMPUTED_VALUE"""),1481.0) | J7: =IFERROR(__xludf.DUMMYFUNCTION("""COMPUTED_VALUE"""),5606.0) | K7: =IFERROR(__xludf.DUMMYFUNCTION("""COMPUTED_VALUE"""),"1. Run") | L7: =IFERROR(__xludf.DUMMYFUNCTION("""COMPUTED_VALUE"""),"Stroganoff-Style Beef Burger") | M7: =IFERROR(__xludf.DUMMYFUNCTION("""COMPUTED_VALUE"""),4313.0) | N7: =IFERROR(__xludf.DUMMYFUNCTION("""COMPUTED_VALUE"""),4744.3) | O7: =IFERROR(__xludf.DUMMYFUNCTION("""COMPUTED_VALUE"""),4959.95)
A8: =IFERROR(__xludf.DUMMYFUNCTION("""COMPUTED_VALUE"""),"Thursday") | B8: =IFERROR(__xludf.DUMMYFUNCTION("""COMPUTED_VALUE"""),"FV0846A - Stroganoff-Style Beef Burger") | C8: =IFERROR(__xludf.DUMMYFUNCTION("""COMPUTED_VALUE"""),2377.0) | D8: =IFERROR(__xludf.DUMMYFUNCTION("""COMPUTED_VALUE"""),1.9808333333333332) | E8: =IFERROR(__xludf.DUMMYFUNCTION("""COMPUTED_VALUE"""),1116.9581251487032) | F8: =IFERROR(__xludf.DUMMYFUNCTION("""COMPUTED_VALUE"""),0.9307984376239193) | G8: =IFERROR(__xludf.DUMMYFUNCTION("""COMPUTED_VALUE"""),604.005710206995) | H8: =IFERROR(__xludf.DUMMYFUNCTION("""COMPUTED_VALUE"""),0.5033380918391624) | I8: =IFERROR(__xludf.DUMMYFUNCTION("""COMPUTED_VALUE"""),679.2236497739709) | J8: =IFERROR(__xludf.DUMMYFUNCTION("""COMPUTED_VALUE"""),2400.187485129669) | K8: =IFERROR(__xludf.DUMMYFUNCTION("""COMPUTED_VALUE"""),"2. Run")
C10: =IFERROR(__xludf.DUMMYFUNCTION("""COMPUTED_VALUE"""),"Forecast") | D10: =IFERROR(__xludf.DUMMYFUNCTION("""COMPUTED_VALUE"""),"vs. plan")
B11: =IFERROR(__xludf.DUMMYFUNCTION("""COMPUTED_VALUE"""),"FV0846A - Stroganoff-Style Beef Burger") | C11: =IFERROR(__xludf.DUMMYFUNCTION("""COMPUTED_VALUE"""),4313.0) | D11: =IFERROR(__xludf.DUMMYFUNCTION("""COMPUTED_VALUE"""),110.0)
B12: =IFERROR(__xludf.DUMMYFUNCTION("""COMPUTED_VALUE"""),"FV0281A - Baja Salmon") | C12: =IFERROR(__xludf.DUMMYFUNCTION("""COMPUTED_VALUE"""),7352.0) | D12: =IFERROR(__xludf.DUMMYFUNCTION("""COMPUTED_VALUE"""),130.0)

Sheet Verden-2026-W20
A1: =IFERROR(__xludf.DUMMYFUNCTION("IMPORTRANGE(""https://docs.google.com/spreadsheets/d/13lZfV1HAcVuOAxd9-xHCEsxO0wHmPnJNl9NuoURpM6U/edit?gid=1819627895#gid=1819627895"",""Verden-2026-W20!A:BB"")"),"") | B1: =IFERROR(__xludf.DUMMYFUNCTION("""COMPUTED_VALUE"""),"Production week") | C1: =IFERROR(__xludf.DUMMYFUNCTION("""COMPUTED_VALUE"""),20.0)
B2: =IFERROR(__xludf.DUMMYFUNCTION("""COMPUTED_VALUE"""),"Priority") | C2: =IFERROR(__xludf.DUMMYFUNCTION("""COMPUTED_VALUE"""),"WOStaging by") | D2: =IFERROR(__xludf.DUMMYFUNCTION("""COMPUTED_VALUE"""),"Comments WO's") | E2: =IFERROR(__xludf.DUMMYFUNCTION("""COMPUTED_VALUE"""),"Debox Day") | F2: =IFERROR(__xludf.DUMMYFUNCTION("""COMPUTED_VALUE"""),"WO Ready") | G2: =IFERROR(__xludf.DUMMYFUNCTION("""COMPUTED_VALUE"""),"Hot Kitchen Weekday") | H2: =IFERROR(__xludf.DUMMYFUNCTION("""COMPUTED_VALUE"""),"Date Needed") | I2: =IFERROR(__xludf.DUMMYFUNCTION("""COMPUTED_VALUE"""),"Work Order Number") | J2: =IFERROR(__xludf.DUMMYFUNCTION("""COMPUTED_VALUE"""),"Recipe ID") | K2: =IFERROR(__xludf.DUMMYFUNCTION("""COMPUTED_VALUE"""),"Recipe Name") | L2: =IFERROR(__xludf.DUMMYFUNCTION("""COMPUTED_VALUE"""),"Sub Recipe Name") | M2: =IFERROR(__xludf.DUMMYFUNCTION("""COMPUTED_VALUE"""),"Production Minimum Needs Amount") | N2: =IFERROR(__xludf.DUMMYFUNCTION("""COMPUTED_VALUE"""),"Cook Methods") | O2: =IFERROR(__xludf.DUMMYFUNCTION("""COMPUTED_VALUE"""),"WO Cooked Portions") | P2: =IFERROR(__xludf.DUMMYFUNCTION("""COMPUTED_VALUE"""),"Target Portions") | Q2: =IFERROR(__xludf.DUMMYFUNCTION("""COMPUTED_VALUE"""),"Cooked Portions Excess") | R2: =IFERROR(__xludf.DUMMYFUNCTION("""COMPUTED_VALUE"""),"Staging Status") | S2: =IFERROR(__xludf.DUMMYFUNCTION("""COMPUTED_VALUE"""),"Staging Comment") | T2: =IFERROR(__xludf.DUMMYFUNCTION("""COMPUTED_VALUE"""),"Kitchen Status") | U2: =IFERROR(__xludf.DUMMYFUNCTION("""COMPUTED_VALUE"""),"Unlocked ETA") | V2: =IFERROR(__xludf.DUMMYFUNCTION("""COMPUTED_VALUE"""),"Work Order Comment") | W2: =IFERROR(__xludf.DUMMYFUNCTION("""COMPUTED_VALUE"""),"Date Needed") | X2: =IFERROR(__xludf.DUMMYFUNCTION("""COMPUTED_VALUE"""),"Work Order Number") | Y2: =IFERROR(__xludf.DUMMYFUNCTION("""COMPUTED_VALUE"""),"Recipe ID") | Z2: =IFERROR(__xludf.DUMMYFUNCTION("""COMPUTED_VALUE"""),"Allergense")
B3: =IFERROR(__xludf.DUMMYFUNCTION("""COMPUTED_VALUE"""),1.0) | C3: =IFERROR(__xludf.DUMMYFUNCTION("""COMPUTED_VALUE"""),"02.05 Part. Staged Chicken&Greek Yoghurt missing ") | D3: =IFERROR(__xludf.DUMMYFUNCTION("""COMPUTED_VALUE"""),"only 650KG Chicken verfügbar. ") | E3: =IFERROR(__xludf.DUMMYFUNCTION("""COMPUTED_VALUE"""),"Sunday") | F3: =IFERROR(__xludf.DUMMYFUNCTION("""COMPUTED_VALUE"""),FALSE) | G3: =IFERROR(__xludf.DUMMYFUNCTION("""COMPUTED_VALUE"""),"Monday") | H3: =IFERROR(__xludf.DUMMYFUNCTION("""COMPUTED_VALUE"""),"2026-05-03 - 1") | I3: =IFERROR(__xludf.DUMMYFUNCTION("""COMPUTED_VALUE"""),"20-32") | J3: =IFERROR(__xludf.DUMMYFUNCTION("""COMPUTED_VALUE"""),"REC-013852-4-002") | K3: =IFERROR(__xludf.DUMMYFUNCTION("""COMPUTED_VALUE"""),"FV0472A - Indian Butter Chicken [DE]") | L3: =IFERROR(__xludf.DUMMYFUNCTION("""COMPUTED_VALUE"""),"Diced chicken - Butter Chicken Batch - BA") | M3: =IFERROR(__xludf.DUMMYFUNCTION("""COMPUTED_VALUE"""),0.0) | N3: =IFERROR(__xludf.DUMMYFUNCTION("""COMPUTED_VALUE"""),"MARINADE / OVEN / BLAST CHILLER") | P3: =IFERROR(__xludf.DUMMYFUNCTION("""COMPUTED_VALUE"""),6102.0) | Q3: =IFERROR(__xludf.DUMMYFUNCTION("""COMPUTED_VALUE"""),-6102.0) | R3: =IFERROR(__xludf.DUMMYFUNCTION("""COMPUTED_VALUE"""),"Partially Staged") | T3: =IFERROR(__xludf.DUMMYFUNCTION("""COMPUTED_VALUE"""),"Not Started") | Z3: =IFERROR(__xludf.DUMMYFUNCTION("""COMPUTED_VALUE"""),"MILCH (EINSCHLIESSLICH LAKTOSE), SCHWEFELDIOXIDE UND SULFITE")
B4: =IFERROR(__xludf.DUMMYFUNCTION("""COMPUTED_VALUE"""),2.0) | C4: =IFERROR(__xludf.DUMMYFUNCTION("""COMPUTED_VALUE"""),"02.05 Part. Staged Onions missing (arrive on 03.5)") | E4: =IFERROR(__xludf.DUMMYFUNCTION("""COMPUTED_VALUE"""),"Sunday") | F4: =IFERROR(__xludf.DUMMYFUNCTION("""COMPUTED_VALUE"""),FALSE) | G4: =IFERROR(__xludf.DUMMYFUNCTION("""COMPUTED_VALUE"""),"Monday") | H4: =IFERROR(__xludf.DUMMYFUNCTION("""COMPUTED_VALUE"""),"2026-05-03 - 1") | I4: =IFERROR(__xludf.DUMMYFUNCTION("""COMPUTED_VALUE"""),"20-35") | J4: =IFERROR(__xludf.DUMMYFUNCTION("""COMPUTED_VALUE"""),"REC-029854-4-001") | K4: =IFERROR(__xludf.DUMMYFUNCTION("""COMPUTED_VALUE"""),"FV0846A - Stroganoff-Style Beef Burger [DE]") | L4: =IFERROR(__xludf.DUMMYFUNCTION("""COMPUTED_VALUE"""),"Beef Burger Master EU") | M4: =IFERROR(__xludf.DUMMYFUNCTION("""COMPUTED_VALUE"""),0.0) | N4: =IFERROR(__xludf.DUMMYFUNCTION("""COMPUTED_VALUE"""),"HORIZONTAL MIXER / PATTY MAKER / OVEN / BLAST CHILLER") | P4: =IFERROR(__xludf.DUMMYFUNCTION("""COMPUTED_VALUE"""),1826.0) | Q4: =IFERROR(__xludf.DUMMYFUNCTION("""COMPUTED_VALUE"""),-1826.0) | R4: =IFERROR(__xludf.DUMMYFUNCTION("""COMPUTED_VALUE"""),"Partially Staged") | T4: =IFERROR(__xludf.DUMMYFUNCTION("""COMPUTED_VALUE"""),"Not Started") | Z4: =IFERROR(__xludf.DUMMYFUNCTION("""COMPUTED_VALUE"""),"SCHWEFELDIOXIDE UND SULFITE")
B5: =IFERROR(__xludf.DUMMYFUNCTION("""COMPUTED_VALUE"""),3.0) | E5: =IFERROR(__xludf.DUMMYFUNCTION("""COMPUTED_VALUE"""),"Monday") | F5: =IFERROR(__xludf.DUMMYFUNCTION("""COMPUTED_VALUE"""),FALSE) | G5: =IFERROR(__xludf.DUMMYFUNCTION("""COMPUTED_VALUE"""),"Tuesday") | H5: =IFERROR(__xludf.DUMMYFUNCTION("""COMPUTED_VALUE"""),"2026-05-04 - 1") | I5: =IFERROR(__xludf.DUMMYFUNCTION("""COMPUTED_VALUE"""),"20-18") | J5: =IFERROR(__xludf.DUMMYFUNCTION("""COMPUTED_VALUE"""),"REC-014197-4-004") | K5: =IFERROR(__xludf.DUMMYFUNCTION("""COMPUTED_VALUE"""),"FV0281A - Baja Salmon [DE]") | L5: =IFERROR(__xludf.DUMMYFUNCTION("""COMPUTED_VALUE"""),"Salmon - BAJA Salmon - Batch") | M5: =IFERROR(__xludf.DUMMYFUNCTION("""COMPUTED_VALUE"""),0.0) | N5: =IFERROR(__xludf.DUMMYFUNCTION("""COMPUTED_VALUE"""),"THAW / HAND MARINADE / OVEN / BLAST CHILLER") | P5: =IFERROR(__xludf.DUMMYFUNCTION("""COMPUTED_VALUE"""),7550.0) | Q5: =IFERROR(__xludf.DUMMYFUNCTION("""COMPUTED_VALUE"""),-7550.0) | R5: =IFERROR(__xludf.DUMMYFUNCTION("""COMPUTED_VALUE"""),"Open") | T5: =IFERROR(__xludf.DUMMYFUNCTION("""COMPUTED_VALUE"""),"Not Started") | Z5: =IFERROR(__xludf.DUMMYFUNCTION("""COMPUTED_VALUE"""),"FISCH, SCHWEFELDIOXIDE UND SULFITE")
B6: =IFERROR(__xludf.DUMMYFUNCTION("""COMPUTED_VALUE"""),4.0) | C6: =IFERROR(__xludf.DUMMYFUNCTION("""COMPUTED_VALUE"""),"02.05 Part. Staged Garlic & Koriander missing (arrive 03.5)") | E6: =IFERROR(__xludf.DUMMYFUNCTION("""COMPUTED_VALUE"""),"Monday") | F6: =IFERROR(__xludf.DUMMYFUNCTION("""COMPUTED_VALUE"""),FALSE) | G6: =IFERROR(__xludf.DUMMYFUNCTION("""COMPUTED_VALUE"""),"Monday") | H6: =IFERROR(__xludf.DUMMYFUNCTION("""COMPUTED_VALUE"""),"2026-05-04 - 1") | I6: =IFERROR(__xludf.DUMMYFUNCTION("""COMPUTED_VALUE"""),"20-31") | J6: =IFERROR(__xludf.DUMMYFUNCTION("""COMPUTED_VALUE"""),"REC-013852-4-002") | K6: =IFERROR(__xludf.DUMMYFUNCTION("""COMPUTED_VALUE"""),"FV0472A - Indian Butter Chicken [DE]") | L6: =IFERROR(__xludf.DUMMYFUNCTION("""COMPUTED_VALUE"""),"Cauliflower rice - Cilantro and Lime Cauliflower Rice - BA") | M6: =IFERROR(__xludf.DUMMYFUNCTION("""COMPUTED_VALUE"""),0.0) | N6: =IFERROR(__xludf.DUMMYFUNCTION("""COMPUTED_VALUE"""),"OVEN / BLAST CHILLER") | P6: =IFERROR(__xludf.DUMMYFUNCTION("""COMPUTED_VALUE"""),6379.0) | Q6: =IFERROR(__xludf.DUMMYFUNCTION("""COMPUTED_VALUE"""),-6379.0) | R6: =IFERROR(__xludf.DUMMYFUNCTION("""COMPUTED_VALUE"""),"Partially Staged") | T6: =IFERROR(__xludf.DUMMYFUNCTION("""COMPUTED_VALUE"""),"Not Started")
B7: =IFERROR(__xludf.DUMMYFUNCTION("""COMPUTED_VALUE"""),5.0) | C7: =IFERROR(__xludf.DUMMYFUNCTION("""COMPUTED_VALUE"""),"02.05 Green Onions missing (arrcie 03.5)") | E7: =IFERROR(__xludf.DUMMYFUNCTION("""COMPUTED_VALUE"""),"Monday") | F7: =IFERROR(__xludf.DUMMYFUNCTION("""COMPUTED_VALUE"""),FALSE) | G7: =IFERROR(__xludf.DUMMYFUNCTION("""COMPUTED_VALUE"""),"Monday") | H7: =IFERROR(__xludf.DUMMYFUNCTION("""COMPUTED_VALUE"""),"2026-05-04 - 1") | I7: =IFERROR(__xludf.DUMMYFUNCTION("""COMPUTED_VALUE"""),"20-33") | J7: =IFERROR(__xludf.DUMMYFUNCTION("""COMPUTED_VALUE"""),"REC-013852-4-002") | K7: =IFERROR(__xludf.DUMMYFUNCTION("""COMPUTED_VALUE"""),"FV0472A - Indian Butter Chicken [DE]") | L7: =IFERROR(__xludf.DUMMYFUNCTION("""COMPUTED_VALUE"""),"Roasted Green Onions") | M7: =IFERROR(__xludf.DUMMYFUNCTION("""COMPUTED_VALUE"""),0.0) | N7: =IFERROR(__xludf.DUMMYFUNCTION("""COMPUTED_VALUE"""),"OVEN / BLAST CHILLER") | P7: =IFERROR(__xludf.DUMMYFUNCTION("""COMPUTED_VALUE"""),6379.0) | Q7: =IFERROR(__xludf.DUMMYFUNCTION("""COMPUTED_VALUE"""),-6379.0) | R7: =IFERROR(__xludf.DUMMYFUNCTION("""COMPUTED_VALUE"""),"Released") | T7: =IFERROR(__xludf.DUMMYFUNCTION("""COMPUTED_VALUE"""),"Not Started")
B8: =IFERROR(__xludf.DUMMYFUNCTION("""COMPUTED_VALUE"""),6.0) | C8: =IFERROR(__xludf.DUMMYFUNCTION("""COMPUTED_VALUE"""),"02.05 Part. Staged missing Onions (arrive 03.5) missing butter unsalted") | E8: =IFERROR(__xludf.DUMMYFUNCTION("""COMPUTED_VALUE"""),"Monday") | F8: =IFERROR(__xludf.DUMMYFUNCTION("""COMPUTED_VALUE"""),FALSE) | G8: =IFERROR(__xludf.DUMMYFUNCTION("""COMPUTED_VALUE"""),"Monday") | H8: =IFERROR(__xludf.DUMMYFUNCTION("""COMPUTED_VALUE"""),"2026-05-04 - 1") | I8: =IFERROR(__xludf.DUMMYFUNCTION("""COMPUTED_VALUE"""),"20-34") | J8: =IFERROR(__xludf.DUMMYFUNCTION("""COMPUTED_VALUE"""),"REC-013852-4-002") | K8: =IFERROR(__xludf.DUMMYFUNCTION("""COMPUTED_VALUE"""),"FV0472A - Indian Butter Chicken [DE]") | L8: =IFERROR(__xludf.DUMMYFUNCTION("""COMPUTED_VALUE"""),"Sauce - Butter Chicken sauce") | M8: =IFERROR(__xludf.DUMMYFUNCTION("""COMPUTED_VALUE"""),0.0) | N8: =IFERROR(__xludf.DUMMYFUNCTION("""COMPUTED_VALUE"""),"SPICE PORTIONING / IMMERSION BLENDER / BRAISER / BLAST CHILLER") | P8: =IFERROR(__xludf.DUMMYFUNCTION("""COMPUTED_VALUE"""),6379.0) | Q8: =IFERROR(__xludf.DUMMYFUNCTION("""COMPUTED_VALUE"""),-6379.0) | R8: =IFERROR(__xludf.DUMMYFUNCTION("""COMPUTED_VALUE"""),"Partially Staged") | T8: =IFERROR(__xludf.DUMMYFUNCTION("""COMPUTED_VALUE"""),"Not Started") | Z8: =IFERROR(__xludf.DUMMYFUNCTION("""COMPUTED_VALUE"""),"MILCH (EINSCHLIESSLICH LAKTOSE), SCHWEFELDIOXIDE UND SULFITE")
B9: =IFERROR(__xludf.DUMMYFUNCTION("""COMPUTED_VALUE"""),7.0) | C9: =IFERROR(__xludf.DUMMYFUNCTION("""COMPUTED_VALUE"""),"02.05 Part. Staged missing green beans (arriive 03.5)") | E9: =IFERROR(__xludf.DUMMYFUNCTION("""COMPUTED_VALUE"""),"Monday") | F9: =IFERROR(__xludf.DUMMYFUNCTION("""COMPUTED_VALUE"""),FALSE) | G9: =IFERROR(__xludf.DUMMYFUNCTION("""COMPUTED_VALUE"""),"Monday") | H9: =IFERROR(__xludf.DUMMYFUNCTION("""COMPUTED_VALUE"""),"2026-05-04 - 1") | I9: =IFERROR(__xludf.DUMMYFUNCTION("""COMPUTED_VALUE"""),"20-26") | J9: =IFERROR(__xludf.DUMMYFUNCTION("""COMPUTED_VALUE"""),"REC-029854-4-001") | K9: =IFERROR(__xludf.DUMMYFUNCTION("""COMPUTED_VALUE"""),"FV0846A - Stroganoff-Style Beef Burger [DE]") | L9: =IFERROR(__xludf.DUMMYFUNCTION("""COMPUTED_VALUE"""),"Green Beans CUT 1-1/2 - Fresh - Less Salt") | M9: =IFERROR(__xludf.DUMMYFUNCTION("""COMPUTED_VALUE"""),0.0) | N9: =IFERROR(__xludf.DUMMYFUNCTION("""COMPUTED_VALUE"""),"OVEN / BLAST CHILLER") | P9: =IFERROR(__xludf.DUMMYFUNCTION("""COMPUTED_VALUE"""),2100.0) | Q9: =IFERROR(__xludf.DUMMYFUNCTION("""COMPUTED_VALUE"""),-2100.0) | R9: =IFERROR(__xludf.DUMMYFUNCTION("""COMPUTED_VALUE"""),"Picking") | T9: =IFERROR(__xludf.DUMMYFUNCTION("""COMPUTED_VALUE"""),"Not Started")
B10: =IFERROR(__xludf.DUMMYFUNCTION("""COMPUTED_VALUE"""),8.0) | C10: =IFERROR(__xludf.DUMMYFUNCTION("""COMPUTED_VALUE"""),"Staged ") | E10: =IFERROR(__xludf.DUMMYFUNCTION("""COMPUTED_VALUE"""),"Monday") | F10: =IFERROR(__xludf.DUMMYFUNCTION("""COMPUTED_VALUE"""),FALSE) | G10: =IFERROR(__xludf.DUMMYFUNCTION("""COMPUTED_VALUE"""),"Monday") | H10: =IFERROR(__xludf.DUMMYFUNCTION("""COMPUTED_VALUE"""),"2026-05-04 - 1") | I10: =IFERROR(__xludf.DUMMYFUNCTION("""COMPUTED_VALUE"""),"20-27") | J10: =IFERROR(__xludf.DUMMYFUNCTION("""COMPUTED_VALUE"""),"REC-029854-4-001") | K10: =IFERROR(__xludf.DUMMYFUNCTION("""COMPUTED_VALUE"""),"FV0846A - Stroganoff-Style Beef Burger [DE]") | L10: =IFERROR(__xludf.DUMMYFUNCTION("""COMPUTED_VALUE"""),"Herb-Parmesan Butter") | M10: =IFERROR(__xludf.DUMMYFUNCTION("""COMPUTED_VALUE"""),0.0) | N10: =IFERROR(__xludf.DUMMYFUNCTION("""COMPUTED_VALUE"""),"PLANETARY MIXER / SCOOPER (BUTTER) / BLAST CHILLER") | P10: =IFERROR(__xludf.DUMMYFUNCTION("""COMPUTED_VALUE"""),2100.0) | Q10: =IFERROR(__xludf.DUMMYFUNCTION("""COMPUTED_VALUE"""),-2100.0) | R10: =IFERROR(__xludf.DUMMYFUNCTION("""COMPUTED_VALUE"""),"Picking") | T10: =IFERROR(__xludf.DUMMYFUNCTION("""COMPUTED_VALUE"""),"Not Started") | Z10: =IFERROR(__xludf.DUMMYFUNCTION("""COMPUTED_VALUE"""),"MILCH (EINSCHLIESSLICH LAKTOSE)")
B11: =IFERROR(__xludf.DUMMYFUNCTION("""COMPUTED_VALUE"""),9.0) | C11: =IFERROR(__xludf.DUMMYFUNCTION("""COMPUTED_VALUE"""),"02.05 Part. Staged missing mushrooms") | E11: =IFERROR(__xludf.DUMMYFUNCTION("""COMPUTED_VALUE"""),"Monday") | F11: =IFERROR(__xludf.DUMMYFUNCTION("""COMPUTED_VALUE"""),FALSE) | G11: =IFERROR(__xludf.DUMMYFUNCTION("""COMPUTED_VALUE"""),"Monday") | H11: =IFERROR(__xludf.DUMMYFUNCTION("""COMPUTED_VALUE"""),"2026-05-04 - 1") | I11: =IFERROR(__xludf.DUMMYFUNCTION("""COMPUTED_VALUE"""),"20-28") | J11: =IFERROR(__xludf.DUMMYFUNCTION("""COMPUTED_VALUE"""),"REC-029854-4-001") | K11: =IFERROR(__xludf.DUMMYFUNCTION("""COMPUTED_VALUE"""),"FV0846A - Stroganoff-Style Beef Burger [DE]") | L11: =IFERROR(__xludf.DUMMYFUNCTION("""COMPUTED_VALUE"""),"Loaded Roasted Sliced Mushrooms 1/2 green onion") | M11: =IFERROR(__xludf.DUMMYFUNCTION("""COMPUTED_VALUE"""),0.0) | N11: =IFERROR(__xludf.DUMMYFUNCTION("""COMPUTED_VALUE"""),"OVEN / BLAST CHILLER") | P11: =IFERROR(__xludf.DUMMYFUNCTION("""COMPUTED_VALUE"""),2100.0) | Q11: =IFERROR(__xludf.DUMMYFUNCTION("""COMPUTED_VALUE"""),-2100.0) | R11: =IFERROR(__xludf.DUMMYFUNCTION("""COMPUTED_VALUE"""),"Partially Staged") | T11: =IFERROR(__xludf.DUMMYFUNCTION("""COMPUTED_VALUE"""),"Not Started") | Z11: =IFERROR(__xludf.DUMMYFUNCTION("""COMPUTED_VALUE"""),"SCHWEFELDIOXIDE UND SULFITE")
B12: =IFERROR(__xludf.DUMMYFUNCTION("""COMPUTED_VALUE"""),10.0) | C12: =IFERROR(__xludf.DUMMYFUNCTION("""COMPUTED_VALUE"""),"missing green onions") | E12: =IFERROR(__xludf.DUMMYFUNCTION("""COMPUTED_VALUE"""),"Monday") | F12: =IFERROR(__xludf.DUMMYFUNCTION("""COMPUTED_VALUE"""),FALSE) | G12: =IFERROR(__xludf.DUMMYFUNCTION("""COMPUTED_VALUE"""),"Monday") | H12: =IFERROR(__xludf.DUMMYFUNCTION("""COMPUTED_VALUE"""),"2026-05-04 - 1") | I12: =IFERROR(__xludf.DUMMYFUNCTION("""COMPUTED_VALUE"""),"20-29") | J12: =IFERROR(__xludf.DUMMYFUNCTION("""COMPUTED_VALUE"""),"REC-029854-4-001") | K12: =IFERROR(__xludf.DUMMYFUNCTION("""COMPUTED_VALUE"""),"FV0846A - Stroganoff-Style Beef Burger [DE]") | L12: =IFERROR(__xludf.DUMMYFUNCTION("""COMPUTED_VALUE"""),"Roasted Green Onions") | M12: =IFERROR(__xludf.DUMMYFUNCTION("""COMPUTED_VALUE"""),0.0) | N12: =IFERROR(__xludf.DUMMYFUNCTION("""COMPUTED_VALUE"""),"OVEN / BLAST CHILLER") | P12: =IFERROR(__xludf.DUMMYFUNCTION("""COMPUTED_VALUE"""),2100.0) | Q12: =IFERROR(__xludf.DUMMYFUNCTION("""COMPUTED_VALUE"""),-2100.0) | R12: =IFERROR(__xludf.DUMMYFUNCTION("""COMPUTED_VALUE"""),"Released") | T12: =IFERROR(__xludf.DUMMYFUNCTION("""COMPUTED_VALUE"""),"Not Started")
B13: =IFERROR(__xludf.DUMMYFUNCTION("""COMPUTED_VALUE"""),11.0) | C13: =IFERROR(__xludf.DUMMYFUNCTION("""COMPUTED_VALUE"""),"02.05 Part. Staged missing mushrooms & green onions") | E13: =IFERROR(__xludf.DUMMYFUNCTION("""COMPUTED_VALUE"""),"Monday") | F13: =IFERROR(__xludf.DUMMYFUNCTION("""COMPUTED_VALUE"""),FALSE) | G13: =IFERROR(__xludf.DUMMYFUNCTION("""COMPUTED_VALUE"""),"Monday") | H13: =IFERROR(__xludf.DUMMYFUNCTION("""COMPUTED_VALUE"""),"2026-05-04 - 1") | I13: =IFERROR(__xludf.DUMMYFUNCTION("""COMPUTED_VALUE"""),"20-30") | J13: =IFERROR(__xludf.DUMMYFUNCTION("""COMPUTED_VALUE"""),"REC-029854-4-001") | K13: =IFERROR(__xludf.DUMMYFUNCTION("""COMPUTED_VALUE"""),"FV0846A - Stroganoff-Style Beef Burger [DE]") | L13: =IFERROR(__xludf.DUMMYFUNCTION("""COMPUTED_VALUE"""),"Sauce for Beef Stroganoff - 1/2 garlic- No wine") | M13: =IFERROR(__xludf.DUMMYFUNCTION("""COMPUTED_VALUE"""),0.0) | N13: =IFERROR(__xludf.DUMMYFUNCTION("""COMPUTED_VALUE"""),"SPICE PORTIONING / IMMERSION BLENDER / BRAISER / BLAST CHILLER") | P13: =IFERROR(__xludf.DUMMYFUNCTION("""COMPUTED_VALUE"""),2100.0) | Q13: =IFERROR(__xludf.DUMMYFUNCTION("""COMPUTED_VALUE"""),-2100.0) | R13: =IFERROR(__xludf.DUMMYFUNCTION("""COMPUTED_VALUE"""),"Partially Staged") | T13: =IFERROR(__xludf.DUMMYFUNCTION("""COMPUTED_VALUE"""),"Not Started") | Z13: =IFERROR(__xludf.DUMMYFUNCTION("""COMPUTED_VALUE"""),"MILCH (EINSCHLIESSLICH LAKTOSE), SCHWEFELDIOXIDE UND SULFITE, SELLERIE, SENF")
B14: =IFERROR(__xludf.DUMMYFUNCTION("""COMPUTED_VALUE"""),12.0) | F14: =IFERROR(__xludf.DUMMYFUNCTION("""COMPUTED_VALUE"""),FALSE) | G14: =IFERROR(__xludf.DUMMYFUNCTION("""COMPUTED_VALUE"""),"Tuesday") | H14: =IFERROR(__xludf.DUMMYFUNCTION("""COMPUTED_VALUE"""),"2026-05-05 - 1") | I14: =IFERROR(__xludf.DUMMYFUNCTION("""COMPUTED_VALUE"""),"20-23") | J14: =IFERROR(__xludf.DUMMYFUNCTION("""COMPUTED_VALUE"""),"REC-013835-4-002") | K14: =IFERROR(__xludf.DUMMYFUNCTION("""COMPUTED_VALUE"""),"FV0333A - Tuscan Shrimp [DE]") | L14: =IFERROR(__xludf.DUMMYFUNCTION("""COMPUTED_VALUE"""),"Tuscan Shrimp batch") | M14: =IFERROR(__xludf.DUMMYFUNCTION("""COMPUTED_VALUE"""),0.0) | N14: =IFERROR(__xludf.DUMMYFUNCTION("""COMPUTED_VALUE"""),"THAW / MARINADE / OVEN / BLAST CHILLER") | P14: =IFERROR(__xludf.DUMMYFUNCTION("""COMPUTED_VALUE"""),2639.0) | Q14: =IFERROR(__xludf.DUMMYFUNCTION("""COMPUTED_VALUE"""),-2639.0) | R14: =IFERROR(__xludf.DUMMYFUNCTION("""COMPUTED_VALUE"""),"Open") | T14: =IFERROR(__xludf.DUMMYFUNCTION("""COMPUTED_VALUE"""),"Not Started") | Z14: =IFERROR(__xludf.DUMMYFUNCTION("""COMPUTED_VALUE"""),"KREBSTIERE, SCHWEFELDIOXIDE UND SULFITE")
B15: =IFERROR(__xludf.DUMMYFUNCTION("""COMPUTED_VALUE"""),13.0) | F15: =IFERROR(__xludf.DUMMYFUNCTION("""COMPUTED_VALUE"""),FALSE) | G15: =IFERROR(__xludf.DUMMYFUNCTION("""COMPUTED_VALUE"""),"Wednesday") | H15: =IFERROR(__xludf.DUMMYFUNCTION("""COMPUTED_VALUE"""),"2026-05-05 - 1") | I15: =IFERROR(__xludf.DUMMYFUNCTION("""COMPUTED_VALUE"""),"20-53") | J15: =IFERROR(__xludf.DUMMYFUNCTION("""COMPUTED_VALUE"""),"REC-013940-4-006") | K15: =IFERROR(__xludf.DUMMYFUNCTION("""COMPUTED_VALUE"""),"FV0035A - Salmon with pesto [DE]") | L15: =IFERROR(__xludf.DUMMYFUNCTION("""COMPUTED_VALUE"""),"Salmon - garlic seasoning") | M15: =IFERROR(__xludf.DUMMYFUNCTION("""COMPUTED_VALUE"""),0.0) | N15: =IFERROR(__xludf.DUMMYFUNCTION("""COMPUTED_VALUE"""),"THAW / HAND MARINADE / OVEN / BLAST CHILLER") | P15: =IFERROR(__xludf.DUMMYFUNCTION("""COMPUTED_VALUE"""),5550.0) | Q15: =IFERROR(__xludf.DUMMYFUNCTION("""COMPUTED_VALUE"""),-5550.0) | R15: =IFERROR(__xludf.DUMMYFUNCTION("""COMPUTED_VALUE"""),"Open") | T15: =IFERROR(__xludf.DUMMYFUNCTION("""COMPUTED_VALUE"""),"Not Started") | Z15: =IFERROR(__xludf.DUMMYFUNCTION("""COMPUTED_VALUE"""),"FISCH")
B16: =IFERROR(__xludf.DUMMYFUNCTION("""COMPUTED_VALUE"""),14.0) | F16: =IFERROR(__xludf.DUMMYFUNCTION("""COMPUTED_VALUE"""),FALSE) | G16: =IFERROR(__xludf.DUMMYFUNCTION("""COMPUTED_VALUE"""),"Tuesday") | H16: =IFERROR(__xludf.DUMMYFUNCTION("""COMPUTED_VALUE"""),"2026-05-05 - 1") | I16: =IFERROR(__xludf.DUMMYFUNCTION("""COMPUTED_VALUE"""),"20-14") | J16: =IFERROR(__xludf.DUMMYFUNCTION("""COMPUTED_VALUE"""),"REC-014197-4-004") | K16: =IFERROR(__xludf.DUMMYFUNCTION("""COMPUTED_VALUE"""),"FV0281A - Baja Salmon [DE]") | L16: =IFERROR(__xludf.DUMMYFUNCTION("""COMPUTED_VALUE"""),"Broccoli - S&P Broccoli FLORETS - less salt") | M16: =IFERROR(__xludf.DUMMYFUNCTION("""COMPUTED_VALUE"""),0.0) | N16: =IFERROR(__xludf.DUMMYFUNCTION("""COMPUTED_VALUE"""),"SPICE PORTIONING / HAND MIX") | P16: =IFERROR(__xludf.DUMMYFUNCTION("""COMPUTED_VALUE"""),7550.0) | Q16: =IFERROR(__xludf.DUMMYFUNCTION("""COMPUTED_VALUE"""),-7550.0) | R16: =IFERROR(__xludf.DUMMYFUNCTION("""COMPUTED_VALUE"""),"Open") | T16: =IFERROR(__xludf.DUMMYFUNCTION("""COMPUTED_VALUE"""),"Not Started")
B17: =IFERROR(__xludf.DUMMYFUNCTION("""COMPUTED_VALUE"""),15.0) | F17: =IFERROR(__xludf.DUMMYFUNCTION("""COMPUTED_VALUE"""),FALSE) | G17: =IFERROR(__xludf.DUMMYFUNCTION("""COMPUTED_VALUE"""),"Tuesday") | H17: =IFERROR(__xludf.DUMMYFUNCTION("""COMPUTED_VALUE"""),"2026-05-05 - 1") | I17: =IFERROR(__xludf.DUMMYFUNCTION("""COMPUTED_VALUE"""),"20-16") | J17: =IFERROR(__xludf.DUMMYFUNCTION("""COMPUTED_VALUE"""),"REC-014197-4-004") | K17: =IFERROR(__xludf.DUMMYFUNCTION("""COMPUTED_VALUE"""),"FV0281A - Baja Salmon [DE]") | L17: =IFERROR(__xludf.DUMMYFUNCTION("""COMPUTED_VALUE"""),"Compound butter - Chili-Garlic Butter - master batch") | M17: =IFERROR(__xludf.DUMMYFUNCTION("""COMPUTED_VALUE"""),0.0) | N17: =IFERROR(__xludf.DUMMYFUNCTION("""COMPUTED_VALUE"""),"PLANETARY MIXER / SCOOPER (BUTTER) / BLAST CHILLER") | P17: =IFERROR(__xludf.DUMMYFUNCTION("""COMPUTED_VALUE"""),7550.0) | Q17: =IFERROR(__xludf.DUMMYFUNCTION("""COMPUTED_VALUE"""),-7550.0) | R17: =IFERROR(__xludf.DUMMYFUNCTION("""COMPUTED_VALUE"""),"Open") | T17: =IFERROR(__xludf.DUMMYFUNCTION("""COMPUTED_VALUE"""),"Not Started") | Z17: =IFERROR(__xludf.DUMMYFUNCTION("""COMPUTED_VALUE"""),"MILCH (EINSCHLIESSLICH LAKTOSE)")
B18: =IFERROR(__xludf.DUMMYFUNCTION("""COMPUTED_VALUE"""),16.0) | F18: =IFERROR(__xludf.DUMMYFUNCTION("""COMPUTED_VALUE"""),FALSE) | G18: =IFERROR(__xludf.DUMMYFUNCTION("""COMPUTED_VALUE"""),"Tuesday") | H18: =IFERROR(__xludf.DUMMYFUNCTION("""COMPUTED_VALUE"""),"2026-05-05 - 1") | I18: =IFERROR(__xludf.DUMMYFUNCTION("""COMPUTED_VALUE"""),"20-17") | J18: =IFERROR(__xludf.DUMMYFUNCTION("""COMPUTED_VALUE"""),"REC-014197-4-004") | K18: =IFERROR(__xludf.DUMMYFUNCTION("""COMPUTED_VALUE"""),"FV0281A - Baja Salmon [DE]") | L18: =IFERROR(__xludf.DUMMYFUNCTION("""COMPUTED_VALUE"""),"Mexican Cauliflower Rice") | M18: =IFERROR(__xludf.DUMMYFUNCTION("""COMPUTED_VALUE"""),0.0) | N18: =IFERROR(__xludf.DUMMYFUNCTION("""COMPUTED_VALUE"""),"OVEN") | P18: =IFERROR(__xludf.DUMMYFUNCTION("""COMPUTED_VALUE"""),7550.0) | Q18: =IFERROR(__xludf.DUMMYFUNCTION("""COMPUTED_VALUE"""),-7550.0) | R18: =IFERROR(__xludf.DUMMYFUNCTION("""COMPUTED_VALUE"""),"Open") | T18: =IFERROR(__xludf.DUMMYFUNCTION("""COMPUTED_VALUE"""),"Not Started")
B19: =IFERROR(__xludf.DUMMYFUNCTION("""COMPUTED_VALUE"""),17.0) | F19: =IFERROR(__xludf.DUMMYFUNCTION("""COMPUTED_VALUE"""),FALSE) | G19: =IFERROR(__xludf.DUMMYFUNCTION("""COMPUTED_VALUE"""),"Tuesday") | H19: =IFERROR(__xludf.DUMMYFUNCTION("""COMPUTED_VALUE"""),"2026-05-05 - 1") | I19: =IFERROR(__xludf.DUMMYFUNCTION("""COMPUTED_VALUE"""),"20-19") | J19: =IFERROR(__xludf.DUMMYFUNCTION("""COMPUTED_VALUE"""),"REC-014197-4-004") | K19: =IFERROR(__xludf.DUMMYFUNCTION("""COMPUTED_VALUE"""),"FV0281A - Baja Salmon [DE]") | L19: =IFERROR(__xludf.DUMMYFUNCTION("""COMPUTED_VALUE"""),"Sauce - Cilantro Sour Cream") | M19: =IFERROR(__xludf.DUMMYFUNCTION("""COMPUTED_VALUE"""),0.0) | N19: =IFERROR(__xludf.DUMMYFUNCTION("""COMPUTED_VALUE"""),"IMMERSION BLENDER / CUPPING") | P19: =IFERROR(__xludf.DUMMYFUNCTION("""COMPUTED_VALUE"""),7550.0) | Q19: =IFERROR(__xludf.DUMMYFUNCTION("""COMPUTED_VALUE"""),-7550.0) | R19: =IFERROR(__xludf.DUMMYFUNCTION("""COMPUTED_VALUE"""),"Open") | T19: =IFERROR(__xludf.DUMMYFUNCTION("""COMPUTED_VALUE"""),"Not Started") | Z19: =IFERROR(__xludf.DUMMYFUNCTION("""COMPUTED_VALUE"""),"MILCH (EINSCHLIESSLICH LAKTOSE)")
B20: =IFERROR(__xludf.DUMMYFUNCTION("""COMPUTED_VALUE"""),18.0) | F20: =IFERROR(__xludf.DUMMYFUNCTION("""COMPUTED_VALUE"""),FALSE) | G20: =IFERROR(__xludf.DUMMYFUNCTION("""COMPUTED_VALUE"""),"Tuesday") | H20: =IFERROR(__xludf.DUMMYFUNCTION("""COMPUTED_VALUE"""),"2026-05-05 - 1") | I20: =IFERROR(__xludf.DUMMYFUNCTION("""COMPUTED_VALUE"""),"20-21") | J20: =IFERROR(__xludf.DUMMYFUNCTION("""COMPUTED_VALUE"""),"REC-013835-4-002") | K20: =IFERROR(__xludf.DUMMYFUNCTION("""COMPUTED_VALUE"""),"FV0333A - Tuscan Shrimp [DE]") | L20: =IFERROR(__xludf.DUMMYFUNCTION("""COMPUTED_VALUE"""),"Creamed Kale - Cream Cheese") | M20: =IFERROR(__xludf.DUMMYFUNCTION("""COMPUTED_VALUE"""),0.0) | N20: =IFERROR(__xludf.DUMMYFUNCTION("""COMPUTED_VALUE"""),"SPICE PORTIONING / BRAISER / BLAST CHILLER") | P20: =IFERROR(__xludf.DUMMYFUNCTION("""COMPUTED_VALUE"""),2639.0) | Q20: =IFERROR(__xludf.DUMMYFUNCTION("""COMPUTED_VALUE"""),-2639.0) | R20: =IFERROR(__xludf.DUMMYFUNCTION("""COMPUTED_VALUE"""),"Open") | T20: =IFERROR(__xludf.DUMMYFUNCTION("""COMPUTED_VALUE"""),"Not Started") | Z20: =IFERROR(__xludf.DUMMYFUNCTION("""COMPUTED_VALUE"""),"MILCH (EINSCHLIESSLICH LAKTOSE), SCHWEFELDIOXIDE UND SULFITE")
B21: =IFERROR(__xludf.DUMMYFUNCTION("""COMPUTED_VALUE"""),19.0) | F21: =IFERROR(__xludf.DUMMYFUNCTION("""COMPUTED_VALUE"""),FALSE) | G21: =IFERROR(__xludf.DUMMYFUNCTION("""COMPUTED_VALUE"""),"Tuesday") | H21: =IFERROR(__xludf.DUMMYFUNCTION("""COMPUTED_VALUE"""),"2026-05-05 - 1") | I21: =IFERROR(__xludf.DUMMYFUNCTION("""COMPUTED_VALUE"""),"20-22") | J21: =IFERROR(__xludf.DUMMYFUNCTION("""COMPUTED_VALUE"""),"REC-013835-4-002") | K21: =IFERROR(__xludf.DUMMYFUNCTION("""COMPUTED_VALUE"""),"FV0333A - Tuscan Shrimp [DE]") | L21: =IFERROR(__xludf.DUMMYFUNCTION("""COMPUTED_VALUE"""),"Sauce - Tuscan Shrimp Butter Sauce") | M21: =IFERROR(__xludf.DUMMYFUNCTION("""COMPUTED_VALUE"""),0.0) | N21: =IFERROR(__xludf.DUMMYFUNCTION("""COMPUTED_VALUE"""),"SPICE PORTIONING / IMMERSION BLENDER / BRAISER / BLAST CHILLER") | P21: =IFERROR(__xludf.DUMMYFUNCTION("""COMPUTED_VALUE"""),2639.0) | Q21: =IFERROR(__xludf.DUMMYFUNCTION("""COMPUTED_VALUE"""),-2639.0) | R21: =IFERROR(__xludf.DUMMYFUNCTION("""COMPUTED_VALUE"""),"Open") | T21: =IFERROR(__xludf.DUMMYFUNCTION("""COMPUTED_VALUE"""),"Not Started") | Z21: =IFERROR(__xludf.DUMMYFUNCTION("""COMPUTED_VALUE"""),"MILCH (EINSCHLIESSLICH LAKTOSE), SCHWEFELDIOXIDE UND SULFITE, SELLERIE")
B22: =IFERROR(__xludf.DUMMYFUNCTION("""COMPUTED_VALUE"""),20.0) | F22: =IFERROR(__xludf.DUMMYFUNCTION("""COMPUTED_VALUE"""),FALSE) | G22: =IFERROR(__xludf.DUMMYFUNCTION("""COMPUTED_VALUE"""),"Tuesday") | H22: =IFERROR(__xludf.DUMMYFUNCTION("""COMPUTED_VALUE"""),"2026-05-05 - 1") | I22: =IFERROR(__xludf.DUMMYFUNCTION("""COMPUTED_VALUE"""),"20-24") | J22: =IFERROR(__xludf.DUMMYFUNCTION("""COMPUTED_VALUE"""),"REC-013835-4-002") | K22: =IFERROR(__xludf.DUMMYFUNCTION("""COMPUTED_VALUE"""),"FV0333A - Tuscan Shrimp [DE]") | L22: =IFERROR(__xludf.DUMMYFUNCTION("""COMPUTED_VALUE"""),"Zucchini/Pepper/Onion Mix for Tuscan Shrimp - 1/2 Diced") | M22: =IFERROR(__xludf.DUMMYFUNCTION("""COMPUTED_VALUE"""),0.0) | P22: =IFERROR(__xludf.DUMMYFUNCTION("""COMPUTED_VALUE"""),2639.0) | Q22: =IFERROR(__xludf.DUMMYFUNCTION("""COMPUTED_VALUE"""),-2639.0) | R22: =IFERROR(__xludf.DUMMYFUNCTION("""COMPUTED_VALUE"""),"Open") | T22: =IFERROR(__xludf.DUMMYFUNCTION("""COMPUTED_VALUE"""),"Not Started")
B23: =IFERROR(__xludf.DUMMYFUNCTION("""COMPUTED_VALUE"""),21.0) | F23: =IFERROR(__xludf.DUMMYFUNCTION("""COMPUTED_VALUE"""),FALSE) | H23: =IFERROR(__xludf.DUMMYFUNCTION("""COMPUTED_VALUE"""),"2026-05-05 - 2") | I23: =IFERROR(__xludf.DUMMYFUNCTION("""COMPUTED_VALUE"""),"20-43") | J23: =IFERROR(__xludf.DUMMYFUNCTION("""COMPUTED_VALUE"""),"REC-029854-4-001") | K23: =IFERROR(__xludf.DUMMYFUNCTION("""COMPUTED_VALUE"""),"FV0846A - Stroganoff-Style Beef Burger [DE]") | L23: =IFERROR(__xludf.DUMMYFUNCTION("""COMPUTED_VALUE"""),"Beef Burger Master EU") | M23: =IFERROR(__xludf.DUMMYFUNCTION("""COMPUTED_VALUE"""),0.0) | N23: =IFERROR(__xludf.DUMMYFUNCTION("""COMPUTED_VALUE"""),"HORIZONTAL MIXER / PATTY MAKER / OVEN / BLAST CHILLER") | P23: =IFERROR(__xludf.DUMMYFUNCTION("""COMPUTED_VALUE"""),3293.0) | Q23: =IFERROR(__xludf.DUMMYFUNCTION("""COMPUTED_VALUE"""),-3293.0) | R23: =IFERROR(__xludf.DUMMYFUNCTION("""COMPUTED_VALUE"""),"Released") | T23: =IFERROR(__xludf.DUMMYFUNCTION("""COMPUTED_VALUE"""),"Not Started") | Y23: =IFERROR(__xludf.DUMMYFUNCTION("""COMPUTED_VALUE"""),"SCHWEFELDIOXIDE UND SULFITE") | Z23: =IFERROR(__xludf.DUMMYFUNCTION("""COMPUTED_VALUE"""),"SCHWEFELDIOXIDE UND SULFITE")
