Workbook

Sheet Overview
A1: Dates | C1: Unique Meals | F1: Meal Volumes - by country | K1: Meal Volumes
A2: Month | B2: Week | C2: Total | D2: Verden | E2: Coman | F2: BE | G2: NL | H2: SE | I2: DK | J2: DE | K2: Total | L2: Verden | M2: Coman
A3: 2026-M01 | B3: 2026-W01 | C3: {=transpose('Slot Selection'!K119:BJ119)} -> 18 | D3: {=transpose('Slot Selection'!K118:BJ118)} -> 0 | E3: =C3-D3 -> 18 | F3: {=transpose('Volume Development'!B26:BA30)} -> 10563 | G3: 13838 | H3: 6383 | I3: 6520 | J3: 13120 | K3: {=transpose('Volume Development'!B14:BA14)} -> 50424 | L3: {=TRANSPOSE('Volume Development'!B4:BA4)} -> 0 | M3: {=transpose('Volume Development'!B5:BA5)} -> 50424
A4: 2026-M01 | B4: 2026-W02 | C4: 18 | D4: 0 | E4: =C4-D4 -> 18 | F4: 15788 | G4: 19716 | H4: 9142 | I4: 9662 | J4: 18009 | K4: 72317 | L4: 0 | M4: 72317
A5: 2026-M01 | B5: 2026-W03 | C5: 18 | D5: 0 | E5: =C5-D5 -> 18 | F5: 18886 | G5: 24561 | H5: 15517 | I5: 14345 | J5: 23886 | K5: 97195 | L5: 0 | M5: 97195
A6: 2026-M01 | B6: 2026-W04 | C6: 18 | D6: 0 | E6: =C6-D6 -> 18 | F6: 19226 | G6: 26659 | H6: 17674 | I6: 15250 | J6: 26001 | K6: 104810 | L6: 0 | M6: 104810
A7: 2026-M01 | B7: 2026-W05 | C7: 18 | D7: 0 | E7: =C7-D7 -> 18 | F7: 19418 | G7: 26913 | H7: 17944 | I7: 14861 | J7: 26398 | K7: 105534 | L7: 0 | M7: 105534
A8: 2026-M02 | B8: 2026-W06 | C8: 18 | D8: 0 | E8: =C8-D8 -> 18 | F8: 20138 | G8: 31395 | H8: 19481 | I8: 15666 | J8: 28331 | K8: 115011 | L8: 0 | M8: 115011
A9: 2026-M02 | B9: 2026-W07 | C9: 18 | D9: 0 | E9: =C9-D9 -> 18 | F9: 20138 | G9: 31345 | H9: 18468 | I9: 15801 | J9: 28372 | K9: 114124 | L9: 0 | M9: 114124
A10: 2026-M02 | B10: 2026-W08 | C10: 18 | D10: 0 | E10: =C10-D10 -> 18 | F10: 18990 | G10: 31766 | H10: 19056 | I10: 15684 | J10: 27692 | K10: 113188 | L10: 0 | M10: 113188
A11: 2026-M02 | B11: 2026-W09 | C11: 18 | D11: 0 | E11: =C11-D11 -> 18 | F11: 19614 | G11: 31723 | H11: 17474 | I11: 16011 | J11: 26774 | K11: 111596 | L11: 0 | M11: 111596
A12: 2026-M03 | B12: 2026-W10 | C12: 18 | D12: 0 | E12: =C12-D12 -> 18 | F12: 20866 | G12: 32924 | H12: 16220 | I12: 14086 | J12: 27372 | K12: 111468 | L12: 0 | M12: 111468
A13: 2026-M03 | B13: 2026-W11 | C13: 18 | D13: 0 | E13: =C13-D13 -> 18 | F13: 21218 | G13: 32787 | H13: 16128 | I13: 14798 | J13: 26621 | K13: 111552 | L13: 0 | M13: 111552
A14: 2026-M03 | B14: 2026-W12 | C14: 18 | D14: 0 | E14: =C14-D14 -> 18 | F14: 20414 | G14: 32817 | H14: 15996 | I14: 14038 | J14: 25038 | K14: 108303 | L14: 0 | M14: 108303
A15: 2026-M03 | B15: 2026-W13 | C15: 18 | D15: 0 | E15: =C15-D15 -> 18 | F15: 18769 | G15: 30745 | H15: 15845 | I15: 13441 | J15: 23649 | K15: 102449 | L15: 0 | M15: 102449
... A54: 2026-M12 | B54: 2026-W52 | C54: 36 | D54: 36 | E54: =C54-D54 -> 0 | F54: 18476.948 | G54: 22374.616 | H54: 10743.873 | I54: 8341.3746 | J54: 14663.092 | K54: 74599.904 | L54: 74599.904 | M54: 0

Sheet Volume Development
A2: Month | B2: 2026-M01 | C2: 2026-M01 | D2: 2026-M01 | E2: 2026-M01 | F2: 2026-M01 | G2: 2026-M02 | H2: 2026-M02 | I2: 2026-M02 | J2: 2026-M02 | K2: 2026-M03 | L2: 2026-M03 | M2: 2026-M03 | N2: 2026-M03 | O2: 2026-M04 | P2: 2026-M04 | Q2: 2026-M04 | R2: 2026-M04 | S2: 2026-M04 | T2: 2026-M05 | U2: 2026-M05 | V2: 2026-M05 | W2: 2026-M05 | X2: 2026-M06 | Y2: 2026-M06 | Z2: 2026-M06 | AA2: 2026-M06 | AB2: 2026-M07 | AC2: 2026-M07 | AD2: 2026-M07 | AE2: 2026-M07 | AF2: 2026-M07 | AG2: 2026-M08 | AH2: 2026-M08 | AI2: 2026-M08 | AJ2: 2026-M08 | AK2: 2026-M09 | AL2: 2026-M09 | AM2: 2026-M09 | AN2: 2026-M09 | AO2: 2026-M10 | AP2: 2026-M10 | AQ2: 2026-M10 | AR2: 2026-M10 | AS2: 2026-M10 | AT2: 2026-M11 | AU2: 2026-M11 | AV2: 2026-M11 | AW2: 2026-M11 | AX2: 2026-M12 | AY2: 2026-M12 | AZ2: 2026-M12 | BA2: 2026-M12
A3: Week | B3: 2026-W01 | C3: 2026-W02 | D3: 2026-W03 | E3: 2026-W04 | F3: 2026-W05 | G3: 2026-W06 | H3: 2026-W07 | I3: 2026-W08 | J3: 2026-W09 | K3: 2026-W10 | L3: 2026-W11 | M3: 2026-W12 | N3: 2026-W13 | O3: 2026-W14 | P3: 2026-W15 | Q3: 2026-W16 | R3: 2026-W17 | S3: 2026-W18 | T3: 2026-W19 | U3: 2026-W20 | V3: 2026-W21 | W3: 2026-W22 | X3: 2026-W23 | Y3: 2026-W24 | Z3: 2026-W25 | AA3: 2026-W26 | AB3: 2026-W27 | AC3: 2026-W28 | AD3: 2026-W29 | AE3: 2026-W30 | AF3: 2026-W31 | AG3: 2026-W32 | AH3: 2026-W33 | AI3: 2026-W34 | AJ3: 2026-W35 | AK3: 2026-W36 | AL3: 2026-W37 | AM3: 2026-W38 | AN3: 2026-W39 | AO3: 2026-W40 | AP3: 2026-W41 | AQ3: 2026-W42 | AR3: 2026-W43 | AS3: 2026-W44 | AT3: 2026-W45 | AU3: 2026-W46 | AV3: 2026-W47 | AW3: 2026-W48 | AX3: 2026-W49 | AY3: 2026-W50 | AZ3: 2026-W51 | BA3: 2026-W52
A4: Verden Meal Volume | B4: =B35+B39+B43 -> 0 | C4: =C35+C39+C43 -> 0 | D4: =D35+D39+D43 -> 0 | E4: =E35+E39+E43 -> 0 | F4: =F35+F39+F43 -> 0 | G4: =G35+G39+G43 -> 0 | H4: =H35+H39+H43 -> 0 | I4: =I35+I39+I43 -> 0 | ... AB4: =AB35+AB39+AB43 -> 79459.142 | AC4: =AC11 -> 78465.319 | AD4: =AD11 -> 73275.561 | AE4: =AE11 -> 69598.196 | AF4: =AF11 -> 77290.85 | AG4: =AG11 -> 79262.829 | AH4: =AH11 -> 84794.296 | AI4: =AI11 -> 94709.683 | AJ4: =AJ11 -> 99479.923 | ... BA4: =BA11 -> 74599.904
A5: Coman Meal Volume | B5: =B36+B40+B44 -> 50424 | C5: =C36+C40+C44 -> 72317 | D5: =D36+D40+D44 -> 97195 | E5: =E36+E40+E44 -> 104810 | F5: =F36+F40+F44 -> 105534 | G5: =G36+G40+G44 -> 115011 | H5: =H36+H40+H44 -> 114124 | I5: =I36+I40+I44 -> 113188 | ... AE5: =AE36+AE40+AE44 -> 8715.2407 | AF5: =AF12 -> 0 | AG5: =AG12 -> 0 | AH5: =AH12 -> 0 | AI5: =AI12 -> 0 | AJ5: =AJ12 -> 0 | AK5: =AK12 -> 0 | AL5: =AL12 -> 0 | AM5: =AM12 -> 0 | ... BA5: =BA12 -> 0
A6: Planned Verden Share | B6: =B4/(B4+B5) -> 0 | C6: =C4/(C4+C5) -> 0 | D6: =D4/(D4+D5) -> 0 | E6: =E4/(E4+E5) -> 0 | F6: =F4/(F4+F5) -> 0 | G6: =G4/(G4+G5) -> 0 | H6: =H4/(H4+H5) -> 0 | I6: =I4/(I4+I5) -> 0 | ... AE6: =AE4/(AE4+AE5) -> 0.88871334 | AF6: =AF7 -> 1 | AG6: =AG7 -> 1 | AH6: =AH7 -> 1 | AI6: =AI7 -> 1 | AJ6: =AJ7 -> 1 | AK6: =AK7 -> 1 | AL6: =AL7 -> 1 | AM6: =AM7 -> 1 | ... BA6: =BA7 -> 1
A7: Goal Verden Share | B7: =B13 -> 0 | C7: =C13 -> 0 | D7: =D13 -> 0 | E7: =E13 -> 0 | F7: =F13 -> 0 | G7: =G13 -> 0 | H7: =H13 -> 0 | I7: =I13 -> 0 | ... BA7: =BA13 -> 1
A8: Unique Verden meals | B8: {=transpose(Overview!D3:D54)} -> 0 | C8: 0 | D8: 0 | E8: 0 | F8: 0 | G8: 0 | H8: 0 | I8: 0 | J8: 0 | K8: 0 | L8: 0 | M8: 0 | N8: 0 | O8: 0 | P8: 0 | Q8: 0 | R8: 0 | S8: 1 | T8: 3 | U8: 5 | V8: 8 | W8: 12 | X8: 17 | Y8: 19 | Z8: 20 | AA8: 21 | AB8: 24 | AC8: 24 | AD8: 24 | AE8: 25 | AF8: 30 | AG8: 30 | AH8: 30 | AI8: 30 | AJ8: 33 | AK8: 33 | AL8: 33 | AM8: 33 | AN8: 33 | AO8: 33 | AP8: 33 | AQ8: 33 | AR8: 33 | AS8: 33 | AT8: 33 | AU8: 33 | AV8: 33 | AW8: 33 | AX8: 36 | AY8: 36 | AZ8: 36 | BA8: 36
A10: Planned Split | B10: 2026-W01 | C10: 2026-W02 | D10: 2026-W03 | E10: 2026-W04 | F10: 2026-W05 | G10: 2026-W06 | H10: 2026-W07 | I10: 2026-W08 | J10: 2026-W09 | K10: 2026-W10 | L10: 2026-W11 | M10: 2026-W12 | N10: 2026-W13 | O10: 2026-W14 | P10: 2026-W15 | Q10: 2026-W16 | R10: 2026-W17 | S10: 2026-W18 | T10: 2026-W19 | U10: 2026-W20 | V10: 2026-W21 | W10: 2026-W22 | X10: 2026-W23 | Y10: 2026-W24 | Z10: 2026-W25 | AA10: 2026-W26 | AB10: 2026-W27 | AC10: 2026-W28 | AD10: 2026-W29 | AE10: 2026-W30 | AF10: 2026-W31 | AG10: 2026-W32 | AH10: 2026-W33 | AI10: 2026-W34 | AJ10: 2026-W35 | AK10: 2026-W36 | AL10: 2026-W37 | AM10: 2026-W38 | AN10: 2026-W39 | AO10: 2026-W40 | AP10: 2026-W41 | AQ10: 2026-W42 | AR10: 2026-W43 | AS10: 2026-W44 | AT10: 2026-W45 | AU10: 2026-W46 | AV10: 2026-W47 | AW10: 2026-W48 | AX10: 2026-W49 | AY10: 2026-W50 | AZ10: 2026-W51 | BA10: 2026-W52
A11: Verden Meal Volume | B11: =B32*B13 -> 0 | C11: =C32*C13 -> 0 | D11: =D32*D13 -> 0 | E11: =E32*E13 -> 0 | F11: =F32*F13 -> 0 | G11: =G32*G13 -> 0 | H11: =H32*H13 -> 0 | I11: =I32*I13 -> 0 | ... BA11: =BA32*BA13 -> 74599.904
A12: Coman Meal Volume | B12: =B32-B11 -> 50424 | C12: =C32-C11 -> 72317 | D12: =D32-D11 -> 97195 | E12: =E32-E11 -> 104810 | F12: =F32-F11 -> 105534 | G12: =G32-G11 -> 115011 | H12: =H32-H11 -> 114124 | I12: =I32-I11 -> 113188 | ... BA12: =BA32-BA11 -> 0
B13: 0 | C13: 0 | D13: 0 | E13: 0 | F13: 0 | G13: 0 | H13: 0 | I13: 0 | J13: 0 | K13: 0 | L13: 0 | M13: 0 | N13: 0 | O13: 0 | P13: 0 | Q13: 0 | R13: 0 | S13: 0 | T13: 0.08 | U13: 0.2 | V13: 0.31 | W13: 0.45 | X13: 0.6 | Y13: 0.65 | Z13: 0.75 | AA13: 0.8 | AB13: 0.85 | AC13: 0.9 | AD13: 0.9 | AE13: 0.9 | AF13: 1 | AG13: 1 | AH13: 1 | AI13: 1 | AJ13: 1 | AK13: 1 | AL13: 1 | AM13: 1 | AN13: 1 | AO13: 1 | AP13: 1 | AQ13: 1 | AR13: 1 | AS13: 1 | AT13: 1 | AU13: 1 | AV13: 1 | AW13: 1 | AX13: 1 | AY13: 1 | AZ13: 1 | BA13: 1
A14: Total Volume | B14: =B11+B12 -> 50424 | C14: =C11+C12 -> 72317 | D14: =D11+D12 -> 97195 | E14: =E11+E12 -> 104810 | F14: =F11+F12 -> 105534 | G14: =G11+G12 -> 115011 | H14: =H11+H12 -> 114124 | I14: =I11+I12 -> 113188 | ... BA14: =BA11+BA12 -> 74599.904
A16: Total Boxes | B16: 2026-W01 | C16: 2026-W02 | D16: 2026-W03 | E16: 2026-W04 | F16: 2026-W05 | G16: 2026-W06 | H16: 2026-W07 | I16: 2026-W08 | J16: 2026-W09 | K16: 2026-W10 | L16: 2026-W11 | M16: 2026-W12 | N16: 2026-W13 | O16: 2026-W14 | P16: 2026-W15 | Q16: 2026-W16 | R16: 2026-W17 | S16: 2026-W18 | T16: 2026-W19 | U16: 2026-W20 | V16: 2026-W21 | W16: 2026-W22 | X16: 2026-W23 | Y16: 2026-W24 | Z16: 2026-W25 | AA16: 2026-W26 | AB16: 2026-W27 | AC16: 2026-W28 | AD16: 2026-W29 | AE16: 2026-W30 | AF16: 2026-W31 | AG16: 2026-W32 | AH16: 2026-W33 | AI16: 2026-W34 | AJ16: 2026-W35 | AK16: 2026-W36 | AL16: 2026-W37 | AM16: 2026-W38 | AN16: 2026-W39 | AO16: 2026-W40 | AP16: 2026-W41 | AQ16: 2026-W42 | AR16: 2026-W43 | AS16: 2026-W44 | AT16: 2026-W45 | AU16: 2026-W46 | AV16: 2026-W47 | AW16: 2026-W48 | AX16: 2026-W49 | AY16: 2026-W50 | AZ16: 2026-W51 | BA16: 2026-W52
A17: BE | B17: 1712 | C17: 2563 | D17: 2910 | E17: 2967 | F17: 2992 | G17: 3127 | H17: 3127 | I17: 2958 | J17: 3084 | K17: 3240 | L17: 3305 | M17: 3198 | N17: 2940 | O17: 3127 | P17: 2577 | Q17: 2637 | R17: 2800 | S17: 2871 | T17: ='Budget Volumes'!AF4 -> 2862 | U17: ='Budget Volumes'!AG4 -> 3138 | V17: ='Budget Volumes'!AH4 -> 3043 | W17: ='Budget Volumes'!AI4 -> 3152 | X17: ='Budget Volumes'!AJ4 -> 3393 | Y17: ='Budget Volumes'!AK4 -> 3373 | Z17: ='Budget Volumes'!AL4 -> 3294 | AA17: ='Budget Volumes'!AM4 -> 3134 | ... BA17: ='Budget Volumes'!BM4 -> 2546
A18: NL | B18: 1994 | C18: 2845 | D18: 3469 | E18: 3776 | F18: 4035 | G18: 4428 | H18: 4421 | I18: 4449 | J18: 4487 | K18: 4670 | L18: 4644 | M18: 4648 | N18: 4357 | O18: 4670 | P18: 3959 | Q18: 4022 | R18: 4273 | S18: 4342 | T18: ='Budget Volumes'!AF5 -> 4238 | U18: ='Budget Volumes'!AG5 -> 4504 | V18: ='Budget Volumes'!AH5 -> 4426 | W18: ='Budget Volumes'!AI5 -> 4310 | X18: ='Budget Volumes'!AJ5 -> 4366 | Y18: ='Budget Volumes'!AK5 -> 4226 | Z18: ='Budget Volumes'!AL5 -> 4331 | AA18: ='Budget Volumes'!AM5 -> 4317 | ... BA18: ='Budget Volumes'!BM5 -> 3422
A19: SE | B19: 790 | C19: 1130 | D19: 1865 | E19: 2099 | F19: 2191 | G19: 2370 | H19: 2280 | I19: 2403 | J19: 2246 | K19: 2112 | L19: 2073 | M19: 2076 | N19: 2057 | O19: 1952 | P19: 1724 | Q19: 1748 | R19: 1830 | S19: 1897 | T19: ='Budget Volumes'!AF8 -> 1653 | U19: ='Budget Volumes'!AG8 -> 1702 | V19: ='Budget Volumes'!AH8 -> 1698 | W19: ='Budget Volumes'!AI8 -> 1715 | X19: ='Budget Volumes'!AJ8 -> 1788 | Y19: ='Budget Volumes'!AK8 -> 1740 | Z19: ='Budget Volumes'!AL8 -> 1599 | AA19: ='Budget Volumes'!AM8 -> 1591 | ... BA19: ='Budget Volumes'!BM8 -> 1322
A20: DK | B20: 1003 | C20: 1505 | D20: 2061 | E20: 2207 | F20: 2160 | G20: 2277 | H20: 2290 | I20: 2334 | J20: 2365 | K20: 2131 | L20: 2212 | M20: 2110 | N20: 2021 | O20: 1726 | P20: 1688 | Q20: 1680 | R20: 1740 | S20: 1888 | T20: ='Budget Volumes'!AF7 -> 1758 | U20: ='Budget Volumes'!AG7 -> 1759 | V20: ='Budget Volumes'!AH7 -> 1736 | W20: ='Budget Volumes'!AI7 -> 1734 | X20: ='Budget Volumes'!AJ7 -> 1826 | Y20: ='Budget Volumes'!AK7 -> 1834 | Z20: ='Budget Volumes'!AL7 -> 1779 | AA20: ='Budget Volumes'!AM7 -> 1739 | ... BA20: ='Budget Volumes'!BM7 -> 1209
A21: DE | B21: 1638 | C21: 2271 | D21: 2920 | E21: 3210 | F21: 3235 | G21: 3455 | H21: 3507 | I21: 3423 | J21: 3351 | K21: 3396 | L21: 3323 | M21: 3125 | N21: 2952 | O21: 2792 | P21: 2593 | Q21: 2590 | R21: 2775 | S21: 2798 | T21: ='Budget Volumes'!AF6 -> 2492 | U21: ='Budget Volumes'!AG6 -> 2585 | V21: ='Budget Volumes'!AH6 -> 2539 | W21: ='Budget Volumes'!AI6 -> 2357 | X21: ='Budget Volumes'!AJ6 -> 2428 | Y21: ='Budget Volumes'!AK6 -> 2304 | Z21: ='Budget Volumes'!AL6 -> 2381 | AA21: ='Budget Volumes'!AM6 -> 2292 | ... BA21: ='Budget Volumes'!BM6 -> 1804
A22: FR | B22: ='Budget Volumes'!N9 -> 0 | C22: ='Budget Volumes'!O9 -> 0 | D22: ='Budget Volumes'!P9 -> 0 | E22: ='Budget Volumes'!Q9 -> 0 | F22: ='Budget Volumes'!R9 -> 0 | G22: ='Budget Volumes'!S9 -> 0 | H22: ='Budget Volumes'!T9 -> 0 | I22: ='Budget Volumes'!U9 -> 0 | ... BA22: ='Budget Volumes'!BM9 -> 0
A23: Total | B23: =sum(B17:B22) -> 7137 | C23: =sum(C17:C22) -> 10314 | D23: =sum(D17:D22) -> 13225 | E23: =sum(E17:E22) -> 14259 | F23: =sum(F17:F22) -> 14613 | G23: =sum(G17:G22) -> 15657 | H23: =sum(H17:H22) -> 15625 | I23: =sum(I17:I22) -> 15567 | ... BA23: =sum(BA17:BA22) -> 10303
A25: Total Meals | B25: 2026-W01 | C25: 2026-W02 | D25: 2026-W03 | E25: 2026-W04 | F25: 2026-W05 | G25: 2026-W06 | H25: 2026-W07 | I25: 2026-W08 | J25: 2026-W09 | K25: 2026-W10 | L25: 2026-W11 | M25: 2026-W12 | N25: 2026-W13 | O25: 2026-W14 | P25: 2026-W15 | Q25: 2026-W16 | R25: 2026-W17 | S25: 2026-W18 | T25: 2026-W19 | U25: 2026-W20 | V25: 2026-W21 | W25: 2026-W22 | X25: 2026-W23 | Y25: 2026-W24 | Z25: 2026-W25 | AA25: 2026-W26 | AB25: 2026-W27 | AC25: 2026-W28 | AD25: 2026-W29 | AE25: 2026-W30 | AF25: 2026-W31 | AG25: 2026-W32 | AH25: 2026-W33 | AI25: 2026-W34 | AJ25: 2026-W35 | AK25: 2026-W36 | AL25: 2026-W37 | AM25: 2026-W38 | AN25: 2026-W39 | AO25: 2026-W40 | AP25: 2026-W41 | AQ25: 2026-W42 | AR25: 2026-W43 | AS25: 2026-W44 | AT25: 2026-W45 | AU25: 2026-W46 | AV25: 2026-W47 | AW25: 2026-W48 | AX25: 2026-W49 | AY25: 2026-W50 | AZ25: 2026-W51 | BA25: 2026-W52
A26: BE | B26: 10563 | C26: 15788 | D26: 18886 | E26: 19226 | F26: 19418 | G26: 20138 | H26: 20138 | I26: 18990 | J26: 19614 | K26: 20866 | L26: 21218 | M26: 20414 | N26: 18769 | O26: 19652 | P26: 16288 | Q26: 16666 | R26: 17594 | S26: 18043 | T26: ='Budget Volumes'!AF12 -> 20107.748 | U26: ='Budget Volumes'!AG12 -> 22046.86 | V26: ='Budget Volumes'!AH12 -> 21379.412 | W26: ='Budget Volumes'!AI12 -> 22145.221 | X26: ='Budget Volumes'!AJ12 -> 23838.431 | Y26: ='Budget Volumes'!AK12 -> 23697.915 | Z26: ='Budget Volumes'!AL12 -> 23142.929 | AA26: ='Budget Volumes'!AM12 -> 22019.685 | ... BA26: ='Budget Volumes'!BM12 -> 18476.948
A27: NL | B27: 13838 | C27: 19716 | D27: 24561 | E27: 26659 | F27: 26913 | G27: 31395 | H27: 31345 | I27: 31766 | J27: 31723 | K27: 32924 | L27: 32787 | M27: 32817 | N27: 30745 | O27: 32738 | P27: 27240 | Q27: 27352 | R27: 29468 | S27: 29782 | T27: ='Budget Volumes'!AF13 -> 26827.851 | U27: ='Budget Volumes'!AG13 -> 28511.714 | V27: ='Budget Volumes'!AH13 -> 28017.949 | W27: ='Budget Volumes'!AI13 -> 27283.634 | X27: ='Budget Volumes'!AJ13 -> 27638.131 | Y27: ='Budget Volumes'!AK13 -> 26751.888 | Z27: ='Budget Volumes'!AL13 -> 27416.655 | AA27: ='Budget Volumes'!AM13 -> 27328.857 | ... BA27: ='Budget Volumes'!BM13 -> 22374.616
A28: SE | B28: 6383 | C28: 9142 | D28: 15517 | E28: 17674 | F28: 17944 | G28: 19481 | H28: 18468 | I28: 19056 | J28: 17474 | K28: 16220 | L28: 16128 | M28: 15996 | N28: 15845 | O28: 14994 | P28: 13790 | Q28: 13928 | R28: 14056 | S28: 14565 | T28: ='Budget Volumes'!AF16 -> 12984.594 | U28: ='Budget Volumes'!AG16 -> 13369.498 | V28: ='Budget Volumes'!AH16 -> 13338.077 | W28: ='Budget Volumes'!AI16 -> 13471.615 | X28: ='Budget Volumes'!AJ16 -> 14045.042 | Y28: ='Budget Volumes'!AK16 -> 13667.994 | Z28: ='Budget Volumes'!AL16 -> 12560.486 | AA28: ='Budget Volumes'!AM16 -> 12498.279 | ... BA28: ='Budget Volumes'!BM16 -> 10743.873
A29: DK | B29: 6520 | C29: 9662 | D29: 14345 | E29: 15250 | F29: 14861 | G29: 15666 | H29: 15801 | I29: 15684 | J29: 16011 | K29: 14086 | L29: 14798 | M29: 14038 | N29: 13441 | O29: 11734 | P29: 11464 | Q29: 11013 | R29: 11407 | S29: 12376 | T29: ='Budget Volumes'!AF15 -> 11762.426 | U29: ='Budget Volumes'!AG15 -> 11769.117 | V29: ='Budget Volumes'!AH15 -> 11615.229 | W29: ='Budget Volumes'!AI15 -> 11601.847 | X29: ='Budget Volumes'!AJ15 -> 12217.401 | Y29: ='Budget Volumes'!AK15 -> 12270.927 | Z29: ='Budget Volumes'!AL15 -> 11902.933 | AA29: ='Budget Volumes'!AM15 -> 11635.649 | ... BA29: ='Budget Volumes'!BM15 -> 8341.3746
A30: DE | B30: 13120 | C30: 18009 | D30: 23886 | E30: 26001 | F30: 26398 | G30: 28331 | H30: 28372 | I30: 27692 | J30: 26774 | K30: 27372 | L30: 26621 | M30: 25038 | N30: 23649 | O30: 22044 | P30: 20744 | Q30: 20643 | R30: 21910 | S30: 22089 | T30: ='Budget Volumes'!AF14 -> 19881.425 | U30: ='Budget Volumes'!AG14 -> 20623.389 | V30: ='Budget Volumes'!AH14 -> 20256.396 | W30: ='Budget Volumes'!AI14 -> 18804.382 | X30: ='Budget Volumes'!AJ14 -> 19370.827 | Y30: ='Budget Volumes'!AK14 -> 18381.542 | Z30: ='Budget Volumes'!AL14 -> 18995.856 | AA30: ='Budget Volumes'!AM14 -> 18285.805 | ... BA30: ='Budget Volumes'!BM14 -> 14663.092
A31: FR | B31: ='Budget Volumes'!N17 -> 0 | C31: ='Budget Volumes'!O17 -> 0 | D31: ='Budget Volumes'!P17 -> 0 | E31: ='Budget Volumes'!Q17 -> 0 | F31: ='Budget Volumes'!R17 -> 0 | G31: ='Budget Volumes'!S17 -> 0 | H31: ='Budget Volumes'!T17 -> 0 | I31: ='Budget Volumes'!U17 -> 0 | ... BA31: ='Budget Volumes'!BM17 -> 0
A32: Total | B32: =sum(B26:B31) -> 50424 | C32: =sum(C26:C31) -> 72317 | D32: =sum(D26:D31) -> 97195 | E32: =sum(E26:E31) -> 104810 | F32: =sum(F26:F31) -> 105534 | G32: =sum(G26:G31) -> 115011 | H32: =sum(H26:H31) -> 114124 | I32: =sum(I26:I31) -> 113188 | ... BA32: =sum(BA26:BA31) -> 74599.904
A34: BENL Volume | B34: 2026-W01 | C34: 2026-W02 | D34: 2026-W03 | E34: 2026-W04 | F34: 2026-W05 | G34: 2026-W06 | H34: 2026-W07 | I34: 2026-W08 | J34: 2026-W09 | K34: 2026-W10 | L34: 2026-W11 | M34: 2026-W12 | N34: 2026-W13 | O34: 2026-W14 | P34: 2026-W15 | Q34: 2026-W16 | R34: 2026-W17 | S34: 2026-W18 | T34: 2026-W19 | U34: 2026-W20 | V34: 2026-W21 | W34: 2026-W22 | X34: 2026-W23 | Y34: 2026-W24 | Z34: 2026-W25 | AA34: 2026-W26 | AB34: 2026-W27 | AC34: 2026-W28 | AD34: 2026-W29 | AE34: 2026-W30 | AF34: 2026-W31 | AG34: 2026-W32 | AH34: 2026-W33 | AI34: 2026-W34 | AJ34: 2026-W35 | AK34: 2026-W36 | AL34: 2026-W37 | AM34: 2026-W38 | AN34: 2026-W39 | AO34: 2026-W40 | AP34: 2026-W41 | AQ34: 2026-W42 | AR34: 2026-W43 | AS34: 2026-W44 | AT34: 2026-W45 | AU34: 2026-W46 | AV34: 2026-W47 | AW34: 2026-W48 | AX34: 2026-W49 | AY34: 2026-W50 | AZ34: 2026-W51 | BA34: 2026-W52
A35: Verden Meal Volume | B35: =(B26+B27)*SUMIF('Slot Selection'!K3:K32,TRUE,'Slot Selection'!$D$3:$D$32) -> 0 | C35: =(C26+C27)*SUMIF('Slot Selection'!L3:L32,TRUE,'Slot Selection'!$D$3:$D$32) -> 0 | D35: =(D26+D27)*SUMIF('Slot Selection'!M3:M32,TRUE,'Slot Selection'!$D$3:$D$32) -> 0 | E35: =(E26+E27)*SUMIF('Slot Selection'!N3:N32,TRUE,'Slot Selection'!$D$3:$D$32) -> 0 | F35: =(F26+F27)*SUMIF('Slot Selection'!O3:O32,TRUE,'Slot Selection'!$D$3:$D$32) -> 0 | G35: =(G26+G27)*SUMIF('Slot Selection'!P3:P32,TRUE,'Slot Selection'!$D$3:$D$32) -> 0 | H35: =(H26+H27)*SUMIF('Slot Selection'!Q3:Q32,TRUE,'Slot Selection'!$D$3:$D$32) -> 0 | I35: =(I26+I27)*SUMIF('Slot Selection'!R3:R32,TRUE,'Slot Selection'!$D$3:$D$32) -> 0 | ... M35: =(M26+M27)*SUMIF('Slot Selection'!V3:V32,TRUE,'Slot Selection'!$D$3:$D$32) -> 0 | N35: =(N26+N27)*SUMIF('Slot Selection'!W3:W38,TRUE,'Slot Selection'!$D$3:$D$38) -> 0 | O35: =(O26+O27)*SUMIF('Slot Selection'!X3:X38,TRUE,'Slot Selection'!$E$3:$E$38) -> 0 | P35: =(P26+P27)*SUMIF('Slot Selection'!Y3:Y38,TRUE,'Slot Selection'!$E$3:$E$38) -> 0 | Q35: =(Q26+Q27)*SUMIF('Slot Selection'!Z3:Z38,TRUE,'Slot Selection'!$E$3:$E$38) -> 0 | R35: =(R26+R27)*SUMIF('Slot Selection'!AA3:AA38,TRUE,'Slot Selection'!$D$3:$D$38) -> 0 | S35: =(S26+S27)*SUMIF('Slot Selection'!AB3:AB38,TRUE,'Slot Selection'!$D$3:$D$38) -> 1434.75 | T35: =(T26+T27)*SUMIF('Slot Selection'!AC3:AC38,TRUE,'Slot Selection'!$E$3:$E$38) -> 0 | U35: =(U26+U27)*SUMIF('Slot Selection'!AD3:AD38,TRUE,'Slot Selection'!$E$3:$E$38) -> 10592.021 | V35: =(V26+V27)*SUMIF('Slot Selection'!AE3:AE38,TRUE,'Slot Selection'!$E$3:$E$38) -> 12122.112 | W35: =(W26+W27)*SUMIF('Slot Selection'!AF3:AF38,TRUE,'Slot Selection'!$E$3:$E$38) -> 24071.852 | X35: =(X26+X27)*SUMIF('Slot Selection'!AG3:AG38,TRUE,'Slot Selection'!$F$3:$F$38) -> 32466.267 | Y35: =(Y26+Y27)*SUMIF('Slot Selection'!AH3:AH38,TRUE,'Slot Selection'!$F$3:$F$38) -> 34840.634 | Z35: =(Z26+Z27)*SUMIF('Slot Selection'!AI3:AI38,TRUE,'Slot Selection'!$F$3:$F$38) -> 40548.786 | AA35: =(AA26+AA27)*SUMIF('Slot Selection'!AJ3:AJ38,TRUE,'Slot Selection'!$F$3:$F$38) -> 42696.358 | AB35: =(AB26+AB27)*SUMIF('Slot Selection'!AK3:AK38,TRUE,'Slot Selection'!$F$3:$F$38) -> 42472.217 | AC35: =(AC26+AC27)*SUMIF('Slot Selection'!AL3:AL38,TRUE,'Slot Selection'!$F$3:$F$38) -> 40238.767 | AD35: =(AD26+AD27)*SUMIF('Slot Selection'!AM3:AM38,TRUE,'Slot Selection'!$F$3:$F$38) -> 37431.378 | AE35: =(AE26+AE27)*SUMIF('Slot Selection'!AN3:AN38,TRUE,'Slot Selection'!$F$3:$F$38) -> 36628.379 | AF35: =(AF26+AF27) -> 40909.451 | AG35: =(AG26+AG27) -> 41336.147 | AH35: =(AH26+AH27) -> 42674.209 | AI35: =(AI26+AI27) -> 48091.944 | AJ35: =(AJ26+AJ27) -> 50209.637 | AK35: =(AK26+AK27) -> 53620.339 | AL35: =(AL26+AL27) -> 60151.874 | AM35: =(AM26+AM27) -> 65915.935 | ... BA35: =(BA26+BA27) -> 40851.564
A36: Coman Meal Volume | B36: =(B26+B27)-B35 -> 24401 | C36: =(C26+C27)-C35 -> 35504 | D36: =(D26+D27)-D35 -> 43447 | E36: =(E26+E27)-E35 -> 45885 | F36: =(F26+F27)-F35 -> 46331 | G36: =(G26+G27)-G35 -> 51533 | H36: =(H26+H27)-H35 -> 51483 | I36: =(I26+I27)-I35 -> 50756 | ... BA36: =(BA26+BA27)-BA35 -> 0
A38: DKSE Volume | B38: 2026-W01 | C38: 2026-W02 | D38: 2026-W03 | E38: 2026-W04 | F38: 2026-W05 | G38: 2026-W06 | H38: 2026-W07 | I38: 2026-W08 | J38: 2026-W09 | K38: 2026-W10 | L38: 2026-W11 | M38: 2026-W12 | N38: 2026-W13 | O38: 2026-W14 | P38: 2026-W15 | Q38: 2026-W16 | R38: 2026-W17 | S38: 2026-W18 | T38: 2026-W19 | U38: 2026-W20 | V38: 2026-W21 | W38: 2026-W22 | X38: 2026-W23 | Y38: 2026-W24 | Z38: 2026-W25 | AA38: 2026-W26 | AB38: 2026-W27 | AC38: 2026-W28 | AD38: 2026-W29 | AE38: 2026-W30 | AF38: 2026-W31 | AG38: 2026-W32 | AH38: 2026-W33 | AI38: 2026-W34 | AJ38: 2026-W35 | AK38: 2026-W36 | AL38: 2026-W37 | AM38: 2026-W38 | AN38: 2026-W39 | AO38: 2026-W40 | AP38: 2026-W41 | AQ38: 2026-W42 | AR38: 2026-W43 | AS38: 2026-W44 | AT38: 2026-W45 | AU38: 2026-W46 | AV38: 2026-W47 | AW38: 2026-W48 | AX38: 2026-W49 | AY38: 2026-W50 | AZ38: 2026-W51 | BA38: 2026-W52
A39: Verden Meal Volume | B39: =(B28+B29)*SUMIF('Slot Selection'!K81:K116,TRUE,'Slot Selection'!$D$81:$D$116) -> 0 | C39: =(C28+C29)*SUMIF('Slot Selection'!L81:L116,TRUE,'Slot Selection'!$D$81:$D$116) -> 0 | D39: =(D28+D29)*SUMIF('Slot Selection'!M81:M116,TRUE,'Slot Selection'!$D$81:$D$116) -> 0 | E39: =(E28+E29)*SUMIF('Slot Selection'!N81:N116,TRUE,'Slot Selection'!$D$81:$D$116) -> 0 | F39: =(F28+F29)*SUMIF('Slot Selection'!O81:O116,TRUE,'Slot Selection'!$D$81:$D$116) -> 0 | G39: =(G28+G29)*SUMIF('Slot Selection'!P81:P116,TRUE,'Slot Selection'!$D$81:$D$116) -> 0 | H39: =(H28+H29)*SUMIF('Slot Selection'!Q81:Q116,TRUE,'Slot Selection'!$D$81:$D$116) -> 0 | I39: =(I28+I29)*SUMIF('Slot Selection'!R81:R116,TRUE,'Slot Selection'!$D$81:$D$116) -> 0 | ... N39: =(N28+N29)*SUMIF('Slot Selection'!W81:W116,TRUE,'Slot Selection'!$D$81:$D$116) -> 0 | O39: =(O28+O29)*SUMIF('Slot Selection'!X81:X116,TRUE,'Slot Selection'!$E$81:$E$116) -> 0 | P39: =(P28+P29)*SUMIF('Slot Selection'!Y81:Y116,TRUE,'Slot Selection'!$E$81:$E$116) -> 0 | Q39: =(Q28+Q29)*SUMIF('Slot Selection'!Z81:Z116,TRUE,'Slot Selection'!$E$81:$E$116) -> 0 | R39: =(R28+R29)*SUMIF('Slot Selection'!AA81:AA116,TRUE,'Slot Selection'!$D$81:$D$116) -> 0 | S39: =(S28+S29)*SUMIF('Slot Selection'!AB81:AB116,TRUE,'Slot Selection'!$D$81:$D$116) -> 808.23 | T39: =(T28+T29)*SUMIF('Slot Selection'!AC81:AC116,TRUE,'Slot Selection'!$E$81:$E$116) -> 4402.495 | U39: =(U28+U29)*SUMIF('Slot Selection'!AD81:AD116,TRUE,'Slot Selection'!$E$81:$E$116) -> 5266.5398 | V39: =(V28+V29)*SUMIF('Slot Selection'!AE81:AE116,TRUE,'Slot Selection'!$E$81:$E$116) -> 9809.1445 | W39: =(W28+W29)*SUMIF('Slot Selection'!AF81:AF116,TRUE,'Slot Selection'!$E$81:$E$116) -> 12210.776 | X39: =(X28+X29)*SUMIF('Slot Selection'!AG81:AG116,TRUE,'Slot Selection'!$F$81:$F$116) -> 16563.723 | Y39: =(Y28+Y29)*SUMIF('Slot Selection'!AH81:AH116,TRUE,'Slot Selection'!$F$81:$F$116) -> 17913.419 | Z39: =(Z28+Z29)*SUMIF('Slot Selection'!AI81:AI116,TRUE,'Slot Selection'!$F$81:$F$116) -> 19619.662 | AA39: =(AA28+AA29)*SUMIF('Slot Selection'!AJ81:AJ116,TRUE,'Slot Selection'!$F$81:$F$116) -> 20880.674 | AB39: =(AB28+AB29)*SUMIF('Slot Selection'!AK81:AK116,TRUE,'Slot Selection'!$F$81:$F$116) -> 20320.89 | AC39: =(AC28+AC29)*SUMIF('Slot Selection'!AL81:AL116,TRUE,'Slot Selection'!$F$81:$F$116) -> 19248.718 | AD39: =(AD28+AD29)*SUMIF('Slot Selection'!AM81:AM116,TRUE,'Slot Selection'!$F$81:$F$116) -> 17504.504 | AE39: =(AE28+AE29)*SUMIF('Slot Selection'!AN81:AN116,TRUE,'Slot Selection'!$F$81:$F$116) -> 17345.784 | AF39: =(AF28+AF29) -> 19951.972 | AG39: =(AG28+AG29) -> 22107.239 | AH39: =(AH28+AH29) -> 25337.513 | AI39: =(AI28+AI29) -> 28679.406 | AJ39: =(AJ28+AJ29) -> 30681.838 | AK39: =(AK28+AK29) -> 32703.729 | AL39: =(AL28+AL29) -> 35989.591 | AM39: =(AM28+AM29) -> 38834.757 | ... BA39: =(BA28+BA29) -> 19085.247
A40: Coman Meal Volume | B40: =(B28+B29)-B39 -> 12903 | C40: =(C28+C29)-C39 -> 18804 | D40: =(D28+D29)-D39 -> 29862 | E40: =(E28+E29)-E39 -> 32924 | F40: =(F28+F29)-F39 -> 32805 | G40: =(G28+G29)-G39 -> 35147 | H40: =(H28+H29)-H39 -> 34269 | I40: =(I28+I29)-I39 -> 34740 | ... BA40: =(BA28+BA29)-BA39 -> 0
A42: DE Volume | B42: 2026-W01 | C42: 2026-W02 | D42: 2026-W03 | E42: 2026-W04 | F42: 2026-W05 | G42: 2026-W06 | H42: 2026-W07 | I42: 2026-W08 | J42: 2026-W09 | K42: 2026-W10 | L42: 2026-W11 | M42: 2026-W12 | N42: 2026-W13 | O42: 2026-W14 | P42: 2026-W15 | Q42: 2026-W16 | R42: 2026-W17 | S42: 2026-W18 | T42: 2026-W19 | U42: 2026-W20 | V42: 2026-W21 | W42: 2026-W22 | X42: 2026-W23 | Y42: 2026-W24 | Z42: 2026-W25 | AA42: 2026-W26 | AB42: 2026-W27 | AC42: 2026-W28 | AD42: 2026-W29 | AE42: 2026-W30 | AF42: 2026-W31 | AG42: 2026-W32 | AH42: 2026-W33 | AI42: 2026-W34 | AJ42: 2026-W35 | AK42: 2026-W36 | AL42: 2026-W37 | AM42: 2026-W38 | AN42: 2026-W39 | AO42: 2026-W40 | AP42: 2026-W41 | AQ42: 2026-W42 | AR42: 2026-W43 | AS42: 2026-W44 | AT42: 2026-W45 | AU42: 2026-W46 | AV42: 2026-W47 | AW42: 2026-W48 | AX42: 2026-W49 | AY42: 2026-W50 | AZ42: 2026-W51 | BA42: 2026-W52
A43: Verden Meal Volume | B43: =(B30)*SUMIF('Slot Selection'!K42:K71,TRUE,'Slot Selection'!$D$42:$D$77) -> 0 | C43: =(C30)*SUMIF('Slot Selection'!L42:L71,TRUE,'Slot Selection'!$D$42:$D$77) -> 0 | D43: =(D30)*SUMIF('Slot Selection'!M42:M71,TRUE,'Slot Selection'!$D$42:$D$77) -> 0 | E43: =(E30)*SUMIF('Slot Selection'!N42:N71,TRUE,'Slot Selection'!$D$42:$D$77) -> 0 | F43: =(F30)*SUMIF('Slot Selection'!O42:O71,TRUE,'Slot Selection'!$D$42:$D$77) -> 0 | G43: =(G30)*SUMIF('Slot Selection'!P42:P71,TRUE,'Slot Selection'!$D$42:$D$77) -> 0 | H43: =(H30)*SUMIF('Slot Selection'!Q42:Q71,TRUE,'Slot Selection'!$D$42:$D$77) -> 0 | I43: =(I30)*SUMIF('Slot Selection'!R42:R71,TRUE,'Slot Selection'!$D$42:$D$77) -> 0 | ... N43: =(N30)*SUMIF('Slot Selection'!W42:W71,TRUE,'Slot Selection'!$D$42:$D$77) -> 0 | O43: =(O30)*SUMIF('Slot Selection'!X42:X71,TRUE,'Slot Selection'!$E$42:$E$77) -> 0 | P43: =(P30)*SUMIF('Slot Selection'!Y42:Y71,TRUE,'Slot Selection'!$E$42:$E$77) -> 0 | Q43: =(Q30)*SUMIF('Slot Selection'!Z42:Z71,TRUE,'Slot Selection'!$E$42:$E$77) -> 0 | R43: =(R30)*SUMIF('Slot Selection'!AA42:AA71,TRUE,'Slot Selection'!$D$42:$D$77) -> 0 | S43: =(S30)*SUMIF('Slot Selection'!AB42:AB71,TRUE,'Slot Selection'!$D$42:$D$77) -> 662.67 | T43: =(T30)*SUMIF('Slot Selection'!AC42:AC71,TRUE,'Slot Selection'!$E$42:$E$77) -> 3536.9055 | U43: =(U30)*SUMIF('Slot Selection'!AD42:AD71,TRUE,'Slot Selection'!$E$42:$E$77) -> 4320.5999 | V43: =(V30)*SUMIF('Slot Selection'!AE42:AE71,TRUE,'Slot Selection'!$E$42:$E$77) -> 7962.7892 | W43: =(W30)*SUMIF('Slot Selection'!AF42:AF71,TRUE,'Slot Selection'!$E$42:$E$77) -> 9157.7339 | X43: =(X30)*SUMIF('Slot Selection'!AG42:AG71,TRUE,'Slot Selection'!$F$42:$F$77) -> 12217.18 | Y43: =(Y30)*SUMIF('Slot Selection'!AH42:AH71,TRUE,'Slot Selection'!$F$42:$F$77) -> 12694.293 | Z43: =(Z30)*SUMIF('Slot Selection'!AI42:AI71,TRUE,'Slot Selection'!$F$42:$F$77) -> 15234.677 | AA43: =(AA30)*SUMIF('Slot Selection'!AJ42:AJ71,TRUE,'Slot Selection'!$F$42:$F$77) -> 15820.879 | AB43: =(AB30)*SUMIF('Slot Selection'!AK42:AK71,TRUE,'Slot Selection'!$F$42:$F$77) -> 16666.036 | AC43: =(AC30)*SUMIF('Slot Selection'!AL42:AL71,TRUE,'Slot Selection'!$F$42:$F$77) -> 15943.841 | AD43: =(AD30)*SUMIF('Slot Selection'!AM42:AM71,TRUE,'Slot Selection'!$F$42:$F$77) -> 15506.358 | AE43: =(AE30)*SUMIF('Slot Selection'!AN42:AN71,TRUE,'Slot Selection'!$F$42:$F$77) -> 14641.924 | AF43: =(AF30) -> 16429.427 | AG43: =(AG30) -> 15819.443 | AH43: =(AH30) -> 16782.575 | AI43: =(AI30) -> 17938.334 | AJ43: =(AJ30) -> 18588.448 | AK43: =(AK30) -> 18805.152 | AL43: =(AL30) -> 20899.964 | AM43: =(AM30) -> 23725.152 | ... BA43: =(BA30) -> 14663.092
A44: Coman Meal Volume | B44: =B30-B43 -> 13120 | C44: =C30-C43 -> 18009 | D44: =D30-D43 -> 23886 | E44: =E30-E43 -> 26001 | F44: =F30-F43 -> 26398 | G44: =G30-G43 -> 28331 | H44: =H30-H43 -> 28372 | I44: =I30-I43 -> 27692 | ... BA44: =BA30-BA43 -> 0

Sheet Slot Selection
A1: BENL | K1: 2026-M01 | L1: 2026-M01 | M1: 2026-M01 | N1: 2026-M01 | O1: 2026-M01 | P1: 2026-M02 | Q1: 2026-M02 | R1: 2026-M02 | S1: 2026-M02 | T1: 2026-M03 | U1: 2026-M03 | V1: 2026-M03 | W1: 2026-M03 | X1: 2026-M04 | Y1: 2026-M04 | Z1: 2026-M04 | AA1: 2026-M04 | AB1: 2026-M04 | AC1: 2026-M05 | AD1: 2026-M05 | AE1: 2026-M05 | AF1: 2026-M05 | AG1: 2026-M06 | AH1: 2026-M06 | AI1: 2026-M06 | AJ1: 2026-M06 | AK1: 2026-M07 | AL1: 2026-M07 | AM1: 2026-M07 | AN1: 2026-M07 | AO1: 2026-M07 | AP1: 2026-M08 | AQ1: 2026-M08 | AR1: 2026-M08 | AS1: 2026-M08 | AT1: 2026-M09 | AU1: 2026-M09 | AV1: 2026-M09 | AW1: 2026-M09 | AX1: 2026-M10 | AY1: 2026-M10 | AZ1: 2026-M10 | BA1: 2026-M10 | BB1: 2026-M10 | BC1: 2026-M11 | BD1: 2026-M11 | BE1: 2026-M11 | BF1: 2026-M11 | BG1: 2026-M12 | BH1: 2026-M12 | BI1: 2026-M12 | BJ1: 2026-M12
A2: Slot | B2: Protein | C2: Preference | D2: 18 | E2: 21 | F2: 24 | G2: 27 | H2: 30 | I2: 33 | J2: 36 | K2: 2026-W01 | L2: 2026-W02 | M2: 2026-W03 | N2: 2026-W04 | O2: 2026-W05 | P2: 2026-W06 | Q2: 2026-W07 | R2: 2026-W08 | S2: 2026-W09 | T2: 2026-W10 | U2: 2026-W11 | V2: 2026-W12 | W2: 2026-W13 | X2: 2026-W14 | Y2: 2026-W15 | Z2: 2026-W16 | AA2: 2026-W17 | AB2: 2026-W18 | AC2: 2026-W19 | AD2: 2026-W20 | AE2: 2026-W21 | AF2: 2026-W22 | AG2: 2026-W23 | AH2: 2026-W24 | AI2: 2026-W25 | AJ2: 2026-W26 | AK2: 2026-W27 | AL2: 2026-W28 | AM2: 2026-W29 | AN2: 2026-W30 | AO2: 2026-W31 | AP2: 2026-W32 | AQ2: 2026-W33 | AR2: 2026-W34 | AS2: 2026-W35 | AT2: 2026-W36 | AU2: 2026-W37 | AV2: 2026-W38 | AW2: 2026-W39 | AX2: 2026-W40 | AY2: 2026-W41 | AZ2: 2026-W42 | BA2: 2026-W43 | BB2: 2026-W44 | BC2: 2026-W45 | BD2: 2026-W46 | BE2: 2026-W47 | BF2: 2026-W48 | BG2: 2026-W49 | BH2: 2026-W50 | BI2: 2026-W51 | BJ2: 2026-W52
A3: 1 | B3: Chicken | C3: CS/P+ | D3: 0.1193 | E3: 0.1114 | F3: 0.1114 | G3: 0.1114 | H3: 0.0798 | I3: 0.0692 | J3: 0.0602 | K3: FALSE | L3: FALSE | M3: FALSE | N3: FALSE | O3: FALSE | P3: FALSE | Q3: FALSE | R3: FALSE | S3: FALSE | T3: FALSE | U3: FALSE | V3: FALSE | W3: FALSE | X3: FALSE | Y3: FALSE | Z3: FALSE | AA3: FALSE | AB3: FALSE | AC3: FALSE | AD3: FALSE | AE3: FALSE | AF3: FALSE | AG3: FALSE | AH3: FALSE | AI3: TRUE | AJ3: TRUE | AK3: TRUE | AL3: TRUE | AM3: TRUE | AN3: TRUE | AO3: TRUE | AP3: TRUE | AQ3: TRUE | AR3: TRUE | AS3: TRUE | AT3: TRUE | AU3: TRUE | AV3: TRUE | AW3: TRUE | AX3: TRUE | AY3: TRUE | AZ3: TRUE | BA3: TRUE | BB3: TRUE | BC3: TRUE | BD3: TRUE | BE3: TRUE | BF3: TRUE | BG3: TRUE | BH3: TRUE | BI3: TRUE | BJ3: TRUE
A4: 2 | B4: Chicken | C4: CS | D4: 0.1033 | E4: 0.0964 | F4: 0.0964 | G4: 0.0964 | H4: 0.0632 | I4: 0.0574 | J4: 0.0463 | K4: FALSE | L4: FALSE | M4: FALSE | N4: FALSE | O4: FALSE | P4: FALSE | Q4: FALSE | R4: FALSE | S4: FALSE | T4: FALSE | U4: FALSE | V4: FALSE | W4: FALSE | X4: FALSE | Y4: FALSE | Z4: FALSE | AA4: FALSE | AB4: FALSE | AC4: FALSE | AD4: FALSE | AE4: TRUE | AF4: FALSE | AG4: TRUE | AH4: TRUE | AI4: TRUE | AJ4: TRUE | AK4: TRUE | AL4: TRUE | AM4: TRUE | AN4: TRUE | AO4: TRUE | AP4: TRUE | AQ4: TRUE | AR4: TRUE | AS4: TRUE | AT4: TRUE | AU4: TRUE | AV4: TRUE | AW4: TRUE | AX4: TRUE | AY4: TRUE | AZ4: TRUE | BA4: TRUE | BB4: TRUE | BC4: TRUE | BD4: TRUE | BE4: TRUE | BF4: TRUE | BG4: TRUE | BH4: TRUE | BI4: TRUE | BJ4: TRUE
A5: 3 | B5: Beef | C5: Keto | D5: 0.097 | E5: 0.0808 | F5: 0.0673 | G5: 0.0673 | H5: 0.0525 | I5: 0.0412 | J5: 0.0324 | K5: FALSE | L5: FALSE | M5: FALSE | N5: FALSE | O5: FALSE | P5: FALSE | Q5: FALSE | R5: FALSE | S5: FALSE | T5: FALSE | U5: FALSE | V5: FALSE | W5: FALSE | X5: FALSE | Y5: FALSE | Z5: FALSE | AA5: FALSE | AB5: FALSE | AC5: FALSE | AD5: FALSE | AE5: FALSE | AF5: TRUE | AG5: TRUE | AH5: TRUE | AI5: TRUE | AJ5: TRUE | AK5: TRUE | AL5: TRUE | AM5: TRUE | AN5: TRUE | AO5: TRUE | AP5: TRUE | AQ5: TRUE | AR5: TRUE | AS5: TRUE | AT5: TRUE | AU5: TRUE | AV5: TRUE | AW5: TRUE | AX5: TRUE | AY5: TRUE | AZ5: TRUE | BA5: TRUE | BB5: TRUE | BC5: TRUE | BD5: TRUE | BE5: TRUE | BF5: TRUE | BG5: TRUE | BH5: TRUE | BI5: TRUE | BJ5: TRUE
A6: 4 | B6: Fish / Seafood / Beef | C6: P+ | D6: 0.0825 | E6: 0.0632 | F6: 0.0519 | G6: 0.0366 | H6: 0.0578 | I6: 0.0435 | J6: 0.0417 | K6: FALSE | L6: FALSE | M6: FALSE | N6: FALSE | O6: FALSE | P6: FALSE | Q6: FALSE | R6: FALSE | S6: FALSE | T6: FALSE | U6: FALSE | V6: FALSE | W6: FALSE | X6: FALSE | Y6: FALSE | Z6: FALSE | AA6: FALSE | AB6: FALSE | AC6: FALSE | AD6: FALSE | AE6: FALSE | AF6: TRUE | AG6: TRUE | AH6: TRUE | AI6: TRUE | AJ6: TRUE | AK6: TRUE | AL6: TRUE | AM6: TRUE | AN6: TRUE | AO6: TRUE | AP6: TRUE | AQ6: TRUE | AR6: TRUE | AS6: TRUE | AT6: TRUE | AU6: TRUE | AV6: TRUE | AW6: TRUE | AX6: TRUE | AY6: TRUE | AZ6: TRUE | BA6: TRUE | BB6: TRUE | BC6: TRUE | BD6: TRUE | BE6: TRUE | BF6: TRUE | BG6: TRUE | BH6: TRUE | BI6: TRUE | BJ6: TRUE
A7: 5 | B7: Chicken | C7: CS | D7: 0.0976 | E7: 0.0911 | F7: 0.0911 | G7: 0.0911 | H7: 0.0592 | I7: 0.0489 | J7: 0.037 | K7: FALSE | L7: FALSE | M7: FALSE | N7: FALSE | O7: FALSE | P7: FALSE | Q7: FALSE | R7: FALSE | S7: FALSE | T7: FALSE | U7: FALSE | V7: FALSE | W7: FALSE | X7: FALSE | Y7: FALSE | Z7: FALSE | AA7: FALSE | AB7: FALSE | AC7: FALSE | AD7: FALSE | AE7: FALSE | AF7: FALSE | AG7: FALSE | AH7: FALSE | AI7: FALSE | AJ7: FALSE | AK7: FALSE | AL7: FALSE | AM7: FALSE | AN7: FALSE | AO7: TRUE | AP7: TRUE | AQ7: TRUE | AR7: TRUE | AS7: TRUE | AT7: TRUE | AU7: TRUE | AV7: TRUE | AW7: TRUE | AX7: TRUE | AY7: TRUE | AZ7: TRUE | BA7: TRUE | BB7: TRUE | BC7: TRUE | BD7: TRUE | BE7: TRUE | BF7: TRUE | BG7: TRUE | BH7: TRUE | BI7: TRUE | BJ7: TRUE
A8: 6 | B8: Fish / Seafood | C8: Keto | D8: 0.0739 | E8: 0.0566 | F8: 0.0465 | G8: 0.0328 | H8: 0.046 | I8: 0.0399 | J8: 0.037 | K8: FALSE | L8: FALSE | M8: FALSE | N8: FALSE | O8: FALSE | P8: FALSE | Q8: FALSE | R8: FALSE | S8: FALSE | T8: FALSE | U8: FALSE | V8: FALSE | W8: FALSE | X8: FALSE | Y8: FALSE | Z8: FALSE | AA8: FALSE | AB8: FALSE | AC8: FALSE | AD8: TRUE | AE8: FALSE | AF8: TRUE | AG8: TRUE | AH8: TRUE | AI8: TRUE | AJ8: TRUE | AK8: TRUE | AL8: TRUE | AM8: TRUE | AN8: TRUE | AO8: TRUE | AP8: TRUE | AQ8: TRUE | AR8: TRUE | AS8: TRUE | AT8: TRUE | AU8: TRUE | AV8: TRUE | AW8: TRUE | AX8: TRUE | AY8: TRUE | AZ8: TRUE | BA8: TRUE | BB8: TRUE | BC8: TRUE | BD8: TRUE | BE8: TRUE | BF8: TRUE | BG8: TRUE | BH8: TRUE | BI8: TRUE | BJ8: TRUE
A9: 7 | B9: Chicken | C9: Keto | D9: 0.0622 | E9: 0.0581 | F9: 0.0581 | G9: 0.0581 | H9: 0.0402 | I9: 0.0376 | J9: 0.0324 | K9: FALSE | L9: FALSE | M9: FALSE | N9: FALSE | O9: FALSE | P9: FALSE | Q9: FALSE | R9: FALSE | S9: FALSE | T9: FALSE | U9: FALSE | V9: FALSE | W9: FALSE | X9: FALSE | Y9: FALSE | Z9: FALSE | AA9: FALSE | AB9: FALSE | AC9: FALSE | AD9: TRUE | AE9: FALSE | AF9: TRUE | AG9: TRUE | AH9: TRUE | AI9: TRUE | AJ9: TRUE | AK9: TRUE | AL9: TRUE | AM9: TRUE | AN9: TRUE | AO9: TRUE | AP9: TRUE | AQ9: TRUE | AR9: TRUE | AS9: TRUE | AT9: TRUE | AU9: TRUE | AV9: TRUE | AW9: TRUE | AX9: TRUE | AY9: TRUE | AZ9: TRUE | BA9: TRUE | BB9: TRUE | BC9: TRUE | BD9: TRUE | BE9: TRUE | BF9: TRUE | BG9: TRUE | BH9: TRUE | BI9: TRUE | BJ9: TRUE
A10: 8 | B10: Chicken | C10: Keto | D10: 0.0677 | E10: 0.0632 | F10: 0.0632 | G10: 0.0632 | H10: 0.0451 | I10: 0.0388 | J10: 0.0324 | K10: FALSE | L10: FALSE | M10: FALSE | N10: FALSE | O10: FALSE | P10: FALSE | Q10: FALSE | R10: FALSE | S10: FALSE | T10: FALSE | U10: FALSE | V10: FALSE | W10: FALSE | X10: FALSE | Y10: FALSE | Z10: FALSE | AA10: FALSE | AB10: FALSE | AC10: FALSE | AD10: FALSE | AE10: FALSE | AF10: FALSE | AG10: FALSE | AH10: FALSE | AI10: FALSE | AJ10: TRUE | AK10: TRUE | AL10: TRUE | AM10: TRUE | AN10: TRUE | AO10: TRUE | AP10: TRUE | AQ10: TRUE | AR10: TRUE | AS10: TRUE | AT10: TRUE | AU10: TRUE | AV10: TRUE | AW10: TRUE | AX10: TRUE | AY10: TRUE | AZ10: TRUE | BA10: TRUE | BB10: TRUE | BC10: TRUE | BD10: TRUE | BE10: TRUE | BF10: TRUE | BG10: TRUE | BH10: TRUE | BI10: TRUE | BJ10: TRUE
A11: 9 | B11: Vegetarian | C11: Veg | D11: 0.0166 | E11: 0.0166 | F11: 0.0166 | G11: 0.0093 | H11: 0.0154 | I11: 0.0159 | J11: 0.0162 | K11: FALSE | L11: FALSE | M11: FALSE | N11: FALSE | O11: FALSE | P11: FALSE | Q11: FALSE | R11: FALSE | S11: FALSE | T11: FALSE | U11: FALSE | V11: FALSE | W11: FALSE | X11: FALSE | Y11: FALSE | Z11: FALSE | AA11: FALSE | AB11: FALSE | AC11: FALSE | AD11: FALSE | AE11: TRUE | AF11: TRUE | AG11: TRUE | AH11: TRUE | AI11: TRUE | AJ11: TRUE | AK11: TRUE | AL11: TRUE | AM11: TRUE | AN11: TRUE | AO11: TRUE | AP11: TRUE | AQ11: TRUE | AR11: TRUE | AS11: TRUE | AT11: TRUE | AU11: TRUE | AV11: TRUE | AW11: TRUE | AX11: TRUE | AY11: TRUE | AZ11: TRUE | BA11: TRUE | BB11: TRUE | BC11: TRUE | BD11: TRUE | BE11: TRUE | BF11: TRUE | BG11: TRUE | BH11: TRUE | BI11: TRUE | BJ11: TRUE
A12: 10 | B12: Vegetarian | C12: Veg | D12: 0.0211 | E12: 0.0211 | F12: 0.0211 | G12: 0.0118 | H12: 0.0162 | I12: 0.017 | J12: 0.0162 | K12: FALSE | L12: FALSE | M12: FALSE | N12: FALSE | O12: FALSE | P12: FALSE | Q12: FALSE | R12: FALSE | S12: FALSE | T12: FALSE | U12: FALSE | V12: FALSE | W12: FALSE | X12: FALSE | Y12: FALSE | Z12: FALSE | AA12: FALSE | AB12: FALSE | AC12: FALSE | AD12: FALSE | AE12: FALSE | AF12: TRUE | AG12: TRUE | AH12: TRUE | AI12: TRUE | AJ12: TRUE | AK12: TRUE | AL12: TRUE | AM12: TRUE | AN12: TRUE | AO12: TRUE | AP12: TRUE | AQ12: TRUE | AR12: TRUE | AS12: TRUE | AT12: TRUE | AU12: TRUE | AV12: TRUE | AW12: TRUE | AX12: TRUE | AY12: TRUE | AZ12: TRUE | BA12: TRUE | BB12: TRUE | BC12: TRUE | BD12: TRUE | BE12: TRUE | BF12: TRUE | BG12: TRUE | BH12: TRUE | BI12: TRUE | BJ12: TRUE
A13: 11 | B13: Pork | C13: Flexible Slot | D13: 0.0215 | E13: 0.0215 | F13: 0.0215 | G13: 0.0215 | H13: 0.0212 | I13: 0.0195 | J13: 0.0185 | K13: FALSE | L13: FALSE | M13: FALSE | N13: FALSE | O13: FALSE | P13: FALSE | Q13: FALSE | R13: FALSE | S13: FALSE | T13: FALSE | U13: FALSE | V13: FALSE | W13: FALSE | X13: FALSE | Y13: FALSE | Z13: FALSE | AA13: FALSE | AB13: FALSE | AC13: FALSE | AD13: FALSE | AE13: FALSE | AF13: FALSE | AG13: FALSE | AH13: FALSE | AI13: FALSE | AJ13: FALSE | AK13: FALSE | AL13: FALSE | AM13: FALSE | AN13: FALSE | AO13: TRUE | AP13: TRUE | AQ13: TRUE | AR13: TRUE | AS13: TRUE | AT13: TRUE | AU13: TRUE | AV13: TRUE | AW13: TRUE | AX13: TRUE | AY13: TRUE | AZ13: TRUE | BA13: TRUE | BB13: TRUE | BC13: TRUE | BD13: TRUE | BE13: TRUE | BF13: TRUE | BG13: TRUE | BH13: TRUE | BI13: TRUE | BJ13: TRUE
A14: 12 | B14: Fish / Seafood | C14: P+ | D14: 0.0478 | E14: 0.0366 | F14: 0.03 | G14: 0.0212 | H14: 0.0355 | I14: 0.0325 | J14: 0.0324 | K14: FALSE | L14: FALSE | M14: FALSE | N14: FALSE | O14: FALSE | P14: FALSE | Q14: FALSE | R14: FALSE | S14: FALSE | T14: FALSE | U14: FALSE | V14: FALSE | W14: FALSE | X14: FALSE | Y14: FALSE | Z14: FALSE | AA14: FALSE | AB14: FALSE | AC14: FALSE | AD14: TRUE | AE14: TRUE | AF14: TRUE | AG14: TRUE | AH14: TRUE | AI14: TRUE | AJ14: TRUE | AK14: TRUE | AL14: TRUE | AM14: TRUE | AN14: TRUE | AO14: TRUE | AP14: TRUE | AQ14: TRUE | AR14: TRUE | AS14: TRUE | AT14: TRUE | AU14: TRUE | AV14: TRUE | AW14: TRUE | AX14: TRUE | AY14: TRUE | AZ14: TRUE | BA14: TRUE | BB14: TRUE | BC14: TRUE | BD14: TRUE | BE14: TRUE | BF14: TRUE | BG14: TRUE | BH14: TRUE | BI14: TRUE | BJ14: TRUE
... A20: 18 | B20: Pork | C20: CS | D20: 0.0233 | E20: 0.0233 | F20: 0.0233 | G20: 0.0233 | H20: 0.0196 | I20: 0.02 | J20: 0.0185 | K20: FALSE | L20: FALSE | M20: FALSE | N20: FALSE | O20: FALSE | P20: FALSE | Q20: FALSE | R20: FALSE | S20: FALSE | T20: FALSE | U20: FALSE | V20: FALSE | W20: FALSE | X20: FALSE | Y20: FALSE | Z20: FALSE | AA20: FALSE | AB20: FALSE | AC20: FALSE | AD20: FALSE | AE20: FALSE | AF20: FALSE | AG20: TRUE | AH20: TRUE | AI20: TRUE | AJ20: TRUE | AK20: TRUE | AL20: TRUE | AM20: TRUE | AN20: TRUE | AO20: TRUE | AP20: TRUE | AQ20: TRUE | AR20: TRUE | AS20: TRUE | AT20: TRUE | AU20: TRUE | AV20: TRUE | AW20: TRUE | AX20: TRUE | AY20: TRUE | AZ20: TRUE | BA20: TRUE | BB20: TRUE | BC20: TRUE | BD20: TRUE | BE20: TRUE | BF20: TRUE | BG20: TRUE | BH20: TRUE | BI20: TRUE | BJ20: TRUE
A21: 19 | B21: Fish / Seafood | C21: Athlete | E21: 0.0478 | F21: 0.042 | G21: 0.0277 | H21: 0.0338 | I21: 0.0346 | J21: 0.0324 | AC21: FALSE | AD21: FALSE | AE21: TRUE | AF21: TRUE | AG21: FALSE | AH21: TRUE | AI21: TRUE | AJ21: TRUE | AK21: TRUE | AL21: TRUE | AM21: TRUE | AN21: TRUE | AO21: TRUE | AP21: TRUE | AQ21: TRUE | AR21: TRUE | AS21: TRUE | AT21: TRUE | AU21: TRUE | AV21: TRUE | AW21: TRUE | AX21: TRUE | AY21: TRUE | AZ21: TRUE | BA21: TRUE | BB21: TRUE | BC21: TRUE | BD21: TRUE | BE21: TRUE | BF21: TRUE | BG21: TRUE | BH21: TRUE | BI21: TRUE | BJ21: TRUE
A22: 20 | B22: Beef | C22: Athlete | E22: 0.0215 | F22: 0.0179 | G22: 0.0179 | H22: 0.0208 | I22: 0.0224 | J22: 0.0231 | AC22: FALSE | AD22: FALSE | AE22: TRUE | AF22: FALSE | AG22: FALSE | AH22: TRUE | AI22: TRUE | AJ22: TRUE | AK22: TRUE | AL22: TRUE | AM22: TRUE | AN22: TRUE | AO22: TRUE | AP22: TRUE | AQ22: TRUE | AR22: TRUE | AS22: TRUE | AT22: TRUE | AU22: TRUE | AV22: TRUE | AW22: TRUE | AX22: TRUE | AY22: TRUE | AZ22: TRUE | BA22: TRUE | BB22: TRUE | BC22: TRUE | BD22: TRUE | BE22: TRUE | BF22: TRUE | BG22: TRUE | BH22: TRUE | BI22: TRUE | BJ22: TRUE
A23: 21 | B23: Chicken | C23: Athlete | E23: 0.03 | F23: 0.03 | G23: 0.03 | H23: 0.0301 | I23: 0.0334 | J23: 0.037 | AC23: FALSE | AD23: FALSE | AE23: FALSE | AF23: TRUE | AG23: TRUE | AH23: TRUE | AI23: TRUE | AJ23: TRUE | AK23: TRUE | AL23: TRUE | AM23: TRUE | AN23: TRUE | AO23: TRUE | AP23: TRUE | AQ23: TRUE | AR23: TRUE | AS23: TRUE | AT23: TRUE | AU23: TRUE | AV23: TRUE | AW23: TRUE | AX23: TRUE | AY23: TRUE | AZ23: TRUE | BA23: TRUE | BB23: TRUE | BC23: TRUE | BD23: TRUE | BE23: TRUE | BF23: TRUE | BG23: TRUE | BH23: TRUE | BI23: TRUE | BJ23: TRUE
A24: 22 | B24: Beef | C24: CS | F24: 0.0215 | G24: 0.0215 | H24: 0.0231 | I24: 0.0255 | J24: 0.0278 | AG24: TRUE | AH24: TRUE | AI24: TRUE | AJ24: TRUE | AK24: TRUE | AL24: TRUE | AM24: TRUE | AN24: TRUE | AO24: TRUE | AP24: TRUE | AQ24: TRUE | AR24: TRUE | AS24: TRUE | AT24: TRUE | AU24: TRUE | AV24: TRUE | AW24: TRUE | AX24: TRUE | AY24: TRUE | AZ24: TRUE | BA24: TRUE | BB24: TRUE | BC24: TRUE | BD24: TRUE | BE24: TRUE | BF24: TRUE | BG24: TRUE | BH24: TRUE | BI24: TRUE | BJ24: TRUE
A25: 23 | B25: Flexible Slot | C25: Mediterranean | F25: 0.03 | G25: 0.03 | H25: 0.0278 | I25: 0.0288 | J25: 0.0278 | AG25: TRUE | AH25: TRUE | AI25: TRUE | AJ25: TRUE | AK25: TRUE | AL25: TRUE | AM25: TRUE | AN25: TRUE | AO25: TRUE | AP25: TRUE | AQ25: TRUE | AR25: TRUE | AS25: TRUE | AT25: TRUE | AU25: TRUE | AV25: TRUE | AW25: TRUE | AX25: TRUE | AY25: TRUE | AZ25: TRUE | BA25: TRUE | BB25: TRUE | BC25: TRUE | BD25: TRUE | BE25: TRUE | BF25: TRUE | BG25: TRUE | BH25: TRUE | BI25: TRUE | BJ25: TRUE
A26: 24 | B26: Shrimp | C26: Mediterranean | F26: 0.0336 | G26: 0.0258 | H26: 0.0329 | I26: 0.034 | J26: 0.0324 | AG26: TRUE | AH26: TRUE | AI26: TRUE | AJ26: TRUE | AK26: TRUE | AL26: TRUE | AM26: TRUE | AN26: TRUE | AO26: TRUE | AP26: TRUE | AQ26: TRUE | AR26: TRUE | AS26: TRUE | AT26: TRUE | AU26: TRUE | AV26: TRUE | AW26: TRUE | AX26: TRUE | AY26: TRUE | AZ26: TRUE | BA26: TRUE | BB26: TRUE | BC26: TRUE | BD26: TRUE | BE26: TRUE | BF26: TRUE | BG26: TRUE | BH26: TRUE | BI26: TRUE | BJ26: TRUE
A27: 25 | B27: Fish / Seafood | C27: Mediterranean | G27: 0.03 | H27: 0.0319 | I27: 0.0325 | J27: 0.0324 | AK27: TRUE | AL27: TRUE | AM27: TRUE | AN27: TRUE | AO27: TRUE | AP27: TRUE | AQ27: TRUE | AR27: TRUE | AS27: TRUE | AT27: TRUE | AU27: TRUE | AV27: TRUE | AW27: TRUE | AX27: TRUE | AY27: TRUE | AZ27: TRUE | BA27: TRUE | BB27: TRUE | BC27: TRUE | BD27: TRUE | BE27: TRUE | BF27: TRUE | BG27: TRUE | BH27: TRUE | BI27: TRUE | BJ27: TRUE
A28: 26 | B28: Fish / Seafood | C28: Mediterranean | G28: 0.03 | H28: 0.0319 | I28: 0.0325 | J28: 0.0324 | AK28: TRUE | AL28: TRUE | AM28: TRUE | AN28: TRUE | AO28: TRUE | AP28: TRUE | AQ28: TRUE | AR28: TRUE | AS28: TRUE | AT28: TRUE | AU28: TRUE | AV28: TRUE | AW28: TRUE | AX28: TRUE | AY28: TRUE | AZ28: TRUE | BA28: TRUE | BB28: TRUE | BC28: TRUE | BD28: TRUE | BE28: TRUE | BF28: TRUE | BG28: TRUE | BH28: TRUE | BI28: TRUE | BJ28: TRUE
A29: 27 | B29: Vegetarian | C29: CS | G29: 0.0166 | H29: 0.0125 | I29: 0.0127 | J29: 0.0162 | AK29: TRUE | AL29: TRUE | AM29: TRUE | AN29: TRUE | AO29: TRUE | AP29: TRUE | AQ29: TRUE | AR29: TRUE | AS29: TRUE | AT29: TRUE | AU29: TRUE | AV29: TRUE | AW29: TRUE | AX29: TRUE | AY29: TRUE | AZ29: TRUE | BA29: TRUE | BB29: TRUE | BC29: TRUE | BD29: TRUE | BE29: TRUE | BF29: TRUE | BG29: TRUE | BH29: TRUE | BI29: TRUE | BJ29: TRUE
A30: 28 | B30: Shrimp | C30: Mediterranean | H30: 0.0319 | I30: 0.0325 | J30: 0.0324 | AO30: TRUE | AP30: TRUE | AQ30: TRUE | AR30: TRUE | AS30: TRUE | AT30: TRUE | AU30: TRUE | AV30: TRUE | AW30: TRUE | AX30: TRUE | AY30: TRUE | AZ30: TRUE | BA30: TRUE | BB30: TRUE | BC30: TRUE | BD30: TRUE | BE30: TRUE | BF30: TRUE | BG30: TRUE | BH30: TRUE | BI30: TRUE | BJ30: TRUE
A31: 29 | B31: Lamb | C31: Athlete | H31: 0.0273 | I31: 0.0278 | J31: 0.0278 | AO31: TRUE | AP31: TRUE | AQ31: TRUE | AR31: TRUE | AS31: TRUE | AT31: TRUE | AU31: TRUE | AV31: TRUE | AW31: TRUE | AX31: TRUE | AY31: TRUE | AZ31: TRUE | BA31: TRUE | BB31: TRUE | BC31: TRUE | BD31: TRUE | BE31: TRUE | BF31: TRUE | BG31: TRUE | BH31: TRUE | BI31: TRUE | BJ31: TRUE
A32: 30 | B32: Lamb | C32: Mediterranean | H32: 0.0273 | I32: 0.0278 | J32: 0.0278 | AO32: TRUE | AP32: TRUE | AQ32: TRUE | AR32: TRUE | AS32: TRUE | AT32: TRUE | AU32: TRUE | AV32: TRUE | AW32: TRUE | AX32: TRUE | AY32: TRUE | AZ32: TRUE | BA32: TRUE | BB32: TRUE | BC32: TRUE | BD32: TRUE | BE32: TRUE | BF32: TRUE | BG32: TRUE | BH32: TRUE | BI32: TRUE | BJ32: TRUE
A33: 31 | B33: Beef | I33: 0.0249 | J33: 0.0231 | AS33: TRUE | AT33: TRUE | AU33: TRUE | AV33: TRUE | AW33: TRUE | AX33: TRUE | AY33: TRUE | AZ33: TRUE | BA33: TRUE | BB33: TRUE | BC33: TRUE | BD33: TRUE | BE33: TRUE | BF33: TRUE | BG33: TRUE | BH33: TRUE | BI33: TRUE | BJ33: TRUE
A34: 32 | B34: Beef | I34: 0.0249 | J34: 0.0231 | AS34: TRUE | AT34: TRUE | AU34: TRUE | AV34: TRUE | AW34: TRUE | AX34: TRUE | AY34: TRUE | AZ34: TRUE | BA34: TRUE | BB34: TRUE | BC34: TRUE | BD34: TRUE | BE34: TRUE | BF34: TRUE | BG34: TRUE | BH34: TRUE | BI34: TRUE | BJ34: TRUE
A35: 33 | B35: Vegetarian | I35: 0.015 | J35: 0.0162 | AS35: TRUE | AT35: TRUE | AU35: TRUE | AV35: TRUE | AW35: TRUE | AX35: TRUE | AY35: TRUE | AZ35: TRUE | BA35: TRUE | BB35: TRUE | BC35: TRUE | BD35: TRUE | BE35: TRUE | BF35: TRUE | BG35: TRUE | BH35: TRUE | BI35: TRUE | BJ35: TRUE
A36: 34 | B36: Vegetarian | J36: 0.0162 | BG36: TRUE | BH36: TRUE | BI36: TRUE | BJ36: TRUE
A37: 35 | B37: Vegetarian | J37: 0.0162 | BG37: TRUE | BH37: TRUE | BI37: TRUE | BJ37: TRUE
A38: 36 | B38: White Fish | J38: 0.0324 | BG38: TRUE | BH38: TRUE | BI38: TRUE | BJ38: TRUE
K39: =countif(K2:K20,FALSE) -> 18 | L39: =countif(L2:L20,FALSE) -> 18 | M39: =countif(M2:M20,FALSE) -> 18 | N39: =countif(N2:N20,FALSE) -> 18 | O39: =countif(O2:O20,FALSE) -> 18 | P39: =countif(P2:P20,FALSE) -> 18 | Q39: =countif(Q2:Q20,FALSE) -> 18 | R39: =countif(R2:R20,FALSE) -> 18 | S39: =countif(S2:S23,FALSE) -> 18 | T39: =countif(T2:T23,FALSE) -> 18 | U39: =countif(U2:U23,FALSE) -> 18 | V39: =countif(V$2:V$26,FALSE) -> 18
A40: DE | K40: 2026-M01 | L40: 2026-M01 | M40: 2026-M01 | N40: 2026-M01 | O40: 2026-M01 | P40: 2026-M02 | Q40: 2026-M02 | R40: 2026-M02 | S40: 2026-M02 | T40: 2026-M03 | U40: 2026-M03 | V40: 2026-M03 | W40: 2026-M03 | X40: 2026-M04 | Y40: 2026-M04 | Z40: 2026-M04 | AA40: 2026-M04 | AB40: 2026-M04 | AC40: 2026-M05 | AD40: 2026-M05 | AE40: 2026-M05 | AF40: 2026-M05 | AG40: 2026-M06 | AH40: 2026-M06 | AI40: 2026-M06 | AJ40: 2026-M06 | AK40: 2026-M07 | AL40: 2026-M07 | AM40: 2026-M07 | AN40: 2026-M07 | AO40: 2026-M07 | AP40: 2026-M08 | AQ40: 2026-M08 | AR40: 2026-M08 | AS40: 2026-M08 | AT40: 2026-M09 | AU40: 2026-M09 | AV40: 2026-M09 | AW40: 2026-M09 | AX40: 2026-M10 | AY40: 2026-M10 | AZ40: 2026-M10 | BA40: 2026-M10 | BB40: 2026-M10 | BC40: 2026-M11 | BD40: 2026-M11 | BE40: 2026-M11 | BF40: 2026-M11 | BG40: 2026-M12 | BH40: 2026-M12 | BI40: 2026-M12 | BJ40: 2026-M12
A41: Slot | B41: Protein | C41: Preference | D41: 18 | E41: 21 | F41: 24 | G41: 27 | H41: 30 | I41: 33 | J41: 36 | K41: 2026-W01 | L41: 2026-W02 | M41: 2026-W03 | N41: 2026-W04 | O41: 2026-W05 | P41: 2026-W06 | Q41: 2026-W07 | R41: 2026-W08 | S41: 2026-W09 | T41: 2026-W10 | U41: 2026-W11 | V41: 2026-W12 | W41: 2026-W13 | X41: 2026-W14 | Y41: 2026-W15 | Z41: 2026-W16 | AA41: 2026-W17 | AB41: 2026-W18 | AC41: 2026-W19 | AD41: 2026-W20 | AE41: 2026-W21 | AF41: 2026-W22 | AG41: 2026-W23 | AH41: 2026-W24 | AI41: 2026-W25 | AJ41: 2026-W26 | AK41: 2026-W27 | AL41: 2026-W28 | AM41: 2026-W29 | AN41: 2026-W30 | AO41: 2026-W31 | AP41: 2026-W32 | AQ41: 2026-W33 | AR41: 2026-W34 | AS41: 2026-W35 | AT41: 2026-W36 | AU41: 2026-W37 | AV41: 2026-W38 | AW41: 2026-W39 | AX41: 2026-W40 | AY41: 2026-W41 | AZ41: 2026-W42 | BA41: 2026-W43 | BB41: 2026-W44 | BC41: 2026-W45 | BD41: 2026-W46 | BE41: 2026-W47 | BF41: 2026-W48 | BG41: 2026-W49 | BH41: 2026-W50 | BI41: 2026-W51 | BJ41: 2026-W52
A42: 1 | B42: Chicken | C42: CS/P+ | D42: 0.1193 | E42: 0.1114 | F42: 0.1114 | G42: 0.1114 | H42: 0.0798 | I42: 0.0692 | J42: 0.0602 | K42: FALSE | L42: FALSE | M42: FALSE | N42: FALSE | O42: FALSE | P42: FALSE | Q42: FALSE | R42: FALSE | S42: FALSE | T42: FALSE | U42: FALSE | V42: FALSE | W42: FALSE | X42: FALSE | Y42: FALSE | Z42: FALSE | AA42: FALSE | AB42: FALSE | AC42: FALSE | AD42: FALSE | AE42: FALSE | AF42: FALSE | AG42: FALSE | AH42: FALSE | AI42: TRUE | AJ42: TRUE | AK42: TRUE | AL42: TRUE | AM42: TRUE | AN42: TRUE | AO42: TRUE | AP42: TRUE | AQ42: TRUE | AR42: TRUE | AS42: TRUE | AT42: TRUE | AU42: TRUE | AV42: TRUE | AW42: TRUE | AX42: TRUE | AY42: TRUE | AZ42: TRUE | BA42: TRUE | BB42: TRUE | BC42: TRUE | BD42: TRUE | BE42: TRUE | BF42: TRUE | BG42: TRUE | BH42: TRUE | BI42: TRUE | BJ42: TRUE
A43: 2 | B43: Chicken | C43: CS | D43: 0.1033 | E43: 0.0964 | F43: 0.0964 | G43: 0.0964 | H43: 0.0632 | I43: 0.0574 | J43: 0.0463 | K43: FALSE | L43: FALSE | M43: FALSE | N43: FALSE | O43: FALSE | P43: FALSE | Q43: FALSE | R43: FALSE | S43: FALSE | T43: FALSE | U43: FALSE | V43: FALSE | W43: FALSE | X43: FALSE | Y43: FALSE | Z43: FALSE | AA43: FALSE | AB43: FALSE | AC43: FALSE | AD43: FALSE | AE43: TRUE | AF43: FALSE | AG43: TRUE | AH43: TRUE | AI43: TRUE | AJ43: TRUE | AK43: TRUE | AL43: TRUE | AM43: TRUE | AN43: TRUE | AO43: TRUE | AP43: TRUE | AQ43: TRUE | AR43: TRUE | AS43: TRUE | AT43: TRUE | AU43: TRUE | AV43: TRUE | AW43: TRUE | AX43: TRUE | AY43: TRUE | AZ43: TRUE | BA43: TRUE | BB43: TRUE | BC43: TRUE | BD43: TRUE | BE43: TRUE | BF43: TRUE | BG43: TRUE | BH43: TRUE | BI43: TRUE | BJ43: TRUE
A44: 3 | B44: Beef | C44: Keto | D44: 0.097 | E44: 0.0808 | F44: 0.0673 | G44: 0.0673 | H44: 0.0525 | I44: 0.0412 | J44: 0.0324 | K44: FALSE | L44: FALSE | M44: FALSE | N44: FALSE | O44: FALSE | P44: FALSE | Q44: FALSE | R44: FALSE | S44: FALSE | T44: FALSE | U44: FALSE | V44: FALSE | W44: FALSE | X44: FALSE | Y44: FALSE | Z44: FALSE | AA44: FALSE | AB44: FALSE | AC44: FALSE | AD44: FALSE | AE44: FALSE | AF44: TRUE | AG44: TRUE | AH44: TRUE | AI44: TRUE | AJ44: TRUE | AK44: TRUE | AL44: TRUE | AM44: TRUE | AN44: TRUE | AO44: TRUE | AP44: TRUE | AQ44: TRUE | AR44: TRUE | AS44: TRUE | AT44: TRUE | AU44: TRUE | AV44: TRUE | AW44: TRUE | AX44: TRUE | AY44: TRUE | AZ44: TRUE | BA44: TRUE | BB44: TRUE | BC44: TRUE | BD44: TRUE | BE44: TRUE | BF44: TRUE | BG44: TRUE | BH44: TRUE | BI44: TRUE | BJ44: TRUE
A45: 4 | B45: Fish / Seafood / Beef | C45: P+ | D45: 0.0825 | E45: 0.0632 | F45: 0.0519 | G45: 0.0366 | H45: 0.0578 | I45: 0.0435 | J45: 0.0417 | K45: FALSE | L45: FALSE | M45: FALSE | N45: FALSE | O45: FALSE | P45: FALSE | Q45: FALSE | R45: FALSE | S45: FALSE | T45: FALSE | U45: FALSE | V45: FALSE | W45: FALSE | X45: FALSE | Y45: FALSE | Z45: FALSE | AA45: FALSE | AB45: FALSE | AC45: TRUE | AD45: FALSE | AE45: FALSE | AF45: TRUE | AG45: TRUE | AH45: TRUE | AI45: TRUE | AJ45: TRUE | AK45: TRUE | AL45: TRUE | AM45: TRUE | AN45: TRUE | AO45: TRUE | AP45: TRUE | AQ45: TRUE | AR45: TRUE | AS45: TRUE | AT45: TRUE | AU45: TRUE | AV45: TRUE | AW45: TRUE | AX45: TRUE | AY45: TRUE | AZ45: TRUE | BA45: TRUE | BB45: TRUE | BC45: TRUE | BD45: TRUE | BE45: TRUE | BF45: TRUE | BG45: TRUE | BH45: TRUE | BI45: TRUE | BJ45: TRUE
...

Sheet ARCHIVED - Meal Selection
L1: DKSE | O1: DE | R1: BENL
A2: Week | B2: Code | C2: NEW Code | D2: Name | E2: Protein | F2: Preference | G2: Slot | H2: Slot Volume | I2: Total Verden Volume | J2: Safety Stock | K2: Total Volume DKSE | L2: Slot Volume Assumptions | M2: Share | N2: Total Volume DE | O2: Slot Volume Assumptions | P2: DE | Q2: Total Volume BENL | R2: Slot Volume Assumptions | S2: BENL
A3: 2026-W17 | B3: FE1346B | C3: FV1346A | D3: Parmesan & Garlic Cream Shredded Beef | E3: Fish / Seafood / Beef | F3: =vlookup(G3,'Slot Selection'!A:C,3,false) -> P+ | G3: 4 | H3: =vlookup(G3,'Slot Selection'!A:D,4,false) -> 0.0825 | I3: 4931 | K3: =vlookup(A3,Overview!B:J,7,false)+vlookup(A3,Overview!B:J,8,false) -> 25463 | L3: =K3*H3*M3 -> 1890.6278 | M3: 0.9 | N3: =vlookup(A3,Overview!B:J,9,false) -> 21910 | O3: =N3*H3*P3 -> 1626.8175 | P3: 0.9 | Q3: =vlookup(A3,Overview!B:G,5,false)+vlookup(A3,Overview!B:G,6,false) -> 47062 | R3: =Q3*H3*S3 -> 0 | S3: 0
A4: 2026-W17 | B4: FE0035F | C4: FV0035A | D4: Salmon with pesto | E4: =vlookup(G4,'Slot Selection'!A:B,2,false) -> Fish / Seafood | F4: =vlookup(G4,'Slot Selection'!A:C,3,false) -> Keto | G4: 6 | H4: =vlookup(G4,'Slot Selection'!A:D,4,false) -> 0.0739 | I4: 3005 | K4: =vlookup(A4,Overview!B:J,7,false)+vlookup(A4,Overview!B:J,8,false) -> 25463 | L4: =K4*H4*M4 -> 1693.5441 | M4: 0.9 | N4: =vlookup(A4,Overview!B:J,9,false) -> 21910 | O4: =N4*H4*P4 -> 1457.2341 | P4: 0.9 | Q4: =vlookup(A4,Overview!B:G,5,false)+vlookup(A4,Overview!B:G,6,false) -> 47062 | R4: =Q4*H4*S4 -> 0 | S4: 0
A5: 2026-W17 | B5: FE4053A | C5: FV4053A | D5: Gochugaru Chicken | E5: =vlookup(G5,'Slot Selection'!A:B,2,false) -> Chicken | F5: =vlookup(G5,'Slot Selection'!A:C,3,false) -> Keto | G5: 7 | H5: =vlookup(G5,'Slot Selection'!A:D,4,false) -> 0.0622 | I5: 2675 | K5: =vlookup(A5,Overview!B:J,7,false)+vlookup(A5,Overview!B:J,8,false) -> 25463 | L5: =K5*H5*M5 -> 1425.4187 | M5: 0.9 | N5: =vlookup(A5,Overview!B:J,9,false) -> 21910 | O5: =N5*H5*P5 -> 1226.5218 | P5: 0.9 | Q5: =vlookup(A5,Overview!B:G,5,false)+vlookup(A5,Overview!B:G,6,false) -> 47062 | R5: =Q5*H5*S5 -> 0 | S5: 0
A6: 2026-W17 | B6: FE4064A | C6: FV4064A | D6: Ginger Garlic Grilled Chicken | E6: =vlookup(G6,'Slot Selection'!A:B,2,false) -> Flexible Slot | F6: =vlookup(G6,'Slot Selection'!A:C,3,false) -> Flexible Slot | G6: 14 | H6: =vlookup(G6,'Slot Selection'!A:D,4,false) -> 0.0317 | I6: 863 | K6: =vlookup(A6,Overview!B:J,7,false)+vlookup(A6,Overview!B:J,8,false) -> 25463 | L6: =K6*H6*M6 -> 726.45939 | M6: 0.9 | N6: =vlookup(A6,Overview!B:J,9,false) -> 21910 | O6: =N6*H6*P6 -> 625.0923 | P6: 0.9 | Q6: =vlookup(A6,Overview!B:G,5,false)+vlookup(A6,Overview!B:G,6,false) -> 47062 | R6: =Q6*H6*S6 -> 0 | S6: 0
A7: 2026-W17 | B7: FE0472A | C7: FV0472A | D7: Indian Butter Chicken | E7: =vlookup(G7,'Slot Selection'!A:B,2,false) -> Flexible Slot | F7: =vlookup(G7,'Slot Selection'!A:C,3,false) -> Flexible Slot | G7: 16 | H7: =vlookup(G7,'Slot Selection'!A:D,4,false) -> 0.03 | I7: 938 | K7: =vlookup(A7,Overview!B:J,7,false)+vlookup(A7,Overview!B:J,8,false) -> 25463 | L7: =K7*H7*M7 -> 687.501 | M7: 0.9 | N7: =vlookup(A7,Overview!B:J,9,false) -> 21910 | O7: =N7*H7*P7 -> 591.57 | P7: 0.9 | Q7: =vlookup(A7,Overview!B:G,5,false)+vlookup(A7,Overview!B:G,6,false) -> 47062 | R7: =Q7*H7*S7 -> 0 | S7: 0
A8: 2026-W18 | B8: FE4063A | C8: FV4063A | D8: Cheddar pulled beef | E8: =vlookup(G8,'Slot Selection'!A:B,2,false) -> Beef | F8: =vlookup(G8,'Slot Selection'!A:C,3,false) -> Keto | G8: 3 | H8: =vlookup(G8,'Slot Selection'!A:E,4,false) -> 0.097 | I8: =1206+600 -> 1806 | J8: 600 | K8: =vlookup(A8,Overview!B:J,7,false)+vlookup(A8,Overview!B:J,8,false) -> 26941 | L8: =K8*H8*M8 -> 783.9831 | M8: 0.3 | N8: =vlookup(A8,Overview!B:J,9,false) -> 22089 | O8: =N8*H8*P8 -> 642.7899 | P8: 0.3 | Q8: =vlookup(A8,Overview!B:G,5,false)+vlookup(A8,Overview!B:G,6,false) -> 47825 | R8: =Q8*H8*S8 -> 0 | S8: 0
A9: 2026-W18 | B9: FE4039A | C9: FV4039A | D9: Salmon in creamy gochugaru sauce | E9: =vlookup(G9,'Slot Selection'!A:B,2,false) -> Fish / Seafood | F9: =vlookup(G9,'Slot Selection'!A:C,3,false) -> Keto | G9: 6 | H9: =vlookup(G9,'Slot Selection'!A:E,4,false) -> 0.0739 | I9: =1711+600 -> 2311 | J9: 600 | K9: =vlookup(A9,Overview!B:J,7,false)+vlookup(A9,Overview!B:J,8,false) -> 26941 | L9: =K9*H9*M9 -> 995.46995 | M9: 0.5 | N9: =vlookup(A9,Overview!B:J,9,false) -> 22089 | O9: =N9*H9*P9 -> 816.18855 | P9: 0.5 | Q9: =vlookup(A9,Overview!B:G,5,false)+vlookup(A9,Overview!B:G,6,false) -> 47825 | R9: =Q9*H9*S9 -> 0 | S9: 0
A10: 2026-W18 | B10: FE0601B | C10: FV0601A | D10: Mozzarella Burger & Roasted Potatoes | E10: =vlookup(G10,'Slot Selection'!A:B,2,false) -> Flexible Slot | F10: =vlookup(G10,'Slot Selection'!A:C,3,false) -> Flexible Slot | G10: 16 | H10: =vlookup(G10,'Slot Selection'!A:E,4,false) -> 0.03 | I10: =3508+600 -> 4108 | J10: 600 | K10: =vlookup(A10,Overview!B:J,7,false)+vlookup(A10,Overview!B:J,8,false) -> 26941 | L10: =K10*H10*M10 -> 808.23 | M10: 1 | N10: =vlookup(A10,Overview!B:J,9,false) -> 22089 | O10: =N10*H10*P10 -> 662.67 | P10: 1 | Q10: =vlookup(A10,Overview!B:G,5,false)+vlookup(A10,Overview!B:G,6,false) -> 47825 | R10: =Q10*H10*S10 -> 1434.75 | S10: 1
A11: 2026-W19 | B11: FE0413F | C11: FV0413A | D11: Braised beef in herby jus | E11: =vlookup(G11,'Slot Selection'!A:B,2,false) -> Beef | F11: =vlookup(G11,'Slot Selection'!A:C,3,false) -> Keto | G11: 3 | H11: =vlookup(G11,'Slot Selection'!A:E,5,false) -> 0.0808 | I11: 3692 | K11: =vlookup(A11,Overview!B:J,7,false)+vlookup(A11,Overview!B:J,8,false) -> 24747.021 | L11: =K11*H11*M11 -> 1999.5593 | M11: 1 | N11: =vlookup(A11,Overview!B:J,9,false) -> 19881.425 | O11: =N11*H11*P11 -> 1606.4192 | P11: 1 | Q11: =vlookup(A11,Overview!B:G,5,false)+vlookup(A11,Overview!B:G,6,false) -> 46935.599 | R11: =Q11*H11*S11 -> 0 | S11: 0
