Workbook
Name _4p_ASL_3: #REF!
Name _3p_ASL_1: #REF!
Name new_job_id_long: #REF!
Name new_job_id_staging: #REF!
Name ASL_2: #REF!
Name _2p_ASL_3: #REF!
Name new_job_staging: #REF!
Name _3p_ASL_3: #REF!
Name ASL_4: #REF!
Name ASL_3: #REF!
Name timezone_rack_planning: #REF!
Name _4p_ASL_3: #REF!
Name _2p_ASL_3: #REF!
Name ASL_2: #REF!
Name master_job_staging: #REF!
Name _3p_ASL_1: #REF!
Name ASL_1: #REF!
Name ASL_4: #REF!
Name master_job_separation: #REF!
Name master_job: #REF!
Name master_job_long: #REF!
Name job_inbox: #REF!
Name new_job_separation: #REF!
Name _2p_ASL_1: #REF!
Name new_job_id_separation: #REF!
Name new_job_status_staging: #REF!
Name _4p_ASL_1: #REF!
Name _3p_ASL_3: #REF!
Name new_job_status_separation: #REF!
Name new_job_status: #REF!
Name new_job_long: #REF!
Name _4p_ASL_1: #REF!
Name _2p_ASL_1: #REF!
Name new_job_id: #REF!
Name ASL_1: #REF!
Name ASL_3: #REF!
Name timestamp_rack_planning: #REF!

Sheet Control Panel
C2: Action Panel
C4: Current HF Week | D4: 2026-W19 | F4: Video Anleitungen
F5: Für jeden Schritt gibt es auch Video Anleitungen.
C6: See documentation for some tabs here: | D6: Documentation | F6: Anleitung
B12: 1 | C12: Create RackfileUPLOAD from HALO
F14: Market | G14: Where to pull from | H14: The tab name
C15: Script settings (don't change) | F15: Market | G15: Halo Link | H15: Tab Name
C16: Halo Link (based on the market selected) | D16: {=XLOOKUP(D30,F16:F24,G16:G24,,0)} -> https://docs.google.com/spreadsheets/d/1VRy_bAGXr4TaGPM2D8dsD6YtY2-RWpgyooUQViQEPQs/edit?gid=1096610893#gid=1096610893 | F16: F-DE | G16: https://docs.google.com/spreadsheets/d/1VRy_bAGXr4TaGPM2D8dsD6YtY2-RWpgyooUQViQEPQs/edit?gid=1096610893#gid=1096610893 | H16: [static] exportP2L - DACH
C17: Tab name (based on the market selected) | D17: {=XLOOKUP(D30,F16:F24,H16:H24,,0)} -> [static] exportP2L - DACH | F17: F-Nordics | G17: https://docs.google.com/spreadsheets/d/1VRy_bAGXr4TaGPM2D8dsD6YtY2-RWpgyooUQViQEPQs/edit?gid=549415256#gid=549415256 | H17: [static] exportP2L - Nordics
C18: Folder Id (based on the market selected) | D18: {=XLOOKUP(D30,F16:F24,I16:I24,,0)}
C28: Settings | F28: Last run for: [F-DE] at [30.04.2026 16:44:38]
C29: For which ASLs do you want to generate it? | D29: 3
C30: Which market do you want to use? | D30: F-DE
B35: 2 | C35: Create rack labels
C37: Instructions
B38: 1 | C38: Labels are generated automatically from the RackfileUPLOAD tab.
B39: 2 | C39: Check if everything is correct
B40: 3 | C40: [Optional] Press the resize button to adjust the text size to fit cells
B42: 4 | C42: Export the labels as a PDF so they can be printed. You can adjust print settings in the code
C44: Reset format
C45: If the format got changed or you want to define a new format for the labels, you can change this in the _label formats tab and then click the button below. It takes a while.
B54: 3 | C54: Create the e-label file
C56: Settings
C57: Select ASLs in cell D29 (above)
B60: 4 | C60: Create test box file and QR codes
C62: Instructions
C63: The tool replaces [FILE_NAME] in the template with the file name defined below. Then downloads this as a CSV and saves it. It also creates the accompanying QR codes and exports these as a pdf. Edit the template tab if you want. The script will replace any mention of [FILE_NAME] in any column. See hidden tabs for the working sheets; "test boxfile" & "QR codes"
C65: Replace with:
C66: =D69&"_"&D4&"_TEST_"&TEXT(NOW(),"dd_mm_yyyy") -> F-DE_2026-W19_TEST_01_05_2026
C68: Settings
C69: Which market do you want to use? | D69: F-DE

Sheet I

Sheet exportP2L
A1: =IFERROR(__xludf.DUMMYFUNCTION("IMPORTRANGE('Control Panel'!D16,'Control Panel'!D17&""!A:Z"")"),"Recipe") -> Recipe | B1: =IFERROR(__xludf.DUMMYFUNCTION("""COMPUTED_VALUE"""),"Ingredient") -> Ingredient | C1: =IFERROR(__xludf.DUMMYFUNCTION("""COMPUTED_VALUE"""),"SKU") -> SKU | D1: =IFERROR(__xludf.DUMMYFUNCTION("""COMPUTED_VALUE"""),"Line") -> Line | E1: =IFERROR(__xludf.DUMMYFUNCTION("""COMPUTED_VALUE"""),"FlowRackPosition") -> FlowRackPosition | F1: =IFERROR(__xludf.DUMMYFUNCTION("""COMPUTED_VALUE"""),"Quantity") -> Quantity | G1: =IFERROR(__xludf.DUMMYFUNCTION("""COMPUTED_VALUE"""),"ScanRegEx") -> ScanRegEx | H1: =IFERROR(__xludf.DUMMYFUNCTION("""COMPUTED_VALUE"""),"StorageConditions") -> StorageConditions
A2: =IFERROR(__xludf.DUMMYFUNCTION("""COMPUTED_VALUE"""),"Factor Box Small") -> Factor Box Small | B2: =IFERROR(__xludf.DUMMYFUNCTION("""COMPUTED_VALUE"""),"Factor Box Small") -> Factor Box Small | C2: =IFERROR(__xludf.DUMMYFUNCTION("""COMPUTED_VALUE"""),"Factor Box Small") -> Factor Box Small | D2: =IFERROR(__xludf.DUMMYFUNCTION("""COMPUTED_VALUE"""),"ASL1") -> ASL1 | E2: =IFERROR(__xludf.DUMMYFUNCTION("""COMPUTED_VALUE"""),"F05") -> F05 | F2: =IFERROR(__xludf.DUMMYFUNCTION("""COMPUTED_VALUE"""),1.0) -> 1 | H2: =IFERROR(__xludf.DUMMYFUNCTION("""COMPUTED_VALUE"""),"Packaging") -> Packaging
A3: =IFERROR(__xludf.DUMMYFUNCTION("""COMPUTED_VALUE"""),"Factor Box Medium") -> Factor Box Medium | B3: =IFERROR(__xludf.DUMMYFUNCTION("""COMPUTED_VALUE"""),"Factor Box Medium") -> Factor Box Medium | C3: =IFERROR(__xludf.DUMMYFUNCTION("""COMPUTED_VALUE"""),"Factor Box Medium") -> Factor Box Medium | D3: =IFERROR(__xludf.DUMMYFUNCTION("""COMPUTED_VALUE"""),"ASL1") -> ASL1 | E3: =IFERROR(__xludf.DUMMYFUNCTION("""COMPUTED_VALUE"""),"F03") -> F03 | F3: =IFERROR(__xludf.DUMMYFUNCTION("""COMPUTED_VALUE"""),1.0) -> 1 | H3: =IFERROR(__xludf.DUMMYFUNCTION("""COMPUTED_VALUE"""),"Packaging") -> Packaging
A4: =IFERROR(__xludf.DUMMYFUNCTION("""COMPUTED_VALUE"""),"Factor Box Large") -> Factor Box Large | B4: =IFERROR(__xludf.DUMMYFUNCTION("""COMPUTED_VALUE"""),"Factor Box Large") -> Factor Box Large | C4: =IFERROR(__xludf.DUMMYFUNCTION("""COMPUTED_VALUE"""),"Factor Box Large") -> Factor Box Large | D4: =IFERROR(__xludf.DUMMYFUNCTION("""COMPUTED_VALUE"""),"ASL1") -> ASL1 | E4: =IFERROR(__xludf.DUMMYFUNCTION("""COMPUTED_VALUE"""),"F02") -> F02 | F4: =IFERROR(__xludf.DUMMYFUNCTION("""COMPUTED_VALUE"""),1.0) -> 1 | H4: =IFERROR(__xludf.DUMMYFUNCTION("""COMPUTED_VALUE"""),"Packaging") -> Packaging
A5: =IFERROR(__xludf.DUMMYFUNCTION("""COMPUTED_VALUE"""),"Factor Liner Medium1") -> Factor Liner Medium1 | B5: =IFERROR(__xludf.DUMMYFUNCTION("""COMPUTED_VALUE"""),"Factor Liner Medium1") -> Factor Liner Medium1 | C5: =IFERROR(__xludf.DUMMYFUNCTION("""COMPUTED_VALUE"""),"Factor Liner Medium1") -> Factor Liner Medium1 | D5: =IFERROR(__xludf.DUMMYFUNCTION("""COMPUTED_VALUE"""),"ASL1") -> ASL1 | E5: =IFERROR(__xludf.DUMMYFUNCTION("""COMPUTED_VALUE"""),"F08") -> F08 | F5: =IFERROR(__xludf.DUMMYFUNCTION("""COMPUTED_VALUE"""),1.0) -> 1 | H5: =IFERROR(__xludf.DUMMYFUNCTION("""COMPUTED_VALUE"""),"Packaging") -> Packaging
A6: =IFERROR(__xludf.DUMMYFUNCTION("""COMPUTED_VALUE"""),"Factor Liner Medium2") -> Factor Liner Medium2 | B6: =IFERROR(__xludf.DUMMYFUNCTION("""COMPUTED_VALUE"""),"Factor Liner Medium2") -> Factor Liner Medium2 | C6: =IFERROR(__xludf.DUMMYFUNCTION("""COMPUTED_VALUE"""),"Factor Liner Medium2") -> Factor Liner Medium2 | D6: =IFERROR(__xludf.DUMMYFUNCTION("""COMPUTED_VALUE"""),"ASL1") -> ASL1 | E6: =IFERROR(__xludf.DUMMYFUNCTION("""COMPUTED_VALUE"""),"F12") -> F12 | F6: =IFERROR(__xludf.DUMMYFUNCTION("""COMPUTED_VALUE"""),1.0) -> 1 | H6: =IFERROR(__xludf.DUMMYFUNCTION("""COMPUTED_VALUE"""),"Packaging") -> Packaging
A7: =IFERROR(__xludf.DUMMYFUNCTION("""COMPUTED_VALUE"""),"Factor Liner Large1") -> Factor Liner Large1 | B7: =IFERROR(__xludf.DUMMYFUNCTION("""COMPUTED_VALUE"""),"Factor Liner Large1") -> Factor Liner Large1 | C7: =IFERROR(__xludf.DUMMYFUNCTION("""COMPUTED_VALUE"""),"Factor Liner Large1") -> Factor Liner Large1 | D7: =IFERROR(__xludf.DUMMYFUNCTION("""COMPUTED_VALUE"""),"ASL1") -> ASL1 | E7: =IFERROR(__xludf.DUMMYFUNCTION("""COMPUTED_VALUE"""),"F07") -> F07 | F7: =IFERROR(__xludf.DUMMYFUNCTION("""COMPUTED_VALUE"""),1.0) -> 1 | H7: =IFERROR(__xludf.DUMMYFUNCTION("""COMPUTED_VALUE"""),"Packaging") -> Packaging
A8: =IFERROR(__xludf.DUMMYFUNCTION("""COMPUTED_VALUE"""),"Factor Liner Large2") -> Factor Liner Large2 | B8: =IFERROR(__xludf.DUMMYFUNCTION("""COMPUTED_VALUE"""),"Factor Liner Large2") -> Factor Liner Large2 | C8: =IFERROR(__xludf.DUMMYFUNCTION("""COMPUTED_VALUE"""),"Factor Liner Large2") -> Factor Liner Large2 | D8: =IFERROR(__xludf.DUMMYFUNCTION("""COMPUTED_VALUE"""),"ASL1") -> ASL1 | E8: =IFERROR(__xludf.DUMMYFUNCTION("""COMPUTED_VALUE"""),"F11") -> F11 | F8: =IFERROR(__xludf.DUMMYFUNCTION("""COMPUTED_VALUE"""),1.0) -> 1 | H8: =IFERROR(__xludf.DUMMYFUNCTION("""COMPUTED_VALUE"""),"Packaging") -> Packaging
A9: =IFERROR(__xludf.DUMMYFUNCTION("""COMPUTED_VALUE"""),"Factor Liner Small1") -> Factor Liner Small1 | B9: =IFERROR(__xludf.DUMMYFUNCTION("""COMPUTED_VALUE"""),"Factor Liner Small1") -> Factor Liner Small1 | C9: =IFERROR(__xludf.DUMMYFUNCTION("""COMPUTED_VALUE"""),"Factor Liner Small1") -> Factor Liner Small1 | D9: =IFERROR(__xludf.DUMMYFUNCTION("""COMPUTED_VALUE"""),"ASL1") -> ASL1 | E9: =IFERROR(__xludf.DUMMYFUNCTION("""COMPUTED_VALUE"""),"F06") -> F06 | F9: =IFERROR(__xludf.DUMMYFUNCTION("""COMPUTED_VALUE"""),1.0) -> 1 | H9: =IFERROR(__xludf.DUMMYFUNCTION("""COMPUTED_VALUE"""),"Packaging") -> Packaging
A10: =IFERROR(__xludf.DUMMYFUNCTION("""COMPUTED_VALUE"""),"Factor Liner Small2") -> Factor Liner Small2 | B10: =IFERROR(__xludf.DUMMYFUNCTION("""COMPUTED_VALUE"""),"Factor Liner Small2") -> Factor Liner Small2 | C10: =IFERROR(__xludf.DUMMYFUNCTION("""COMPUTED_VALUE"""),"Factor Liner Small2") -> Factor Liner Small2 | D10: =IFERROR(__xludf.DUMMYFUNCTION("""COMPUTED_VALUE"""),"ASL1") -> ASL1 | E10: =IFERROR(__xludf.DUMMYFUNCTION("""COMPUTED_VALUE"""),"F10") -> F10 | F10: =IFERROR(__xludf.DUMMYFUNCTION("""COMPUTED_VALUE"""),1.0) -> 1 | H10: =IFERROR(__xludf.DUMMYFUNCTION("""COMPUTED_VALUE"""),"Packaging") -> Packaging
A11: =IFERROR(__xludf.DUMMYFUNCTION("""COMPUTED_VALUE"""),"FR1") -> FR1 | B11: =IFERROR(__xludf.DUMMYFUNCTION("""COMPUTED_VALUE"""),"FA-DE Freebies") -> FA-DE Freebies | C11: =IFERROR(__xludf.DUMMYFUNCTION("""COMPUTED_VALUE"""),"Loyalties") -> Loyalties | D11: =IFERROR(__xludf.DUMMYFUNCTION("""COMPUTED_VALUE"""),"ASL1") -> ASL1 | E11: =IFERROR(__xludf.DUMMYFUNCTION("""COMPUTED_VALUE"""),"F143") -> F143 | F11: =IFERROR(__xludf.DUMMYFUNCTION("""COMPUTED_VALUE"""),1.0) -> 1 | H11: =IFERROR(__xludf.DUMMYFUNCTION("""COMPUTED_VALUE"""),"Chilled") -> Chilled
A12: =IFERROR(__xludf.DUMMYFUNCTION("""COMPUTED_VALUE"""),"WB1") -> WB1 | B12: =IFERROR(__xludf.DUMMYFUNCTION("""COMPUTED_VALUE"""),"FA-DE Welcome Booklet") -> FA-DE Welcome Booklet | C12: =IFERROR(__xludf.DUMMYFUNCTION("""COMPUTED_VALUE"""),"Loyalties") -> Loyalties | D12: =IFERROR(__xludf.DUMMYFUNCTION("""COMPUTED_VALUE"""),"ASL1") -> ASL1 | E12: =IFERROR(__xludf.DUMMYFUNCTION("""COMPUTED_VALUE"""),"F142") -> F142 | F12: =IFERROR(__xludf.DUMMYFUNCTION("""COMPUTED_VALUE"""),1.0) -> 1 | H12: =IFERROR(__xludf.DUMMYFUNCTION("""COMPUTED_VALUE"""),"Chilled") -> Chilled
A13: =IFERROR(__xludf.DUMMYFUNCTION("""COMPUTED_VALUE"""),"FLY1") -> FLY1 | B13: =IFERROR(__xludf.DUMMYFUNCTION("""COMPUTED_VALUE"""),"FA-DE First Box - Flyer about program") -> FA-DE First Box - Flyer about program | C13: =IFERROR(__xludf.DUMMYFUNCTION("""COMPUTED_VALUE"""),"Loyalties") -> Loyalties | D13: =IFERROR(__xludf.DUMMYFUNCTION("""COMPUTED_VALUE"""),"ASL1") -> ASL1 | E13: =IFERROR(__xludf.DUMMYFUNCTION("""COMPUTED_VALUE"""),"F141") -> F141 | F13: =IFERROR(__xludf.DUMMYFUNCTION("""COMPUTED_VALUE"""),1.0) -> 1 | H13: =IFERROR(__xludf.DUMMYFUNCTION("""COMPUTED_VALUE"""),"Chilled") -> Chilled
A14: =IFERROR(__xludf.DUMMYFUNCTION("""COMPUTED_VALUE"""),"BAG1") -> BAG1 | B14: =IFERROR(__xludf.DUMMYFUNCTION("""COMPUTED_VALUE"""),"FA-DE Second Box - Tote Bag") -> FA-DE Second Box - Tote Bag | C14: =IFERROR(__xludf.DUMMYFUNCTION("""COMPUTED_VALUE"""),"Loyalties") -> Loyalties | D14: =IFERROR(__xludf.DUMMYFUNCTION("""COMPUTED_VALUE"""),"ASL1") -> ASL1 | E14: =IFERROR(__xludf.DUMMYFUNCTION("""COMPUTED_VALUE"""),"F139") -> F139 | F14: =IFERROR(__xludf.DUMMYFUNCTION("""COMPUTED_VALUE"""),1.0) -> 1 | H14: =IFERROR(__xludf.DUMMYFUNCTION("""COMPUTED_VALUE"""),"Chilled") -> Chilled
A15: =IFERROR(__xludf.DUMMYFUNCTION("""COMPUTED_VALUE"""),"FLY2") -> FLY2 | B15: =IFERROR(__xludf.DUMMYFUNCTION("""COMPUTED_VALUE"""),"FA-DE Second Box - Flyer") -> FA-DE Second Box - Flyer | C15: =IFERROR(__xludf.DUMMYFUNCTION("""COMPUTED_VALUE"""),"Loyalties") -> Loyalties | D15: =IFERROR(__xludf.DUMMYFUNCTION("""COMPUTED_VALUE"""),"ASL1") -> ASL1 | E15: =IFERROR(__xludf.DUMMYFUNCTION("""COMPUTED_VALUE"""),"F140") -> F140 | F15: =IFERROR(__xludf.DUMMYFUNCTION("""COMPUTED_VALUE"""),1.0) -> 1 | H15: =IFERROR(__xludf.DUMMYFUNCTION("""COMPUTED_VALUE"""),"Chilled") -> Chilled
A16: =IFERROR(__xludf.DUMMYFUNCTION("""COMPUTED_VALUE"""),"SOC1") -> SOC1 | B16: =IFERROR(__xludf.DUMMYFUNCTION("""COMPUTED_VALUE"""),"FA-DE Third Box - Socks") -> FA-DE Third Box - Socks | C16: =IFERROR(__xludf.DUMMYFUNCTION("""COMPUTED_VALUE"""),"Loyalties") -> Loyalties | D16: =IFERROR(__xludf.DUMMYFUNCTION("""COMPUTED_VALUE"""),"ASL1") -> ASL1 | E16: =IFERROR(__xludf.DUMMYFUNCTION("""COMPUTED_VALUE"""),"F138") -> F138 | F16: =IFERROR(__xludf.DUMMYFUNCTION("""COMPUTED_VALUE"""),1.0) -> 1 | H16: =IFERROR(__xludf.DUMMYFUNCTION("""COMPUTED_VALUE"""),"Chilled") -> Chilled
A17: =IFERROR(__xludf.DUMMYFUNCTION("""COMPUTED_VALUE"""),"FLY3") -> FLY3 | B17: =IFERROR(__xludf.DUMMYFUNCTION("""COMPUTED_VALUE"""),"FA-DE Third Box - Flyer") -> FA-DE Third Box - Flyer | C17: =IFERROR(__xludf.DUMMYFUNCTION("""COMPUTED_VALUE"""),"Loyalties") -> Loyalties | D17: =IFERROR(__xludf.DUMMYFUNCTION("""COMPUTED_VALUE"""),"ASL1") -> ASL1 | E17: =IFERROR(__xludf.DUMMYFUNCTION("""COMPUTED_VALUE"""),"F137") -> F137 | F17: =IFERROR(__xludf.DUMMYFUNCTION("""COMPUTED_VALUE"""),1.0) -> 1 | H17: =IFERROR(__xludf.DUMMYFUNCTION("""COMPUTED_VALUE"""),"Chilled") -> Chilled
A18: =IFERROR(__xludf.DUMMYFUNCTION("""COMPUTED_VALUE"""),"FLA1") -> FLA1 | B18: =IFERROR(__xludf.DUMMYFUNCTION("""COMPUTED_VALUE"""),"FA-DE Fourth Box - Hydroflask") -> FA-DE Fourth Box - Hydroflask | C18: =IFERROR(__xludf.DUMMYFUNCTION("""COMPUTED_VALUE"""),"Loyalties") -> Loyalties | D18: =IFERROR(__xludf.DUMMYFUNCTION("""COMPUTED_VALUE"""),"ASL1") -> ASL1 | E18: =IFERROR(__xludf.DUMMYFUNCTION("""COMPUTED_VALUE"""),"F135") -> F135 | F18: =IFERROR(__xludf.DUMMYFUNCTION("""COMPUTED_VALUE"""),1.0) -> 1 | H18: =IFERROR(__xludf.DUMMYFUNCTION("""COMPUTED_VALUE"""),"Chilled") -> Chilled
A19: =IFERROR(__xludf.DUMMYFUNCTION("""COMPUTED_VALUE"""),"FLY4") -> FLY4 | B19: =IFERROR(__xludf.DUMMYFUNCTION("""COMPUTED_VALUE"""),"FA-DE Fourth Box - Flyer") -> FA-DE Fourth Box - Flyer | C19: =IFERROR(__xludf.DUMMYFUNCTION("""COMPUTED_VALUE"""),"Loyalties") -> Loyalties | D19: =IFERROR(__xludf.DUMMYFUNCTION("""COMPUTED_VALUE"""),"ASL1") -> ASL1 | E19: =IFERROR(__xludf.DUMMYFUNCTION("""COMPUTED_VALUE"""),"F136") -> F136 | F19: =IFERROR(__xludf.DUMMYFUNCTION("""COMPUTED_VALUE"""),1.0) -> 1 | H19: =IFERROR(__xludf.DUMMYFUNCTION("""COMPUTED_VALUE"""),"Chilled") -> Chilled
A20: =IFERROR(__xludf.DUMMYFUNCTION("""COMPUTED_VALUE"""),"Ice6") -> Ice6 | B20: =IFERROR(__xludf.DUMMYFUNCTION("""COMPUTED_VALUE"""),"IcePack1") -> IcePack1 | C20: =IFERROR(__xludf.DUMMYFUNCTION("""COMPUTED_VALUE"""),"IcePack") -> IcePack | D20: =IFERROR(__xludf.DUMMYFUNCTION("""COMPUTED_VALUE"""),"ASL1") -> ASL1 | E20: =IFERROR(__xludf.DUMMYFUNCTION("""COMPUTED_VALUE"""),"F144") -> F144 | F20: =IFERROR(__xludf.DUMMYFUNCTION("""COMPUTED_VALUE"""),1.0) -> 1 | H20: =IFERROR(__xludf.DUMMYFUNCTION("""COMPUTED_VALUE"""),"Chilled") -> Chilled
A21: =IFERROR(__xludf.DUMMYFUNCTION("""COMPUTED_VALUE"""),"Ice9") -> Ice9 | B21: =IFERROR(__xludf.DUMMYFUNCTION("""COMPUTED_VALUE"""),"IcePack1") -> IcePack1 | C21: =IFERROR(__xludf.DUMMYFUNCTION("""COMPUTED_VALUE"""),"IcePack") -> IcePack | D21: =IFERROR(__xludf.DUMMYFUNCTION("""COMPUTED_VALUE"""),"ASL1") -> ASL1 | E21: =IFERROR(__xludf.DUMMYFUNCTION("""COMPUTED_VALUE"""),"F144") -> F144 | F21: =IFERROR(__xludf.DUMMYFUNCTION("""COMPUTED_VALUE"""),1.0) -> 1 | H21: =IFERROR(__xludf.DUMMYFUNCTION("""COMPUTED_VALUE"""),"Chilled") -> Chilled
A22: =IFERROR(__xludf.DUMMYFUNCTION("""COMPUTED_VALUE"""),"Ice12") -> Ice12 | B22: =IFERROR(__xludf.DUMMYFUNCTION("""COMPUTED_VALUE"""),"IcePack1") -> IcePack1 | C22: =IFERROR(__xludf.DUMMYFUNCTION("""COMPUTED_VALUE"""),"IcePack") -> IcePack | D22: =IFERROR(__xludf.DUMMYFUNCTION("""COMPUTED_VALUE"""),"ASL1") -> ASL1 | E22: =IFERROR(__xludf.DUMMYFUNCTION("""COMPUTED_VALUE"""),"F144") -> F144 | F22: =IFERROR(__xludf.DUMMYFUNCTION("""COMPUTED_VALUE"""),2.0) -> 2 | H22: =IFERROR(__xludf.DUMMYFUNCTION("""COMPUTED_VALUE"""),"Chilled") -> Chilled
A23: =IFERROR(__xludf.DUMMYFUNCTION("""COMPUTED_VALUE"""),"Ice6") -> Ice6 | B23: =IFERROR(__xludf.DUMMYFUNCTION("""COMPUTED_VALUE"""),"IcePack2") -> IcePack2 | C23: =IFERROR(__xludf.DUMMYFUNCTION("""COMPUTED_VALUE"""),"IcePack") -> IcePack | D23: =IFERROR(__xludf.DUMMYFUNCTION("""COMPUTED_VALUE"""),"ASL1") -> ASL1 | E23: =IFERROR(__xludf.DUMMYFUNCTION("""COMPUTED_VALUE"""),"F105") -> F105 | F23: =IFERROR(__xludf.DUMMYFUNCTION("""COMPUTED_VALUE"""),0.0) -> 0 | H23: =IFERROR(__xludf.DUMMYFUNCTION("""COMPUTED_VALUE"""),"Chilled") -> Chilled
A24: =IFERROR(__xludf.DUMMYFUNCTION("""COMPUTED_VALUE"""),"Ice9") -> Ice9 | B24: =IFERROR(__xludf.DUMMYFUNCTION("""COMPUTED_VALUE"""),"IcePack2") -> IcePack2 | C24: =IFERROR(__xludf.DUMMYFUNCTION("""COMPUTED_VALUE"""),"IcePack") -> IcePack | D24: =IFERROR(__xludf.DUMMYFUNCTION("""COMPUTED_VALUE"""),"ASL1") -> ASL1 | E24: =IFERROR(__xludf.DUMMYFUNCTION("""COMPUTED_VALUE"""),"F105") -> F105 | F24: =IFERROR(__xludf.DUMMYFUNCTION("""COMPUTED_VALUE"""),1.0) -> 1 | H24: =IFERROR(__xludf.DUMMYFUNCTION("""COMPUTED_VALUE"""),"Chilled") -> Chilled
A25: =IFERROR(__xludf.DUMMYFUNCTION("""COMPUTED_VALUE"""),"Ice12") -> Ice12 | B25: =IFERROR(__xludf.DUMMYFUNCTION("""COMPUTED_VALUE"""),"IcePack2") -> IcePack2 | C25: =IFERROR(__xludf.DUMMYFUNCTION("""COMPUTED_VALUE"""),"IcePack") -> IcePack | D25: =IFERROR(__xludf.DUMMYFUNCTION("""COMPUTED_VALUE"""),"ASL1") -> ASL1 | E25: =IFERROR(__xludf.DUMMYFUNCTION("""COMPUTED_VALUE"""),"F105") -> F105 | F25: =IFERROR(__xludf.DUMMYFUNCTION("""COMPUTED_VALUE"""),0.0) -> 0 | H25: =IFERROR(__xludf.DUMMYFUNCTION("""COMPUTED_VALUE"""),"Chilled") -> Chilled
A26: =IFERROR(__xludf.DUMMYFUNCTION("""COMPUTED_VALUE"""),"Ice6") -> Ice6 | B26: =IFERROR(__xludf.DUMMYFUNCTION("""COMPUTED_VALUE"""),"IcePack3") -> IcePack3 | C26: =IFERROR(__xludf.DUMMYFUNCTION("""COMPUTED_VALUE"""),"IcePack") -> IcePack | D26: =IFERROR(__xludf.DUMMYFUNCTION("""COMPUTED_VALUE"""),"ASL1") -> ASL1 | E26: =IFERROR(__xludf.DUMMYFUNCTION("""COMPUTED_VALUE"""),"F127") -> F127 | F26: =IFERROR(__xludf.DUMMYFUNCTION("""COMPUTED_VALUE"""),1.0) -> 1 | H26: =IFERROR(__xludf.DUMMYFUNCTION("""COMPUTED_VALUE"""),"Chilled") -> Chilled
A27: =IFERROR(__xludf.DUMMYFUNCTION("""COMPUTED_VALUE"""),"Ice9") -> Ice9 | B27: =IFERROR(__xludf.DUMMYFUNCTION("""COMPUTED_VALUE"""),"IcePack3") -> IcePack3 | C27: =IFERROR(__xludf.DUMMYFUNCTION("""COMPUTED_VALUE"""),"IcePack") -> IcePack | D27: =IFERROR(__xludf.DUMMYFUNCTION("""COMPUTED_VALUE"""),"ASL1") -> ASL1 | E27: =IFERROR(__xludf.DUMMYFUNCTION("""COMPUTED_VALUE"""),"F127") -> F127 | F27: =IFERROR(__xludf.DUMMYFUNCTION("""COMPUTED_VALUE"""),1.0) -> 1 | H27: =IFERROR(__xludf.DUMMYFUNCTION("""COMPUTED_VALUE"""),"Chilled") -> Chilled
A28: =IFERROR(__xludf.DUMMYFUNCTION("""COMPUTED_VALUE"""),"Ice12") -> Ice12 | B28: =IFERROR(__xludf.DUMMYFUNCTION("""COMPUTED_VALUE"""),"IcePack3") -> IcePack3 | C28: =IFERROR(__xludf.DUMMYFUNCTION("""COMPUTED_VALUE"""),"IcePack") -> IcePack | D28: =IFERROR(__xludf.DUMMYFUNCTION("""COMPUTED_VALUE"""),"ASL1") -> ASL1 | E28: =IFERROR(__xludf.DUMMYFUNCTION("""COMPUTED_VALUE"""),"F127") -> F127 | F28: =IFERROR(__xludf.DUMMYFUNCTION("""COMPUTED_VALUE"""),2.0) -> 2 | H28: =IFERROR(__xludf.DUMMYFUNCTION("""COMPUTED_VALUE"""),"Chilled") -> Chilled
A29: =IFERROR(__xludf.DUMMYFUNCTION("""COMPUTED_VALUE"""),"220_1p") -> 220_1p | B29: =IFERROR(__xludf.DUMMYFUNCTION("""COMPUTED_VALUE"""),"220 - Free4Life_ Ginger Lemon Apple Wellness Shot_Single") -> 220 - Free4Life_ Ginger Lemon Apple Wellness Shot_Single | C29: =IFERROR(__xludf.DUMMYFUNCTION("""COMPUTED_VALUE"""),"BEV-00-136840-3a") -> BEV-00-136840-3a | D29: =IFERROR(__xludf.DUMMYFUNCTION("""COMPUTED_VALUE"""),"ASL1") -> ASL1 | E29: =IFERROR(__xludf.DUMMYFUNCTION("""COMPUTED_VALUE"""),"F89") -> F89 | F29: =IFERROR(__xludf.DUMMYFUNCTION("""COMPUTED_VALUE"""),1.0) -> 1 | H29: =IFERROR(__xludf.DUMMYFUNCTION("""COMPUTED_VALUE"""),"Chilled") -> Chilled
A30: =IFERROR(__xludf.DUMMYFUNCTION("""COMPUTED_VALUE"""),"221_1p") -> 221_1p | B30: =IFERROR(__xludf.DUMMYFUNCTION("""COMPUTED_VALUE"""),"221 - Free4Life_ Spirulina Ginger Lime Ginger Shot_Single") -> 221 - Free4Life_ Spirulina Ginger Lime Ginger Shot_Single | C30: =IFERROR(__xludf.DUMMYFUNCTION("""COMPUTED_VALUE"""),"BEV-00-137951-2a") -> BEV-00-137951-2a | D30: =IFERROR(__xludf.DUMMYFUNCTION("""COMPUTED_VALUE"""),"ASL1") -> ASL1 | E30: =IFERROR(__xludf.DUMMYFUNCTION("""COMPUTED_VALUE"""),"F112") -> F112 | F30: =IFERROR(__xludf.DUMMYFUNCTION("""COMPUTED_VALUE"""),1.0) -> 1 | H30: =IFERROR(__xludf.DUMMYFUNCTION("""COMPUTED_VALUE"""),"Chilled") -> Chilled
A31: =IFERROR(__xludf.DUMMYFUNCTION("""COMPUTED_VALUE"""),"222_1p") -> 222_1p | B31: =IFERROR(__xludf.DUMMYFUNCTION("""COMPUTED_VALUE"""),"222 - Free4Life_ Turmeric Cayenne Pineapple Ginger Shot_Single") -> 222 - Free4Life_ Turmeric Cayenne Pineapple Ginger Shot_Single | C31: =IFERROR(__xludf.DUMMYFUNCTION("""COMPUTED_VALUE"""),"BEV-00-137952-2a") -> BEV-00-137952-2a | D31: =IFERROR(__xludf.DUMMYFUNCTION("""COMPUTED_VALUE"""),"ASL1") -> ASL1 | E31: =IFERROR(__xludf.DUMMYFUNCTION("""COMPUTED_VALUE"""),"F124") -> F124 | F31: =IFERROR(__xludf.DUMMYFUNCTION("""COMPUTED_VALUE"""),1.0) -> 1 | H31: =IFERROR(__xludf.DUMMYFUNCTION("""COMPUTED_VALUE"""),"Chilled") -> Chilled
A32: =IFERROR(__xludf.DUMMYFUNCTION("""COMPUTED_VALUE"""),"301_1p") -> 301_1p | B32: =IFERROR(__xludf.DUMMYFUNCTION("""COMPUTED_VALUE"""),"565072 - Gegrilltes Hähnchen mit Ratatouille") -> 565072 - Gegrilltes Hähnchen mit Ratatouille | C32: =IFERROR(__xludf.DUMMYFUNCTION("""COMPUTED_VALUE"""),"CON-00-136674-3") -> CON-00-136674-3 | D32: =IFERROR(__xludf.DUMMYFUNCTION("""COMPUTED_VALUE"""),"ASL1") -> ASL1 | E32: =IFERROR(__xludf.DUMMYFUNCTION("""COMPUTED_VALUE"""),"F97") -> F97 | F32: =IFERROR(__xludf.DUMMYFUNCTION("""COMPUTED_VALUE"""),1.0) -> 1 | H32: =IFERROR(__xludf.DUMMYFUNCTION("""COMPUTED_VALUE"""),"Chilled") -> Chilled
A33: =IFERROR(__xludf.DUMMYFUNCTION("""COMPUTED_VALUE"""),"302_1p") -> 302_1p | B33: =IFERROR(__xludf.DUMMYFUNCTION("""COMPUTED_VALUE"""),"565209 - Grünes Chili-Hähnchen mit Quinoa-Salsa") -> 565209 - Grünes Chili-Hähnchen mit Quinoa-Salsa | C33: =IFERROR(__xludf.DUMMYFUNCTION("""COMPUTED_VALUE"""),"CON-00-152205-2") -> CON-00-152205-2 | D33: =IFERROR(__xludf.DUMMYFUNCTION("""COMPUTED_VALUE"""),"ASL1") -> ASL1 | E33: =IFERROR(__xludf.DUMMYFUNCTION("""COMPUTED_VALUE"""),"F133") -> F133 | F33: =IFERROR(__xludf.DUMMYFUNCTION("""COMPUTED_VALUE"""),1.0) -> 1 | H33: =IFERROR(__xludf.DUMMYFUNCTION("""COMPUTED_VALUE"""),"Chilled") -> Chilled
A34: =IFERROR(__xludf.DUMMYFUNCTION("""COMPUTED_VALUE"""),"303_1p") -> 303_1p | B34: =IFERROR(__xludf.DUMMYFUNCTION("""COMPUTED_VALUE"""),"565309 - Geschmortes Rind in Kräuterjus") -> 565309 - Geschmortes Rind in Kräuterjus | C34: =IFERROR(__xludf.DUMMYFUNCTION("""COMPUTED_VALUE"""),"CON-00-136698-3") -> CON-00-136698-3 | D34: =IFERROR(__xludf.DUMMYFUNCTION("""COMPUTED_VALUE"""),"ASL1") -> ASL1 | E34: =IFERROR(__xludf.DUMMYFUNCTION("""COMPUTED_VALUE"""),"F88") -> F88 | F34: =IFERROR(__xludf.DUMMYFUNCTION("""COMPUTED_VALUE"""),1.0) -> 1 | H34: =IFERROR(__xludf.DUMMYFUNCTION("""COMPUTED_VALUE"""),"Chilled") -> Chilled
A35: =IFERROR(__xludf.DUMMYFUNCTION("""COMPUTED_VALUE"""),"304_1p") -> 304_1p | B35: =IFERROR(__xludf.DUMMYFUNCTION("""COMPUTED_VALUE"""),"565064 - Lachs in Senf-Dill-Sauce") -> 565064 - Lachs in Senf-Dill-Sauce | C35: =IFERROR(__xludf.DUMMYFUNCTION("""COMPUTED_VALUE"""),"CON-00-137745-2") -> CON-00-137745-2 | D35: =IFERROR(__xludf.DUMMYFUNCTION("""COMPUTED_VALUE"""),"ASL1") -> ASL1 | E35: =IFERROR(__xludf.DUMMYFUNCTION("""COMPUTED_VALUE"""),"F55") -> F55 | F35: =IFERROR(__xludf.DUMMYFUNCTION("""COMPUTED_VALUE"""),1.0) -> 1 | H35: =IFERROR(__xludf.DUMMYFUNCTION("""COMPUTED_VALUE"""),"Chilled") -> Chilled
A36: =IFERROR(__xludf.DUMMYFUNCTION("""COMPUTED_VALUE"""),"305_1p") -> 305_1p | B36: =IFERROR(__xludf.DUMMYFUNCTION("""COMPUTED_VALUE"""),"565178 - Westafrikanisches Hähnchen-Erdnuss-Curry") -> 565178 - Westafrikanisches Hähnchen-Erdnuss-Curry | C36: =IFERROR(__xludf.DUMMYFUNCTION("""COMPUTED_VALUE"""),"CON-00-150748-2") -> CON-00-150748-2 | D36: =IFERROR(__xludf.DUMMYFUNCTION("""COMPUTED_VALUE"""),"ASL1") -> ASL1 | E36: =IFERROR(__xludf.DUMMYFUNCTION("""COMPUTED_VALUE"""),"F109") -> F109 | F36: =IFERROR(__xludf.DUMMYFUNCTION("""COMPUTED_VALUE"""),1.0) -> 1 | H36: =IFERROR(__xludf.DUMMYFUNCTION("""COMPUTED_VALUE"""),"Chilled") -> Chilled
A37: =IFERROR(__xludf.DUMMYFUNCTION("""COMPUTED_VALUE"""),"306_1p") -> 306_1p | B37: =IFERROR(__xludf.DUMMYFUNCTION("""COMPUTED_VALUE"""),"565189 - Lachs Piccata") -> 565189 - Lachs Piccata | C37: =IFERROR(__xludf.DUMMYFUNCTION("""COMPUTED_VALUE"""),"CON-00-152025-2") -> CON-00-152025-2 | D37: =IFERROR(__xludf.DUMMYFUNCTION("""COMPUTED_VALUE"""),"ASL1") -> ASL1 | E37: =IFERROR(__xludf.DUMMYFUNCTION("""COMPUTED_VALUE"""),"F96") -> F96 | F37: =IFERROR(__xludf.DUMMYFUNCTION("""COMPUTED_VALUE"""),1.0) -> 1 | H37: =IFERROR(__xludf.DUMMYFUNCTION("""COMPUTED_VALUE"""),"Chilled") -> Chilled
A38: =IFERROR(__xludf.DUMMYFUNCTION("""COMPUTED_VALUE"""),"307_1p") -> 307_1p | B38: =IFERROR(__xludf.DUMMYFUNCTION("""COMPUTED_VALUE"""),"565164 - Hähnchen mit karamellisierten Zwiebeln & Emmentaler-Fondue") -> 565164 - Hähnchen mit karamellisierten Zwiebeln & Emmentaler-Fondue | C38: =IFERROR(__xludf.DUMMYFUNCTION("""COMPUTED_VALUE"""),"CON-00-148220-2") -> CON-00-148220-2 | D38: =IFERROR(__xludf.DUMMYFUNCTION("""COMPUTED_VALUE"""),"ASL1") -> ASL1 | E38: =IFERROR(__xludf.DUMMYFUNCTION("""COMPUTED_VALUE"""),"F92") -> F92 | F38: =IFERROR(__xludf.DUMMYFUNCTION("""COMPUTED_VALUE"""),1.0) -> 1 | H38: =IFERROR(__xludf.DUMMYFUNCTION("""COMPUTED_VALUE"""),"Chilled") -> Chilled
A39: =IFERROR(__xludf.DUMMYFUNCTION("""COMPUTED_VALUE"""),"308_1p") -> 308_1p | B39: =IFERROR(__xludf.DUMMYFUNCTION("""COMPUTED_VALUE"""),"565043 - Würziges Hähnchen mit Jalapeño, Limette und Cheddar") -> 565043 - Würziges Hähnchen mit Jalapeño, Limette und Cheddar | C39: =IFERROR(__xludf.DUMMYFUNCTION("""COMPUTED_VALUE"""),"CON-00-136638-3") -> CON-00-136638-3 | D39: =IFERROR(__xludf.DUMMYFUNCTION("""COMPUTED_VALUE"""),"ASL1") -> ASL1 | E39: =IFERROR(__xludf.DUMMYFUNCTION("""COMPUTED_VALUE"""),"F65") -> F65 | F39: =IFERROR(__xludf.DUMMYFUNCTION("""COMPUTED_VALUE"""),1.0) -> 1 | H39: =IFERROR(__xludf.DUMMYFUNCTION("""COMPUTED_VALUE"""),"Chilled") -> Chilled
A40: =IFERROR(__xludf.DUMMYFUNCTION("""COMPUTED_VALUE"""),"309_1p") -> 309_1p | B40: =IFERROR(__xludf.DUMMYFUNCTION("""COMPUTED_VALUE"""),"565244 - Cremiges Tomaten-Risotto") -> 565244 - Cremiges Tomaten-Risotto | C40: =IFERROR(__xludf.DUMMYFUNCTION("""COMPUTED_VALUE"""),"CON-00-136629-3") -> CON-00-136629-3 | D40: =IFERROR(__xludf.DUMMYFUNCTION("""COMPUTED_VALUE"""),"ASL1") -> ASL1 | E40: =IFERROR(__xludf.DUMMYFUNCTION("""COMPUTED_VALUE"""),"F134") -> F134 | F40: =IFERROR(__xludf.DUMMYFUNCTION("""COMPUTED_VALUE"""),1.0) -> 1 | H40: =IFERROR(__xludf.DUMMYFUNCTION("""COMPUTED_VALUE"""),"Chilled") -> Chilled
...

Sheet RackfileUPLOAD
A1: Recipe | B1: Line | C1: FlowRackPosition | D1: Quantity | E1: SKU | F1: Ingredient | G1: ScanRegEx | H1: LabelPos | I1: UniCode | J1: DisplayName | K1: Gramage | L1: Sort | M1: PortionSize
A2: Factor Box Large | B2: ASL3 | C2: F02 | D2: 1 | E2: Factor Box Large | F2: Factor Box Large | H2: ASL3F02 | I2: ASL3F02 | J2: Factor Box Large | L2: 2 | M2: {=IF(ISNUMBER(LEFT(A2:A3367)+0)*(RIGHT(A2:A3367)="p"),RIGHT(A2:A3367,2),IF(A2:A3367="",,"0p"))} -> 0p
A3: Factor Box Medium | B3: ASL3 | C3: F03 | D3: 1 | E3: Factor Box Medium | F3: Factor Box Medium | H3: ASL3F03 | I3: ASL3F03 | J3: Factor Box Medium | L3: 3 | M3: 0p
A4: Factor Box Small | B4: ASL3 | C4: F05 | D4: 1 | E4: Factor Box Small | F4: Factor Box Small | H4: ASL3F05 | I4: ASL3F05 | J4: Factor Box Small | L4: 5 | M4: 0p
A5: Factor Liner Small1 | B5: ASL3 | C5: F06 | D5: 1 | E5: Factor Liner Small1 | F5: Factor Liner Small1 | H5: ASL3F06 | I5: ASL3F06 | J5: Factor Liner Small1 | L5: 6 | M5: 0p
A6: Factor Liner Large1 | B6: ASL3 | C6: F07 | D6: 1 | E6: Factor Liner Large1 | F6: Factor Liner Large1 | H6: ASL3F07 | I6: ASL3F07 | J6: Factor Liner Large1 | L6: 7 | M6: 0p
A7: Factor Liner Medium1 | B7: ASL3 | C7: F08 | D7: 1 | E7: Factor Liner Medium1 | F7: Factor Liner Medium1 | H7: ASL3F08 | I7: ASL3F08 | J7: Factor Liner Medium1 | L7: 8 | M7: 0p
A8: Factor Liner Small2 | B8: ASL3 | C8: F10 | D8: 1 | E8: Factor Liner Small2 | F8: Factor Liner Small2 | H8: ASL3F10 | I8: ASL3F10 | J8: Factor Liner Small2 | L8: 10 | M8: 0p
A9: Factor Liner Large2 | B9: ASL3 | C9: F11 | D9: 1 | E9: Factor Liner Large2 | F9: Factor Liner Large2 | H9: ASL3F11 | I9: ASL3F11 | J9: Factor Liner Large2 | L9: 11 | M9: 0p
A10: Factor Liner Medium2 | B10: ASL3 | C10: F12 | D10: 1 | E10: Factor Liner Medium2 | F10: Factor Liner Medium2 | H10: ASL3F12 | I10: ASL3F12 | J10: Factor Liner Medium2 | L10: 12 | M10: 0p
A11: 304_1p | B11: ASL3 | C11: F55 | D11: 1 | E11: CON-00-137745-2 | F11: 565064 - Lachs in Senf-Dill-Sauce | H11: ASL3F55 | I11: ASL3F551p | J11: 565064 - Lachs in Senf-Dill-Sauce | L11: 55 | M11: 1p
A12: 318_1p | B12: ASL3 | C12: F56 | D12: 1 | E12: CON-00-136696-3 | F12: 565095 - Schweinefilet in würziger Ancho-Chili-Sauce | H12: ASL3F56 | I12: ASL3F561p | J12: 565095 - Schweinefilet in würziger Ancho-Chili-Sauce | L12: 56 | M12: 1p
A13: 317_1p | B13: ASL3 | C13: F59 | D13: 1 | E13: CON-00-155185-3 | F13: 565252 - Rinderragù mit sonnengetrockneten Tomaten und Pasta | H13: ASL3F59 | I13: ASL3F591p | J13: 565252 - Rinderragù mit sonnengetrockneten Tomaten und Pasta | L13: 59 | M13: 1p
A14: 315_1p | B14: ASL3 | C14: F62 | D14: 1 | E14: CON-00-136694-3 | F14: 565091 - Scharfes Rinderhack mit Jalapeños | H14: ASL3F62 | I14: ASL3F621p | J14: 565091 - Scharfes Rinderhack mit Jalapeños | L14: 62 | M14: 1p
... A53: Ice12 | B53: ASL3 | C53: F144 | D53: 2 | E53: IcePack | F53: IcePack1 | H53: ASL3F144 | I53: ASL3F144 | J53: IcePack1 | L53: 144 | M53: 0p

Sheet II

Sheet Rack labels | HF
A1: Set the rack numbers in column A The ASLs are pulled from the control sheet via a formula
A2: Week Number (pulled from the contol sheet) | B2: =RIGHT('Control Panel'!D4,2) -> 19 | D2: {=IFERROR(INDEX(SORT(UNIQUE(RackfileUPLOAD!$B$2:$B277)),1),"")} -> ASL3 | E2: {=IFERROR(INDEX(SORT(UNIQUE(RackfileUPLOAD!$B$2:$B277)),1),"")} -> ASL3 | F2: {=IFERROR(INDEX(SORT(UNIQUE(RackfileUPLOAD!$B$2:$B277)),1),"")} -> ASL3 | G2: {=IFERROR(INDEX(SORT(UNIQUE(RackfileUPLOAD!$B$2:$B277)),1),"")} -> ASL3 | I2: {=IFERROR(INDEX(SORT(UNIQUE(RackfileUPLOAD!$B$2:$B277)),1),"")} -> ASL3 | J2: {=IFERROR(INDEX(SORT(UNIQUE(RackfileUPLOAD!$B$2:$B277)),1),"")} -> ASL3 | K2: {=IFERROR(INDEX(SORT(UNIQUE(RackfileUPLOAD!$B$2:$B277)),1),"")} -> ASL3 | L2: {=IFERROR(INDEX(SORT(UNIQUE(RackfileUPLOAD!$B$2:$B277)),1),"")} -> ASL3 | O2: {=IFERROR(INDEX(SORT(UNIQUE(RackfileUPLOAD!$B$2:$B277)),2),"")} | P2: {=IFERROR(INDEX(SORT(UNIQUE(RackfileUPLOAD!$B$2:$B277)),2),"")} | Q2: {=IFERROR(INDEX(SORT(UNIQUE(RackfileUPLOAD!$B$2:$B277)),2),"")} | R2: {=IFERROR(INDEX(SORT(UNIQUE(RackfileUPLOAD!$B$2:$B277)),2),"")} | T2: {=IFERROR(INDEX(SORT(UNIQUE(RackfileUPLOAD!$B$2:$B277)),2),"")} | U2: {=IFERROR(INDEX(SORT(UNIQUE(RackfileUPLOAD!$B$2:$B277)),2),"")} | V2: {=IFERROR(INDEX(SORT(UNIQUE(RackfileUPLOAD!$B$2:$B277)),2),"")} | W2: {=IFERROR(INDEX(SORT(UNIQUE(RackfileUPLOAD!$B$2:$B277)),2),"")} | Z2: {=IFERROR(INDEX(SORT(UNIQUE(RackfileUPLOAD!$B$2:$B277)),3),"")} | AA2: {=IFERROR(INDEX(SORT(UNIQUE(RackfileUPLOAD!$B$2:$B277)),3),"")} | AB2: {=IFERROR(INDEX(SORT(UNIQUE(RackfileUPLOAD!$B$2:$B277)),3),"")} | AC2: {=IFERROR(INDEX(SORT(UNIQUE(RackfileUPLOAD!$B$2:$B277)),3),"")} | AE2: {=IFERROR(INDEX(SORT(UNIQUE(RackfileUPLOAD!$B$2:$B277)),3),"")} | AF2: {=IFERROR(INDEX(SORT(UNIQUE(RackfileUPLOAD!$B$2:$B277)),3),"")} | AG2: {=IFERROR(INDEX(SORT(UNIQUE(RackfileUPLOAD!$B$2:$B277)),3),"")} | AH2: {=IFERROR(INDEX(SORT(UNIQUE(RackfileUPLOAD!$B$2:$B277)),3),"")} | AK2: {=IFERROR(INDEX(SORT(UNIQUE(RackfileUPLOAD!$B$2:$B277)),4),"")} | AL2: {=IFERROR(INDEX(SORT(UNIQUE(RackfileUPLOAD!$B$2:$B277)),4),"")} | AM2: {=IFERROR(INDEX(SORT(UNIQUE(RackfileUPLOAD!$B$2:$B277)),4),"")} | AN2: {=IFERROR(INDEX(SORT(UNIQUE(RackfileUPLOAD!$B$2:$B277)),4),"")} | AP2: {=IFERROR(INDEX(SORT(UNIQUE(RackfileUPLOAD!$B$2:$B277)),4),"")} | AQ2: {=IFERROR(INDEX(SORT(UNIQUE(RackfileUPLOAD!$B$2:$B277)),4),"")} | AR2: {=IFERROR(INDEX(SORT(UNIQUE(RackfileUPLOAD!$B$2:$B277)),4),"")} | AS2: {=IFERROR(INDEX(SORT(UNIQUE(RackfileUPLOAD!$B$2:$B277)),4),"")} | AV2: {=IFERROR(INDEX(SORT(UNIQUE(RackfileUPLOAD!$B$2:$B277)),5),"")} | AW2: {=IFERROR(INDEX(SORT(UNIQUE(RackfileUPLOAD!$B$2:$B277)),5),"")} | AX2: {=IFERROR(INDEX(SORT(UNIQUE(RackfileUPLOAD!$B$2:$B277)),5),"")} | AY2: {=IFERROR(INDEX(SORT(UNIQUE(RackfileUPLOAD!$B$2:$B277)),5),"")} | BA2: {=IFERROR(INDEX(SORT(UNIQUE(RackfileUPLOAD!$B$2:$B277)),5),"")} | BB2: {=IFERROR(INDEX(SORT(UNIQUE(RackfileUPLOAD!$B$2:$B277)),5),"")} | BC2: {=IFERROR(INDEX(SORT(UNIQUE(RackfileUPLOAD!$B$2:$B277)),5),"")} | BD2: {=IFERROR(INDEX(SORT(UNIQUE(RackfileUPLOAD!$B$2:$B277)),5),"")} | BG2: {=IFERROR(INDEX(SORT(UNIQUE(RackfileUPLOAD!$B$2:$B277)),6),"")} | BH2: {=IFERROR(INDEX(SORT(UNIQUE(RackfileUPLOAD!$B$2:$B277)),6),"")} | BI2: {=IFERROR(INDEX(SORT(UNIQUE(RackfileUPLOAD!$B$2:$B277)),6),"")} | BJ2: {=IFERROR(INDEX(SORT(UNIQUE(RackfileUPLOAD!$B$2:$B277)),6),"")} | BL2: {=IFERROR(INDEX(SORT(UNIQUE(RackfileUPLOAD!$B$2:$B277)),6),"")} | BM2: {=IFERROR(INDEX(SORT(UNIQUE(RackfileUPLOAD!$B$2:$B277)),6),"")} | BN2: {=IFERROR(INDEX(SORT(UNIQUE(RackfileUPLOAD!$B$2:$B277)),6),"")} | BO2: {=IFERROR(INDEX(SORT(UNIQUE(RackfileUPLOAD!$B$2:$B277)),6),"")}
A4: 13 | D4: =IF(D$2="",,D$2&"_KW "&$B$2&"_F"&$A4) -> ASL3_KW 19_F13 | E4: =IFNA(VLOOKUP(E$2&"F"&$A4,RackfileUPLOAD!$H:$K,3,FALSE),"") | I4: =IF(I$2="",,I$2&"_KW "&$B$2&"_F"&$A4+1) -> ASL3_KW 19_F14 | J4: =IFNA(VLOOKUP(J$2&"F"&$A4+1,RackfileUPLOAD!$H:$K,3,FALSE),"") | O4: =IF(O$2="",,O$2&"_KW "&$B$2&"_F"&$A4) | P4: =IFNA(VLOOKUP(P$2&"F"&$A4,RackfileUPLOAD!$H:$K,3,FALSE),"") | T4: =IF(T$2="",,T$2&"_KW "&$B$2&"_F"&$A4+1) | U4: =IFNA(VLOOKUP(U$2&"F"&$A4+1,RackfileUPLOAD!$H:$K,3,FALSE),"") | Z4: =IF(Z$2="",,Z$2&"_KW "&$B$2&"_F"&$A4) | AA4: =IFNA(VLOOKUP(AA$2&"F"&$A4,RackfileUPLOAD!$H:$K,3,FALSE),"") | AE4: =IF(AE$2="",,AE$2&"_KW "&$B$2&"_F"&$A4+1) | AF4: =IFNA(VLOOKUP(AF$2&"F"&$A4+1,RackfileUPLOAD!$H:$K,3,FALSE),"") | AK4: =IF(AK$2="",,AK$2&"_KW "&$B$2&"_F"&$A4) | AL4: =IFNA(VLOOKUP(AL$2&"F"&$A4,RackfileUPLOAD!$H:$K,3,FALSE),"") | AP4: =IF(AP$2="",,AP$2&"_KW "&$B$2&"_F"&$A4+1) | AQ4: =IFNA(VLOOKUP(AQ$2&"F"&$A4+1,RackfileUPLOAD!$H:$K,3,FALSE),"") | AV4: =IF(AV$2="",,AV$2&"_KW "&$B$2&"_F"&$A4) | AW4: =IFNA(VLOOKUP(AW$2&"F"&$A4,RackfileUPLOAD!$H:$K,3,FALSE),"") | BA4: =IF(BA$2="",,BA$2&"_KW "&$B$2&"_F"&$A4+1) | BB4: =IFNA(VLOOKUP(BB$2&"F"&$A4+1,RackfileUPLOAD!$H:$K,3,FALSE),"") | BG4: =IF(BG$2="",,BG$2&"_KW "&$B$2&"_F"&$A4) | BH4: =IFNA(VLOOKUP(BH$2&"F"&$A4,RackfileUPLOAD!$H:$K,3,FALSE),"") | BL4: =IF(BL$2="",,BL$2&"_KW "&$B$2&"_F"&$A4+1) | BM4: =IFNA(VLOOKUP(BM$2&"F"&$A4+1,RackfileUPLOAD!$H:$K,3,FALSE),"")
E5: =IF(E4="","","2p") | F5: =IF(E4="","","3p") | G5: =IF(E4="","","4p") | J5: =IF(J4="","","2p") | K5: =IF(J4="","","3p") | L5: =IF(J4="","","4p") | P5: =IF(P4="","","2p") | Q5: =IF(P4="","","3p") | R5: =IF(P4="","","4p") | U5: =IF(U4="","","2p") | V5: =IF(U4="","","3p") | W5: =IF(U4="","","4p") | AA5: =IF(AA4="","","2p") | AB5: =IF(AA4="","","3p") | AC5: =IF(AA4="","","4p") | AF5: =IF(AF4="","","2p") | AG5: =IF(AF4="","","3p") | AH5: =IF(AF4="","","4p") | AL5: =IF(AL4="","","2p") | AM5: =IF(AL4="","","3p") | AN5: =IF(AL4="","","4p") | AQ5: =IF(AQ4="","","2p") | AR5: =IF(AQ4="","","3p") | AS5: =IF(AQ4="","","4p") | AW5: =IF(AW4="","","2p") | AX5: =IF(AW4="","","3p") | AY5: =IF(AW4="","","4p") | BB5: =IF(BB4="","","2p") | BC5: =IF(BB4="","","3p") | BD5: =IF(BB4="","","4p") | BH5: =IF(BH4="","","2p") | BI5: =IF(BH4="","","3p") | BJ5: =IF(BH4="","","4p") | BM5: =IF(BM4="","","2p") | BN5: =IF(BM4="","","3p") | BO5: =IF(BM4="","","4p")
E6: =IF(E4="IcePack","",IFNA(VLOOKUP(E$2&"F"&$A4&E5,RackfileUPLOAD!$I:$K,3,FALSE),IFNA(VLOOKUP(E$2&"F"&$A4,RackfileUPLOAD!$I:$K,3,FALSE),""))) | F6: =IF(E4="IcePack","",IFNA(VLOOKUP(E$2&"F"&$A4&F5,RackfileUPLOAD!$I:$K,3,FALSE),IFNA(VLOOKUP(E$2&"F"&$A4,RackfileUPLOAD!$I:$K,3,FALSE),""))) | G6: =IF(E4="IcePack","",IFNA(VLOOKUP(E$2&"F"&$A4&G5,RackfileUPLOAD!$I:$K,3,FALSE),IFNA(VLOOKUP(E$2&"F"&$A4,RackfileUPLOAD!$I:$K,3,FALSE),""))) | J6: =IF(J4="IcePack","",IFNA(VLOOKUP(J$2&"F"&$A4+1&J5,RackfileUPLOAD!$I:$K,3,FALSE),IFNA(VLOOKUP(J$2&"F"&$A4+1,RackfileUPLOAD!$I:$K,3,FALSE),""))) | K6: =IF(J4="IcePack","",IFNA(VLOOKUP(J$2&"F"&$A4+1&K5,RackfileUPLOAD!$I:$K,3,FALSE),IFNA(VLOOKUP(J$2&"F"&$A4+1,RackfileUPLOAD!$I:$K,3,FALSE),""))) | L6: =IF(J4="IcePack","",IFNA(VLOOKUP(J$2&"F"&$A4+1&L5,RackfileUPLOAD!$I:$K,3,FALSE),IFNA(VLOOKUP(J$2&"F"&$A4+1,RackfileUPLOAD!$I:$K,3,FALSE),""))) | P6: =IF(P4="IcePack","",IFNA(VLOOKUP(P$2&"F"&$A4&P5,RackfileUPLOAD!$I:$K,3,FALSE),IFNA(VLOOKUP(P$2&"F"&$A4,RackfileUPLOAD!$I:$K,3,FALSE),""))) | Q6: =IF(P4="IcePack","",IFNA(VLOOKUP(P$2&"F"&$A4&Q5,RackfileUPLOAD!$I:$K,3,FALSE),IFNA(VLOOKUP(P$2&"F"&$A4,RackfileUPLOAD!$I:$K,3,FALSE),""))) | R6: =IF(P4="IcePack","",IFNA(VLOOKUP(P$2&"F"&$A4&R5,RackfileUPLOAD!$I:$K,3,FALSE),IFNA(VLOOKUP(P$2&"F"&$A4,RackfileUPLOAD!$I:$K,3,FALSE),""))) | U6: =IF(U4="IcePack","",IFNA(VLOOKUP(U$2&"F"&$A4+1&U5,RackfileUPLOAD!$I:$K,3,FALSE),IFNA(VLOOKUP(U$2&"F"&$A4+1,RackfileUPLOAD!$I:$K,3,FALSE),""))) | V6: =IF(U4="IcePack","",IFNA(VLOOKUP(U$2&"F"&$A4+1&V5,RackfileUPLOAD!$I:$K,3,FALSE),IFNA(VLOOKUP(U$2&"F"&$A4+1,RackfileUPLOAD!$I:$K,3,FALSE),""))) | W6: =IF(U4="IcePack","",IFNA(VLOOKUP(U$2&"F"&$A4+1&W5,RackfileUPLOAD!$I:$K,3,FALSE),IFNA(VLOOKUP(U$2&"F"&$A4+1,RackfileUPLOAD!$I:$K,3,FALSE),""))) | AA6: =IF(AA4="IcePack","",IFNA(VLOOKUP(AA$2&"F"&$A4&AA5,RackfileUPLOAD!$I:$K,3,FALSE),IFNA(VLOOKUP(AA$2&"F"&$A4,RackfileUPLOAD!$I:$K,3,FALSE),""))) | AB6: =IF(AA4="IcePack","",IFNA(VLOOKUP(AA$2&"F"&$A4&AB5,RackfileUPLOAD!$I:$K,3,FALSE),IFNA(VLOOKUP(AA$2&"F"&$A4,RackfileUPLOAD!$I:$K,3,FALSE),""))) | AC6: =IF(AA4="IcePack","",IFNA(VLOOKUP(AA$2&"F"&$A4&AC5,RackfileUPLOAD!$I:$K,3,FALSE),IFNA(VLOOKUP(AA$2&"F"&$A4,RackfileUPLOAD!$I:$K,3,FALSE),""))) | AF6: =IF(AF4="IcePack","",IFNA(VLOOKUP(AF$2&"F"&$A4+1&AF5,RackfileUPLOAD!$I:$K,3,FALSE),IFNA(VLOOKUP(AF$2&"F"&$A4+1,RackfileUPLOAD!$I:$K,3,FALSE),""))) | AG6: =IF(AF4="IcePack","",IFNA(VLOOKUP(AF$2&"F"&$A4+1&AG5,RackfileUPLOAD!$I:$K,3,FALSE),IFNA(VLOOKUP(AF$2&"F"&$A4+1,RackfileUPLOAD!$I:$K,3,FALSE),""))) | AH6: =IF(AF4="IcePack","",IFNA(VLOOKUP(AF$2&"F"&$A4+1&AH5,RackfileUPLOAD!$I:$K,3,FALSE),IFNA(VLOOKUP(AF$2&"F"&$A4+1,RackfileUPLOAD!$I:$K,3,FALSE),""))) | AL6: =IF(AL4="IcePack","",IFNA(VLOOKUP(AL$2&"F"&$A4&AL5,RackfileUPLOAD!$I:$K,3,FALSE),IFNA(VLOOKUP(AL$2&"F"&$A4,RackfileUPLOAD!$I:$K,3,FALSE),""))) | AM6: =IF(AL4="IcePack","",IFNA(VLOOKUP(AL$2&"F"&$A4&AM5,RackfileUPLOAD!$I:$K,3,FALSE),IFNA(VLOOKUP(AL$2&"F"&$A4,RackfileUPLOAD!$I:$K,3,FALSE),""))) | AN6: =IF(AL4="IcePack","",IFNA(VLOOKUP(AL$2&"F"&$A4&AN5,RackfileUPLOAD!$I:$K,3,FALSE),IFNA(VLOOKUP(AL$2&"F"&$A4,RackfileUPLOAD!$I:$K,3,FALSE),""))) | AQ6: =IF(AQ4="IcePack","",IFNA(VLOOKUP(AQ$2&"F"&$A4+1&AQ5,RackfileUPLOAD!$I:$K,3,FALSE),IFNA(VLOOKUP(AQ$2&"F"&$A4+1,RackfileUPLOAD!$I:$K,3,FALSE),""))) | AR6: =IF(AQ4="IcePack","",IFNA(VLOOKUP(AQ$2&"F"&$A4+1&AR5,RackfileUPLOAD!$I:$K,3,FALSE),IFNA(VLOOKUP(AQ$2&"F"&$A4+1,RackfileUPLOAD!$I:$K,3,FALSE),""))) | AS6: =IF(AQ4="IcePack","",IFNA(VLOOKUP(AQ$2&"F"&$A4+1&AS5,RackfileUPLOAD!$I:$K,3,FALSE),IFNA(VLOOKUP(AQ$2&"F"&$A4+1,RackfileUPLOAD!$I:$K,3,FALSE),""))) | AW6: =IF(AW4="IcePack","",IFNA(VLOOKUP(AW$2&"F"&$A4&AW5,RackfileUPLOAD!$I:$K,3,FALSE),IFNA(VLOOKUP(AW$2&"F"&$A4,RackfileUPLOAD!$I:$K,3,FALSE),""))) | AX6: =IF(AW4="IcePack","",IFNA(VLOOKUP(AW$2&"F"&$A4&AX5,RackfileUPLOAD!$I:$K,3,FALSE),IFNA(VLOOKUP(AW$2&"F"&$A4,RackfileUPLOAD!$I:$K,3,FALSE),""))) | AY6: =IF(AW4="IcePack","",IFNA(VLOOKUP(AW$2&"F"&$A4&AY5,RackfileUPLOAD!$I:$K,3,FALSE),IFNA(VLOOKUP(AW$2&"F"&$A4,RackfileUPLOAD!$I:$K,3,FALSE),""))) | BB6: =IF(BB4="IcePack","",IFNA(VLOOKUP(BB$2&"F"&$A4+1&BB5,RackfileUPLOAD!$I:$K,3,FALSE),IFNA(VLOOKUP(BB$2&"F"&$A4+1,RackfileUPLOAD!$I:$K,3,FALSE),""))) | BC6: =IF(BB4="IcePack","",IFNA(VLOOKUP(BB$2&"F"&$A4+1&BC5,RackfileUPLOAD!$I:$K,3,FALSE),IFNA(VLOOKUP(BB$2&"F"&$A4+1,RackfileUPLOAD!$I:$K,3,FALSE),""))) | BD6: =IF(BB4="IcePack","",IFNA(VLOOKUP(BB$2&"F"&$A4+1&BD5,RackfileUPLOAD!$I:$K,3,FALSE),IFNA(VLOOKUP(BB$2&"F"&$A4+1,RackfileUPLOAD!$I:$K,3,FALSE),""))) | BH6: =IF(BH4="IcePack","",IFNA(VLOOKUP(BH$2&"F"&$A4&BH5,RackfileUPLOAD!$I:$K,3,FALSE),IFNA(VLOOKUP(BH$2&"F"&$A4,RackfileUPLOAD!$I:$K,3,FALSE),""))) | BI6: =IF(BH4="IcePack","",IFNA(VLOOKUP(BH$2&"F"&$A4&BI5,RackfileUPLOAD!$I:$K,3,FALSE),IFNA(VLOOKUP(BH$2&"F"&$A4,RackfileUPLOAD!$I:$K,3,FALSE),""))) | BJ6: =IF(BH4="IcePack","",IFNA(VLOOKUP(BH$2&"F"&$A4&BJ5,RackfileUPLOAD!$I:$K,3,FALSE),IFNA(VLOOKUP(BH$2&"F"&$A4,RackfileUPLOAD!$I:$K,3,FALSE),""))) | BM6: =IF(BM4="IcePack","",IFNA(VLOOKUP(BM$2&"F"&$A4+1&BM5,RackfileUPLOAD!$I:$K,3,FALSE),IFNA(VLOOKUP(BM$2&"F"&$A4+1,RackfileUPLOAD!$I:$K,3,FALSE),""))) | BN6: =IF(BM4="IcePack","",IFNA(VLOOKUP(BM$2&"F"&$A4+1&BN5,RackfileUPLOAD!$I:$K,3,FALSE),IFNA(VLOOKUP(BM$2&"F"&$A4+1,RackfileUPLOAD!$I:$K,3,FALSE),""))) | BO6: =IF(BM4="IcePack","",IFNA(VLOOKUP(BM$2&"F"&$A4+1&BO5,RackfileUPLOAD!$I:$K,3,FALSE),IFNA(VLOOKUP(BM$2&"F"&$A4+1,RackfileUPLOAD!$I:$K,3,FALSE),"")))
A8: =A4+2 -> 15 | D8: =IF(D$2="",,D$2&"_KW "&$B$2&"_F"&$A8) -> ASL3_KW 19_F15 | E8: =IFNA(VLOOKUP(E$2&"F"&$A8,RackfileUPLOAD!$H:$K,3,FALSE),"") | I8: =IF(I$2="",,I$2&"_KW "&$B$2&"_F"&$A8) -> ASL3_KW 19_F15 | J8: =IFNA(VLOOKUP(J$2&"F"&$A8+1,RackfileUPLOAD!$H:$K,3,FALSE),"") | O8: =IF(O$2="",,O$2&"_KW "&$B$2&"_F"&$A8) | P8: =IFNA(VLOOKUP(P$2&"F"&$A8,RackfileUPLOAD!$H:$K,3,FALSE),"") | T8: =IF(T$2="",,T$2&"_KW "&$B$2&"_F"&$A8) | U8: =IFNA(VLOOKUP(U$2&"F"&$A8+1,RackfileUPLOAD!$H:$K,3,FALSE),"") | Z8: =IF(Z$2="",,Z$2&"_KW "&$B$2&"_F"&$A8) | AA8: =IFNA(VLOOKUP(AA$2&"F"&$A8,RackfileUPLOAD!$H:$K,3,FALSE),"") | AE8: =IF(AE$2="",,AE$2&"_KW "&$B$2&"_F"&$A8) | AF8: =IFNA(VLOOKUP(AF$2&"F"&$A8+1,RackfileUPLOAD!$H:$K,3,FALSE),"") | AK8: =IF(AK$2="",,AK$2&"_KW "&$B$2&"_F"&$A8) | AL8: =IFNA(VLOOKUP(AL$2&"F"&$A8,RackfileUPLOAD!$H:$K,3,FALSE),"") | AP8: =IF(AP$2="",,AP$2&"_KW "&$B$2&"_F"&$A8) | AQ8: =IFNA(VLOOKUP(AQ$2&"F"&$A8+1,RackfileUPLOAD!$H:$K,3,FALSE),"") | AV8: =IF(AV$2="",,AV$2&"_KW "&$B$2&"_F"&$A8) | AW8: =IFNA(VLOOKUP(AW$2&"F"&$A8,RackfileUPLOAD!$H:$K,3,FALSE),"") | BA8: =IF(BA$2="",,BA$2&"_KW "&$B$2&"_F"&$A8) | BB8: =IFNA(VLOOKUP(BB$2&"F"&$A8+1,RackfileUPLOAD!$H:$K,3,FALSE),"") | BG8: =IF(BG$2="",,BG$2&"_KW "&$B$2&"_F"&$A8) | BH8: =IFNA(VLOOKUP(BH$2&"F"&$A8,RackfileUPLOAD!$H:$K,3,FALSE),"") | BL8: =IF(BL$2="",,BL$2&"_KW "&$B$2&"_F"&$A8) | BM8: =IFNA(VLOOKUP(BM$2&"F"&$A8+1,RackfileUPLOAD!$H:$K,3,FALSE),"")
E9: =IF(E8="","","2p") | F9: =IF(E8="","","3p") | G9: =IF(E8="","","4p") | J9: =IF(J8="","","2p") | K9: =IF(J8="","","3p") | L9: =IF(J8="","","4p") | P9: =IF(P8="","","2p") | Q9: =IF(P8="","","3p") | R9: =IF(P8="","","4p") | U9: =IF(U8="","","2p") | V9: =IF(U8="","","3p") | W9: =IF(U8="","","4p") | AA9: =IF(AA8="","","2p") | AB9: =IF(AA8="","","3p") | AC9: =IF(AA8="","","4p") | AF9: =IF(AF8="","","2p") | AG9: =IF(AF8="","","3p") | AH9: =IF(AF8="","","4p") | AL9: =IF(AL8="","","2p") | AM9: =IF(AL8="","","3p") | AN9: =IF(AL8="","","4p") | AQ9: =IF(AQ8="","","2p") | AR9: =IF(AQ8="","","3p") | AS9: =IF(AQ8="","","4p") | AW9: =IF(AW8="","","2p") | AX9: =IF(AW8="","","3p") | AY9: =IF(AW8="","","4p") | BB9: =IF(BB8="","","2p") | BC9: =IF(BB8="","","3p") | BD9: =IF(BB8="","","4p") | BH9: =IF(BH8="","","2p") | BI9: =IF(BH8="","","3p") | BJ9: =IF(BH8="","","4p") | BM9: =IF(BM8="","","2p") | BN9: =IF(BM8="","","3p") | BO9: =IF(BM8="","","4p")
E10: =IF(E8="IcePack","",IFNA(VLOOKUP(E$2&"F"&$A8&E9,RackfileUPLOAD!$I:$K,3,FALSE),IFNA(VLOOKUP(E$2&"F"&$A8,RackfileUPLOAD!$I:$K,3,FALSE),""))) | F10: =IF(E8="IcePack","",IFNA(VLOOKUP(E$2&"F"&$A8&F9,RackfileUPLOAD!$I:$K,3,FALSE),IFNA(VLOOKUP(E$2&"F"&$A8,RackfileUPLOAD!$I:$K,3,FALSE),""))) | G10: =IF(E8="IcePack","",IFNA(VLOOKUP(E$2&"F"&$A8&G9,RackfileUPLOAD!$I:$K,3,FALSE),IFNA(VLOOKUP(E$2&"F"&$A8,RackfileUPLOAD!$I:$K,3,FALSE),""))) | J10: =IF(J8="IcePack","",IFNA(VLOOKUP(J$2&"F"&$A8+1&J9,RackfileUPLOAD!$I:$K,3,FALSE),IFNA(VLOOKUP(J$2&"F"&$A8+1,RackfileUPLOAD!$I:$K,3,FALSE),""))) | K10: =IF(J8="IcePack","",IFNA(VLOOKUP(J$2&"F"&$A8+1&K9,RackfileUPLOAD!$I:$K,3,FALSE),IFNA(VLOOKUP(J$2&"F"&$A8+1,RackfileUPLOAD!$I:$K,3,FALSE),""))) | L10: =IF(J8="IcePack","",IFNA(VLOOKUP(J$2&"F"&$A8+1&L9,RackfileUPLOAD!$I:$K,3,FALSE),IFNA(VLOOKUP(J$2&"F"&$A8+1,RackfileUPLOAD!$I:$K,3,FALSE),""))) | P10: =IF(P8="IcePack","",IFNA(VLOOKUP(P$2&"F"&$A8&P9,RackfileUPLOAD!$I:$K,3,FALSE),IFNA(VLOOKUP(P$2&"F"&$A8,RackfileUPLOAD!$I:$K,3,FALSE),""))) | Q10: =IF(P8="IcePack","",IFNA(VLOOKUP(P$2&"F"&$A8&Q9,RackfileUPLOAD!$I:$K,3,FALSE),IFNA(VLOOKUP(P$2&"F"&$A8,RackfileUPLOAD!$I:$K,3,FALSE),""))) | R10: =IF(P8="IcePack","",IFNA(VLOOKUP(P$2&"F"&$A8&R9,RackfileUPLOAD!$I:$K,3,FALSE),IFNA(VLOOKUP(P$2&"F"&$A8,RackfileUPLOAD!$I:$K,3,FALSE),""))) | U10: =IF(U8="IcePack","",IFNA(VLOOKUP(U$2&"F"&$A8+1&U9,RackfileUPLOAD!$I:$K,3,FALSE),IFNA(VLOOKUP(U$2&"F"&$A8+1,RackfileUPLOAD!$I:$K,3,FALSE),""))) | V10: =IF(U8="IcePack","",IFNA(VLOOKUP(U$2&"F"&$A8+1&V9,RackfileUPLOAD!$I:$K,3,FALSE),IFNA(VLOOKUP(U$2&"F"&$A8+1,RackfileUPLOAD!$I:$K,3,FALSE),""))) | W10: =IF(U8="IcePack","",IFNA(VLOOKUP(U$2&"F"&$A8+1&W9,RackfileUPLOAD!$I:$K,3,FALSE),IFNA(VLOOKUP(U$2&"F"&$A8+1,RackfileUPLOAD!$I:$K,3,FALSE),""))) | AA10: =IF(AA8="IcePack","",IFNA(VLOOKUP(AA$2&"F"&$A8&AA9,RackfileUPLOAD!$I:$K,3,FALSE),IFNA(VLOOKUP(AA$2&"F"&$A8,RackfileUPLOAD!$I:$K,3,FALSE),""))) | AB10: =IF(AA8="IcePack","",IFNA(VLOOKUP(AA$2&"F"&$A8&AB9,RackfileUPLOAD!$I:$K,3,FALSE),IFNA(VLOOKUP(AA$2&"F"&$A8,RackfileUPLOAD!$I:$K,3,FALSE),""))) | AC10: =IF(AA8="IcePack","",IFNA(VLOOKUP(AA$2&"F"&$A8&AC9,RackfileUPLOAD!$I:$K,3,FALSE),IFNA(VLOOKUP(AA$2&"F"&$A8,RackfileUPLOAD!$I:$K,3,FALSE),""))) | AF10: =IF(AF8="IcePack","",IFNA(VLOOKUP(AF$2&"F"&$A8+1&AF9,RackfileUPLOAD!$I:$K,3,FALSE),IFNA(VLOOKUP(AF$2&"F"&$A8+1,RackfileUPLOAD!$I:$K,3,FALSE),""))) | AG10: =IF(AF8="IcePack","",IFNA(VLOOKUP(AF$2&"F"&$A8+1&AG9,RackfileUPLOAD!$I:$K,3,FALSE),IFNA(VLOOKUP(AF$2&"F"&$A8+1,RackfileUPLOAD!$I:$K,3,FALSE),""))) | AH10: =IF(AF8="IcePack","",IFNA(VLOOKUP(AF$2&"F"&$A8+1&AH9,RackfileUPLOAD!$I:$K,3,FALSE),IFNA(VLOOKUP(AF$2&"F"&$A8+1,RackfileUPLOAD!$I:$K,3,FALSE),""))) | AL10: =IF(AL8="IcePack","",IFNA(VLOOKUP(AL$2&"F"&$A8&AL9,RackfileUPLOAD!$I:$K,3,FALSE),IFNA(VLOOKUP(AL$2&"F"&$A8,RackfileUPLOAD!$I:$K,3,FALSE),""))) | AM10: =IF(AL8="IcePack","",IFNA(VLOOKUP(AL$2&"F"&$A8&AM9,RackfileUPLOAD!$I:$K,3,FALSE),IFNA(VLOOKUP(AL$2&"F"&$A8,RackfileUPLOAD!$I:$K,3,FALSE),""))) | AN10: =IF(AL8="IcePack","",IFNA(VLOOKUP(AL$2&"F"&$A8&AN9,RackfileUPLOAD!$I:$K,3,FALSE),IFNA(VLOOKUP(AL$2&"F"&$A8,RackfileUPLOAD!$I:$K,3,FALSE),""))) | AQ10: =IF(AQ8="IcePack","",IFNA(VLOOKUP(AQ$2&"F"&$A8+1&AQ9,RackfileUPLOAD!$I:$K,3,FALSE),IFNA(VLOOKUP(AQ$2&"F"&$A8+1,RackfileUPLOAD!$I:$K,3,FALSE),""))) | AR10: =IF(AQ8="IcePack","",IFNA(VLOOKUP(AQ$2&"F"&$A8+1&AR9,RackfileUPLOAD!$I:$K,3,FALSE),IFNA(VLOOKUP(AQ$2&"F"&$A8+1,RackfileUPLOAD!$I:$K,3,FALSE),""))) | AS10: =IF(AQ8="IcePack","",IFNA(VLOOKUP(AQ$2&"F"&$A8+1&AS9,RackfileUPLOAD!$I:$K,3,FALSE),IFNA(VLOOKUP(AQ$2&"F"&$A8+1,RackfileUPLOAD!$I:$K,3,FALSE),""))) | AW10: =IF(AW8="IcePack","",IFNA(VLOOKUP(AW$2&"F"&$A8&AW9,RackfileUPLOAD!$I:$K,3,FALSE),IFNA(VLOOKUP(AW$2&"F"&$A8,RackfileUPLOAD!$I:$K,3,FALSE),""))) | AX10: =IF(AW8="IcePack","",IFNA(VLOOKUP(AW$2&"F"&$A8&AX9,RackfileUPLOAD!$I:$K,3,FALSE),IFNA(VLOOKUP(AW$2&"F"&$A8,RackfileUPLOAD!$I:$K,3,FALSE),""))) | AY10: =IF(AW8="IcePack","",IFNA(VLOOKUP(AW$2&"F"&$A8&AY9,RackfileUPLOAD!$I:$K,3,FALSE),IFNA(VLOOKUP(AW$2&"F"&$A8,RackfileUPLOAD!$I:$K,3,FALSE),""))) | BB10: =IF(BB8="IcePack","",IFNA(VLOOKUP(BB$2&"F"&$A8+1&BB9,RackfileUPLOAD!$I:$K,3,FALSE),IFNA(VLOOKUP(BB$2&"F"&$A8+1,RackfileUPLOAD!$I:$K,3,FALSE),""))) | BC10: =IF(BB8="IcePack","",IFNA(VLOOKUP(BB$2&"F"&$A8+1&BC9,RackfileUPLOAD!$I:$K,3,FALSE),IFNA(VLOOKUP(BB$2&"F"&$A8+1,RackfileUPLOAD!$I:$K,3,FALSE),""))) | BD10: =IF(BB8="IcePack","",IFNA(VLOOKUP(BB$2&"F"&$A8+1&BD9,RackfileUPLOAD!$I:$K,3,FALSE),IFNA(VLOOKUP(BB$2&"F"&$A8+1,RackfileUPLOAD!$I:$K,3,FALSE),""))) | BH10: =IF(BH8="IcePack","",IFNA(VLOOKUP(BH$2&"F"&$A8&BH9,RackfileUPLOAD!$I:$K,3,FALSE),IFNA(VLOOKUP(BH$2&"F"&$A8,RackfileUPLOAD!$I:$K,3,FALSE),""))) | BI10: =IF(BH8="IcePack","",IFNA(VLOOKUP(BH$2&"F"&$A8&BI9,RackfileUPLOAD!$I:$K,3,FALSE),IFNA(VLOOKUP(BH$2&"F"&$A8,RackfileUPLOAD!$I:$K,3,FALSE),""))) | BJ10: =IF(BH8="IcePack","",IFNA(VLOOKUP(BH$2&"F"&$A8&BJ9,RackfileUPLOAD!$I:$K,3,FALSE),IFNA(VLOOKUP(BH$2&"F"&$A8,RackfileUPLOAD!$I:$K,3,FALSE),""))) | BM10: =IF(BM8="IcePack","",IFNA(VLOOKUP(BM$2&"F"&$A8+1&BM9,RackfileUPLOAD!$I:$K,3,FALSE),IFNA(VLOOKUP(BM$2&"F"&$A8+1,RackfileUPLOAD!$I:$K,3,FALSE),""))) | BN10: =IF(BM8="IcePack","",IFNA(VLOOKUP(BM$2&"F"&$A8+1&BN9,RackfileUPLOAD!$I:$K,3,FALSE),IFNA(VLOOKUP(BM$2&"F"&$A8+1,RackfileUPLOAD!$I:$K,3,FALSE),""))) | BO10: =IF(BM8="IcePack","",IFNA(VLOOKUP(BM$2&"F"&$A8+1&BO9,RackfileUPLOAD!$I:$K,3,FALSE),IFNA(VLOOKUP(BM$2&"F"&$A8+1,RackfileUPLOAD!$I:$K,3,FALSE),"")))
A12: =A8+2 -> 17 | D12: =IF(D$2="",,D$2&"_KW "&$B$2&"_F"&$A12) -> ASL3_KW 19_F17 | E12: =IFNA(VLOOKUP(E$2&"F"&$A12,RackfileUPLOAD!$H:$K,3,FALSE),"") | I12: =IF(I$2="",,I$2&"_KW "&$B$2&"_F"&$A12) -> ASL3_KW 19_F17 | J12: =IFNA(VLOOKUP(J$2&"F"&$A12+1,RackfileUPLOAD!$H:$K,3,FALSE),"") | O12: =IF(O$2="",,O$2&"_KW "&$B$2&"_F"&$A12) | P12: =IFNA(VLOOKUP(P$2&"F"&$A12,RackfileUPLOAD!$H:$K,3,FALSE),"") | T12: =IF(T$2="",,T$2&"_KW "&$B$2&"_F"&$A12) | U12: =IFNA(VLOOKUP(U$2&"F"&$A12+1,RackfileUPLOAD!$H:$K,3,FALSE),"") | Z12: =IF(Z$2="",,Z$2&"_KW "&$B$2&"_F"&$A12) | AA12: =IFNA(VLOOKUP(AA$2&"F"&$A12,RackfileUPLOAD!$H:$K,3,FALSE),"") | AE12: =IF(AE$2="",,AE$2&"_KW "&$B$2&"_F"&$A12) | AF12: =IFNA(VLOOKUP(AF$2&"F"&$A12+1,RackfileUPLOAD!$H:$K,3,FALSE),"") | AK12: =IF(AK$2="",,AK$2&"_KW "&$B$2&"_F"&$A12) | AL12: =IFNA(VLOOKUP(AL$2&"F"&$A12,RackfileUPLOAD!$H:$K,3,FALSE),"") | AP12: =IF(AP$2="",,AP$2&"_KW "&$B$2&"_F"&$A12) | AQ12: =IFNA(VLOOKUP(AQ$2&"F"&$A12+1,RackfileUPLOAD!$H:$K,3,FALSE),"") | AV12: =IF(AV$2="",,AV$2&"_KW "&$B$2&"_F"&$A12) | AW12: =IFNA(VLOOKUP(AW$2&"F"&$A12,RackfileUPLOAD!$H:$K,3,FALSE),"") | BA12: =IF(BA$2="",,BA$2&"_KW "&$B$2&"_F"&$A12) | BB12: =IFNA(VLOOKUP(BB$2&"F"&$A12+1,RackfileUPLOAD!$H:$K,3,FALSE),"") | BG12: =IF(BG$2="",,BG$2&"_KW "&$B$2&"_F"&$A12) | BH12: =IFNA(VLOOKUP(BH$2&"F"&$A12,RackfileUPLOAD!$H:$K,3,FALSE),"") | BL12: =IF(BL$2="",,BL$2&"_KW "&$B$2&"_F"&$A12) | BM12: =IFNA(VLOOKUP(BM$2&"F"&$A12+1,RackfileUPLOAD!$H:$K,3,FALSE),"")
E13: =IF(E12="","","2p") | F13: =IF(E12="","","3p") | G13: =IF(E12="","","4p") | J13: =IF(J12="","","2p") | K13: =IF(J12="","","3p") | L13: =IF(J12="","","4p") | P13: =IF(P12="","","2p") | Q13: =IF(P12="","","3p") | R13: =IF(P12="","","4p") | U13: =IF(U12="","","2p") | V13: =IF(U12="","","3p") | W13: =IF(U12="","","4p") | AA13: =IF(AA12="","","2p") | AB13: =IF(AA12="","","3p") | AC13: =IF(AA12="","","4p") | AF13: =IF(AF12="","","2p") | AG13: =IF(AF12="","","3p") | AH13: =IF(AF12="","","4p") | AL13: =IF(AL12="","","2p") | AM13: =IF(AL12="","","3p") | AN13: =IF(AL12="","","4p") | AQ13: =IF(AQ12="","","2p") | AR13: =IF(AQ12="","","3p") | AS13: =IF(AQ12="","","4p") | AW13: =IF(AW12="","","2p") | AX13: =IF(AW12="","","3p") | AY13: =IF(AW12="","","4p") | BB13: =IF(BB12="","","2p") | BC13: =IF(BB12="","","3p") | BD13: =IF(BB12="","","4p") | BH13: =IF(BH12="","","2p") | BI13: =IF(BH12="","","3p") | BJ13: =IF(BH12="","","4p") | BM13: =IF(BM12="","","2p") | BN13: =IF(BM12="","","3p") | BO13: =IF(BM12="","","4p")
E14: =IF(E12="IcePack","",IFNA(VLOOKUP(E$2&"F"&$A12&E13,RackfileUPLOAD!$I:$K,3,FALSE),IFNA(VLOOKUP(E$2&"F"&$A12,RackfileUPLOAD!$I:$K,3,FALSE),""))) | F14: =IF(E12="IcePack","",IFNA(VLOOKUP(E$2&"F"&$A12&F13,RackfileUPLOAD!$I:$K,3,FALSE),IFNA(VLOOKUP(E$2&"F"&$A12,RackfileUPLOAD!$I:$K,3,FALSE),""))) | G14: =IF(E12="IcePack","",IFNA(VLOOKUP(E$2&"F"&$A12&G13,RackfileUPLOAD!$I:$K,3,FALSE),IFNA(VLOOKUP(E$2&"F"&$A12,RackfileUPLOAD!$I:$K,3,FALSE),""))) | J14: =IF(J12="IcePack","",IFNA(VLOOKUP(J$2&"F"&$A12+1&J13,RackfileUPLOAD!$I:$K,3,FALSE),IFNA(VLOOKUP(J$2&"F"&$A12+1,RackfileUPLOAD!$I:$K,3,FALSE),""))) | K14: =IF(J12="IcePack","",IFNA(VLOOKUP(J$2&"F"&$A12+1&K13,RackfileUPLOAD!$I:$K,3,FALSE),IFNA(VLOOKUP(J$2&"F"&$A12+1,RackfileUPLOAD!$I:$K,3,FALSE),""))) | L14: =IF(J12="IcePack","",IFNA(VLOOKUP(J$2&"F"&$A12+1&L13,RackfileUPLOAD!$I:$K,3,FALSE),IFNA(VLOOKUP(J$2&"F"&$A12+1,RackfileUPLOAD!$I:$K,3,FALSE),""))) | P14: =IF(P12="IcePack","",IFNA(VLOOKUP(P$2&"F"&$A12&P13,RackfileUPLOAD!$I:$K,3,FALSE),IFNA(VLOOKUP(P$2&"F"&$A12,RackfileUPLOAD!$I:$K,3,FALSE),""))) | Q14: =IF(P12="IcePack","",IFNA(VLOOKUP(P$2&"F"&$A12&Q13,RackfileUPLOAD!$I:$K,3,FALSE),IFNA(VLOOKUP(P$2&"F"&$A12,RackfileUPLOAD!$I:$K,3,FALSE),""))) | R14: =IF(P12="IcePack","",IFNA(VLOOKUP(P$2&"F"&$A12&R13,RackfileUPLOAD!$I:$K,3,FALSE),IFNA(VLOOKUP(P$2&"F"&$A12,RackfileUPLOAD!$I:$K,3,FALSE),""))) | U14: =IF(U12="IcePack","",IFNA(VLOOKUP(U$2&"F"&$A12+1&U13,RackfileUPLOAD!$I:$K,3,FALSE),IFNA(VLOOKUP(U$2&"F"&$A12+1,RackfileUPLOAD!$I:$K,3,FALSE),""))) | V14: =IF(U12="IcePack","",IFNA(VLOOKUP(U$2&"F"&$A12+1&V13,RackfileUPLOAD!$I:$K,3,FALSE),IFNA(VLOOKUP(U$2&"F"&$A12+1,RackfileUPLOAD!$I:$K,3,FALSE),""))) | W14: =IF(U12="IcePack","",IFNA(VLOOKUP(U$2&"F"&$A12+1&W13,RackfileUPLOAD!$I:$K,3,FALSE),IFNA(VLOOKUP(U$2&"F"&$A12+1,RackfileUPLOAD!$I:$K,3,FALSE),""))) | AA14: =IF(AA12="IcePack","",IFNA(VLOOKUP(AA$2&"F"&$A12&AA13,RackfileUPLOAD!$I:$K,3,FALSE),IFNA(VLOOKUP(AA$2&"F"&$A12,RackfileUPLOAD!$I:$K,3,FALSE),""))) | AB14: =IF(AA12="IcePack","",IFNA(VLOOKUP(AA$2&"F"&$A12&AB13,RackfileUPLOAD!$I:$K,3,FALSE),IFNA(VLOOKUP(AA$2&"F"&$A12,RackfileUPLOAD!$I:$K,3,FALSE),""))) | AC14: =IF(AA12="IcePack","",IFNA(VLOOKUP(AA$2&"F"&$A12&AC13,RackfileUPLOAD!$I:$K,3,FALSE),IFNA(VLOOKUP(AA$2&"F"&$A12,RackfileUPLOAD!$I:$K,3,FALSE),""))) | AF14: =IF(AF12="IcePack","",IFNA(VLOOKUP(AF$2&"F"&$A12+1&AF13,RackfileUPLOAD!$I:$K,3,FALSE),IFNA(VLOOKUP(AF$2&"F"&$A12+1,RackfileUPLOAD!$I:$K,3,FALSE),""))) | AG14: =IF(AF12="IcePack","",IFNA(VLOOKUP(AF$2&"F"&$A12+1&AG13,RackfileUPLOAD!$I:$K,3,FALSE),IFNA(VLOOKUP(AF$2&"F"&$A12+1,RackfileUPLOAD!$I:$K,3,FALSE),""))) | AH14: =IF(AF12="IcePack","",IFNA(VLOOKUP(AF$2&"F"&$A12+1&AH13,RackfileUPLOAD!$I:$K,3,FALSE),IFNA(VLOOKUP(AF$2&"F"&$A12+1,RackfileUPLOAD!$I:$K,3,FALSE),""))) | AL14: =IF(AL12="IcePack","",IFNA(VLOOKUP(AL$2&"F"&$A12&AL13,RackfileUPLOAD!$I:$K,3,FALSE),IFNA(VLOOKUP(AL$2&"F"&$A12,RackfileUPLOAD!$I:$K,3,FALSE),""))) | AM14: =IF(AL12="IcePack","",IFNA(VLOOKUP(AL$2&"F"&$A12&AM13,RackfileUPLOAD!$I:$K,3,FALSE),IFNA(VLOOKUP(AL$2&"F"&$A12,RackfileUPLOAD!$I:$K,3,FALSE),""))) | AN14: =IF(AL12="IcePack","",IFNA(VLOOKUP(AL$2&"F"&$A12&AN13,RackfileUPLOAD!$I:$K,3,FALSE),IFNA(VLOOKUP(AL$2&"F"&$A12,RackfileUPLOAD!$I:$K,3,FALSE),""))) | AQ14: =IF(AQ12="IcePack","",IFNA(VLOOKUP(AQ$2&"F"&$A12+1&AQ13,RackfileUPLOAD!$I:$K,3,FALSE),IFNA(VLOOKUP(AQ$2&"F"&$A12+1,RackfileUPLOAD!$I:$K,3,FALSE),""))) | AR14: =IF(AQ12="IcePack","",IFNA(VLOOKUP(AQ$2&"F"&$A12+1&AR13,RackfileUPLOAD!$I:$K,3,FALSE),IFNA(VLOOKUP(AQ$2&"F"&$A12+1,RackfileUPLOAD!$I:$K,3,FALSE),""))) | AS14: =IF(AQ12="IcePack","",IFNA(VLOOKUP(AQ$2&"F"&$A12+1&AS13,RackfileUPLOAD!$I:$K,3,FALSE),IFNA(VLOOKUP(AQ$2&"F"&$A12+1,RackfileUPLOAD!$I:$K,3,FALSE),""))) | AW14: =IF(AW12="IcePack","",IFNA(VLOOKUP(AW$2&"F"&$A12&AW13,RackfileUPLOAD!$I:$K,3,FALSE),IFNA(VLOOKUP(AW$2&"F"&$A12,RackfileUPLOAD!$I:$K,3,FALSE),""))) | AX14: =IF(AW12="IcePack","",IFNA(VLOOKUP(AW$2&"F"&$A12&AX13,RackfileUPLOAD!$I:$K,3,FALSE),IFNA(VLOOKUP(AW$2&"F"&$A12,RackfileUPLOAD!$I:$K,3,FALSE),""))) | AY14: =IF(AW12="IcePack","",IFNA(VLOOKUP(AW$2&"F"&$A12&AY13,RackfileUPLOAD!$I:$K,3,FALSE),IFNA(VLOOKUP(AW$2&"F"&$A12,RackfileUPLOAD!$I:$K,3,FALSE),""))) | BB14: =IF(BB12="IcePack","",IFNA(VLOOKUP(BB$2&"F"&$A12+1&BB13,RackfileUPLOAD!$I:$K,3,FALSE),IFNA(VLOOKUP(BB$2&"F"&$A12+1,RackfileUPLOAD!$I:$K,3,FALSE),""))) | BC14: =IF(BB12="IcePack","",IFNA(VLOOKUP(BB$2&"F"&$A12+1&BC13,RackfileUPLOAD!$I:$K,3,FALSE),IFNA(VLOOKUP(BB$2&"F"&$A12+1,RackfileUPLOAD!$I:$K,3,FALSE),""))) | BD14: =IF(BB12="IcePack","",IFNA(VLOOKUP(BB$2&"F"&$A12+1&BD13,RackfileUPLOAD!$I:$K,3,FALSE),IFNA(VLOOKUP(BB$2&"F"&$A12+1,RackfileUPLOAD!$I:$K,3,FALSE),""))) | BH14: =IF(BH12="IcePack","",IFNA(VLOOKUP(BH$2&"F"&$A12&BH13,RackfileUPLOAD!$I:$K,3,FALSE),IFNA(VLOOKUP(BH$2&"F"&$A12,RackfileUPLOAD!$I:$K,3,FALSE),""))) | BI14: =IF(BH12="IcePack","",IFNA(VLOOKUP(BH$2&"F"&$A12&BI13,RackfileUPLOAD!$I:$K,3,FALSE),IFNA(VLOOKUP(BH$2&"F"&$A12,RackfileUPLOAD!$I:$K,3,FALSE),""))) | BJ14: =IF(BH12="IcePack","",IFNA(VLOOKUP(BH$2&"F"&$A12&BJ13,RackfileUPLOAD!$I:$K,3,FALSE),IFNA(VLOOKUP(BH$2&"F"&$A12,RackfileUPLOAD!$I:$K,3,FALSE),""))) | BM14: =IF(BM12="IcePack","",IFNA(VLOOKUP(BM$2&"F"&$A12+1&BM13,RackfileUPLOAD!$I:$K,3,FALSE),IFNA(VLOOKUP(BM$2&"F"&$A12+1,RackfileUPLOAD!$I:$K,3,FALSE),""))) | BN14: =IF(BM12="IcePack","",IFNA(VLOOKUP(BM$2&"F"&$A12+1&BN13,RackfileUPLOAD!$I:$K,3,FALSE),IFNA(VLOOKUP(BM$2&"F"&$A12+1,RackfileUPLOAD!$I:$K,3,FALSE),""))) | BO14: =IF(BM12="IcePack","",IFNA(VLOOKUP(BM$2&"F"&$A12+1&BO13,RackfileUPLOAD!$I:$K,3,FALSE),IFNA(VLOOKUP(BM$2&"F"&$A12+1,RackfileUPLOAD!$I:$K,3,FALSE),"")))
A16: =A12+2 -> 19 | D16: =IF(D$2="",,D$2&"_KW "&$B$2&"_F"&$A16) -> ASL3_KW 19_F19 | E16: =IFNA(VLOOKUP(E$2&"F"&$A16,RackfileUPLOAD!$H:$K,3,FALSE),"") | I16: =IF(I$2="",,I$2&"_KW "&$B$2&"_F"&$A16) -> ASL3_KW 19_F19 | J16: =IFNA(VLOOKUP(J$2&"F"&$A16+1,RackfileUPLOAD!$H:$K,3,FALSE),"") | O16: =IF(O$2="",,O$2&"_KW "&$B$2&"_F"&$A16) | P16: =IFNA(VLOOKUP(P$2&"F"&$A16,RackfileUPLOAD!$H:$K,3,FALSE),"") | T16: =IF(T$2="",,T$2&"_KW "&$B$2&"_F"&$A16) | U16: =IFNA(VLOOKUP(U$2&"F"&$A16+1,RackfileUPLOAD!$H:$K,3,FALSE),"") | Z16: =IF(Z$2="",,Z$2&"_KW "&$B$2&"_F"&$A16) | AA16: =IFNA(VLOOKUP(AA$2&"F"&$A16,RackfileUPLOAD!$H:$K,3,FALSE),"") | AE16: =IF(AE$2="",,AE$2&"_KW "&$B$2&"_F"&$A16) | AF16: =IFNA(VLOOKUP(AF$2&"F"&$A16+1,RackfileUPLOAD!$H:$K,3,FALSE),"") | AK16: =IF(AK$2="",,AK$2&"_KW "&$B$2&"_F"&$A16) | AL16: =IFNA(VLOOKUP(AL$2&"F"&$A16,RackfileUPLOAD!$H:$K,3,FALSE),"") | AP16: =IF(AP$2="",,AP$2&"_KW "&$B$2&"_F"&$A16) | AQ16: =IFNA(VLOOKUP(AQ$2&"F"&$A16+1,RackfileUPLOAD!$H:$K,3,FALSE),"") | AV16: =IF(AV$2="",,AV$2&"_KW "&$B$2&"_F"&$A16) | AW16: =IFNA(VLOOKUP(AW$2&"F"&$A16,RackfileUPLOAD!$H:$K,3,FALSE),"") | BA16: =IF(BA$2="",,BA$2&"_KW "&$B$2&"_F"&$A16) | BB16: =IFNA(VLOOKUP(BB$2&"F"&$A16+1,RackfileUPLOAD!$H:$K,3,FALSE),"") | BG16: =IF(BG$2="",,BG$2&"_KW "&$B$2&"_F"&$A16) | BH16: =IFNA(VLOOKUP(BH$2&"F"&$A16,RackfileUPLOAD!$H:$K,3,FALSE),"") | BL16: =IF(BL$2="",,BL$2&"_KW "&$B$2&"_F"&$A16) | BM16: =IFNA(VLOOKUP(BM$2&"F"&$A16+1,RackfileUPLOAD!$H:$K,3,FALSE),"")
