Workbook
Name master_job: #REF!
Name master_job_long: #REF!
Name job_inbox: #REF!
Name new_job_id_long: #REF!
Name new_job_id_staging: #REF!
Name new_job_separation: #REF!
Name new_job_staging: #REF!
Name new_job_id_separation: #REF!
Name new_job_status_staging: #REF!
Name new_job_status_separation: #REF!
Name new_job_status: CONTROL_CENTER!$F$8
Name new_job_long: #REF!
Name timezone_rack_planning: CONTROL_CENTER!$G$6
Name new_job_id: CONTROL_CENTER!$F$7
Name master_job_staging: #REF!
Name master_job_separation: #REF!
Name timestamp_rack_planning: CONTROL_CENTER!$F$6

Sheet Inputs
A1: =IFERROR(__xludf.DUMMYFUNCTION("IMPORTRANGE(""https://docs.google.com/spreadsheets/d/1YscgiuKYVI2pGcMJ3RcJwWGQEkG46RnVnji8q8a4AeE/edit?gid=1935731438#gid=1935731438"",""Produktionsvorbereitung_v2!A1:G100"")"),"#REF!") -> #REF!
M3: VolumeFile
M5: name | N5: demand_thursday | O5: demand_friday | P5: demand_saturday | Q5: demand_sunday | R5: demand_monday | S5: station_constraint | T5: level_constraint | U5: pickface_constraint | V5: separate_constraint
M6: IcePack1 | N6: =IFERROR( XLOOKUP(M6,J:J,L:L),"") -> 5138 | O6: 0 | P6: 0 | Q6: 0 | R6: 0 | U6: F29 | X6: RackFile_Combined | AG6: Grouping
J7: Converter TABLE | M7: IcePack2 | N7: =IFERROR( XLOOKUP(M7,J:J,L:L),"") -> 422 | O7: 0 | P7: 0 | Q7: 0 | R7: 0 | U7: F105 | AP7: Maitre Forecast
J8: =IF(B9="","",B9&" - "&D9) | K8: =IFERROR(C9,"") | L8: {=IFERROR(XLOOKUP(K8,C:C,G:G),"")} | M8: IcePack3 | N8: =IFERROR( XLOOKUP(M8,J:J,L:L),"") -> 5138 | O8: 0 | P8: 0 | Q8: 0 | R8: 0 | U8: F137 | X8: Recipe | Y8: Ingredient | Z8: SKU | AA8: Line | AB8: FlowRackPosition | AC8: Quantity | AD8: ScanRegEx | AE8: StorageConditions | AG8: recipe_slot | AH8: ingredient_sku | AI8: ingredient_name | AJ8: final_key | AK8: picks_2p | AL8: picks_3p | AM8: picks_4p | AP8: name | AQ8: demand_thursday | AR8: demand_friday | AS8: demand_saturday | AT8: demand_sunday | AU8: demand_monday | AV8: station_constraint | AW8: level_constraint | AX8: pickface_constraint | AY8: separate_constraint
J9: =IF(B10="","",B10&" - "&D10) | K9: =IFERROR(C10,"") | L9: 2314 | M9: =IFERROR(J9,"") | N9: =IFERROR( XLOOKUP(M9,J:J,L:L),"") | O9: =IF($N9="","","0") | P9: =IF($N9="","","0") | Q9: =IF($N9="","","0") | R9: =IF($N9="","","0") | X9: =IF($J9="","", LEFT($J9,3)&"_1p") | Y9: =IFERROR(M9,"") | Z9: =XLOOKUP(Y9,J:J,K:K) | AA9: =IF(Z9="","","ASL1") | AC9: =IF(X9="","","1") | AE9: =IF(X9="","","Chilled") | AG9: =B10 | AH9: =IFERROR( XLOOKUP(AG9,B:B,C:C),"") | AI9: =IFERROR(XLOOKUP(AH9,K:K,J:J),"") | AJ9: =AI9 | AK9: =IF(AJ9="","","1") | AL9: =IF(AK9="","","0") | AM9: =IF(AL9="","","0") | AP9: W21 | AQ9: 301 | AR9: CON-00-138294-2 | AS9: Hähnchen mit Champignons und Reis | AT9: 2010
J10: =IF(B11="","",B11&" - "&D11) | K10: =IFERROR(C11,"") | L10: 1850 | M10: =IFERROR(J10,"") | N10: =IFERROR( XLOOKUP(M10,J:J,L:L),"") | O10: =IF($N10="","","0") | P10: =IF($N10="","","0") | Q10: =IF($N10="","","0") | R10: =IF($N10="","","0") | X10: =IF($J10="","", LEFT($J10,3)&"_1p") | Y10: =IFERROR(M10,"") | Z10: =XLOOKUP(Y10,J:J,K:K) | AA10: =IF(Z10="","","ASL1") | AC10: =IF(X10="","","1") | AE10: =IF(X10="","","Chilled") | AG10: =B11 | AH10: =IFERROR( XLOOKUP(AG10,B:B,C:C),"") | AI10: =IFERROR(XLOOKUP(AH10,K:K,J:J),"") | AJ10: =AI10 | AK10: =IF(AJ10="","","1") | AL10: =IF(AK10="","","0") | AM10: =IF(AL10="","","0") | AP10: W21 | AQ10: 302 | AR10: CON-00-136693-3 | AS10: Rindfleisch mit BBQ-Sauce | AT10: 1622
J11: =IF(B12="","",B12&" - "&D12) | K11: =IFERROR(C12,"") | L11: 2104 | M11: =IFERROR(J11,"") | N11: =IFERROR( XLOOKUP(M11,J:J,L:L),"") | O11: =IF($N11="","","0") | P11: =IF($N11="","","0") | Q11: =IF($N11="","","0") | R11: =IF($N11="","","0") | X11: =IF($J11="","", LEFT($J11,3)&"_1p") | Y11: =IFERROR(M11,"") | Z11: =XLOOKUP(Y11,J:J,K:K) | AA11: =IF(Z11="","","ASL1") | AC11: =IF(X11="","","1") | AE11: =IF(X11="","","Chilled") | AG11: =B12 | AH11: =IFERROR( XLOOKUP(AG11,B:B,C:C),"") | AI11: =IFERROR(XLOOKUP(AH11,K:K,J:J),"") | AJ11: =AI11 | AK11: =IF(AJ11="","","1") | AL11: =IF(AK11="","","0") | AM11: =IF(AL11="","","0") | AP11: W21 | AQ11: 303 | AR11: CON-00-137559-2 | AS11: Gochugaru-Hähnchen | AT11: 1990
J12: =IF(B13="","",B13&" - "&D13) | K12: =IFERROR(C13,"") | L12: 2313 | M12: =IFERROR(J12,"") | N12: =IFERROR( XLOOKUP(M12,J:J,L:L),"") | O12: =IF($N12="","","0") | P12: =IF($N12="","","0") | Q12: =IF($N12="","","0") | R12: =IF($N12="","","0") | X12: =IF($J12="","", LEFT($J12,3)&"_1p") | Y12: =IFERROR(M12,"") | Z12: =XLOOKUP(Y12,J:J,K:K) | AA12: =IF(Z12="","","ASL1") | AC12: =IF(X12="","","1") | AE12: =IF(X12="","","Chilled") | AG12: =B13 | AH12: =IFERROR( XLOOKUP(AG12,B:B,C:C),"") | AI12: =IFERROR(XLOOKUP(AH12,K:K,J:J),"") | AJ12: =AI12 | AK12: =IF(AJ12="","","1") | AL12: =IF(AK12="","","0") | AM12: =IF(AL12="","","0") | AP12: W21 | AQ12: 304 | AR12: CON-00-136648-3 | AS12: Pulled Chicken mit Cheddar und Speck | AT12: 2319
J13: =IF(B14="","",B14&" - "&D14) | K13: =IFERROR(C14,"") | L13: 1993 | M13: =IFERROR(J13,"") | N13: =IFERROR( XLOOKUP(M13,J:J,L:L),"") | O13: =IF($N13="","","0") | P13: =IF($N13="","","0") | Q13: =IF($N13="","","0") | R13: =IF($N13="","","0") | X13: =IF($J13="","", LEFT($J13,3)&"_1p") | Y13: =IFERROR(M13,"") | Z13: =XLOOKUP(Y13,J:J,K:K) | AA13: =IF(Z13="","","ASL1") | AC13: =IF(X13="","","1") | AE13: =IF(X13="","","Chilled") | AG13: =B14 | AH13: =IFERROR( XLOOKUP(AG13,B:B,C:C),"") | AI13: =IFERROR(XLOOKUP(AH13,K:K,J:J),"") | AJ13: =AI13 | AK13: =IF(AJ13="","","1") | AL13: =IF(AK13="","","0") | AM13: =IF(AL13="","","0") | AP13: W21 | AQ13: 305 | AR13: CON-00-136659-3 | AS13: Gegrilltes Hähnchenfilet mit Pesto | AT13: 1898
J14: =IF(B15="","",B15&" - "&D15) | K14: =IFERROR(C15,"") | L14: 1705 | M14: =IFERROR(J14,"") | N14: =IFERROR( XLOOKUP(M14,J:J,L:L),"") | O14: =IF($N14="","","0") | P14: =IF($N14="","","0") | Q14: =IF($N14="","","0") | R14: =IF($N14="","","0") | X14: =IF($J14="","", LEFT($J14,3)&"_1p") | Y14: =IFERROR(M14,"") | Z14: =XLOOKUP(Y14,J:J,K:K) | AA14: =IF(Z14="","","ASL1") | AC14: =IF(X14="","","1") | AE14: =IF(X14="","","Chilled") | AG14: =B15 | AH14: =IFERROR( XLOOKUP(AG14,B:B,C:C),"") | AI14: =IFERROR(XLOOKUP(AH14,K:K,J:J),"") | AJ14: =AI14 | AK14: =IF(AJ14="","","1") | AL14: =IF(AK14="","","0") | AM14: =IF(AL14="","","0") | AP14: W21 | AQ14: 306 | AR14: CON-00-136638-3 | AS14: Scharfes Hähnchen mit Jalapeño, Limette und Cheddar | AT14: 1492
J15: =IF(B16="","",B16&" - "&D16) | K15: =IFERROR(C16,"") | L15: 1062 | M15: =IFERROR(J15,"") | N15: =IFERROR( XLOOKUP(M15,J:J,L:L),"") | O15: =IF($N15="","","0") | P15: =IF($N15="","","0") | Q15: =IF($N15="","","0") | R15: =IF($N15="","","0") | X15: =IF($J15="","", LEFT($J15,3)&"_1p") | Y15: =IFERROR(M15,"") | Z15: =XLOOKUP(Y15,J:J,K:K) | AA15: =IF(Z15="","","ASL1") | AC15: =IF(X15="","","1") | AE15: =IF(X15="","","Chilled") | AG15: =B16 | AH15: =IFERROR( XLOOKUP(AG15,B:B,C:C),"") | AI15: =IFERROR(XLOOKUP(AH15,K:K,J:J),"") | AJ15: =AI15 | AK15: =IF(AJ15="","","1") | AL15: =IF(AK15="","","0") | AM15: =IF(AL15="","","0") | AP15: W21 | AQ15: 307 | AR15: CON-00-138996-2 | AS15: Cheddar Pulled Beef | AT15: 1307
J16: =IF(B17="","",B17&" - "&D17) | K16: =IFERROR(C17,"") | L16: 1356 | M16: =IFERROR(J16,"") | N16: =IFERROR( XLOOKUP(M16,J:J,L:L),"") | O16: =IF($N16="","","0") | P16: =IF($N16="","","0") | Q16: =IF($N16="","","0") | R16: =IF($N16="","","0") | X16: =IF($J16="","", LEFT($J16,3)&"_1p") | Y16: =IFERROR(M16,"") | Z16: =XLOOKUP(Y16,J:J,K:K) | AA16: =IF(Z16="","","ASL1") | AC16: =IF(X16="","","1") | AE16: =IF(X16="","","Chilled") | AG16: =B17 | AH16: =IFERROR( XLOOKUP(AG16,B:B,C:C),"") | AI16: =IFERROR(XLOOKUP(AH16,K:K,J:J),"") | AJ16: =AI16 | AK16: =IF(AJ16="","","1") | AL16: =IF(AK16="","","0") | AM16: =IF(AL16="","","0") | AP16: W21 | AQ16: 308 | AR16: CON-00-136617-3 | AS16: Lachs auf Blumenkohlreis in Käsecreme | AT16: 1722
J17: =IF(B18="","",B18&" - "&D18) | K17: =IFERROR(C18,"") | L17: 393 | M17: =IFERROR(J17,"") | N17: =IFERROR( XLOOKUP(M17,J:J,L:L),"") | O17: =IF($N17="","","0") | P17: =IF($N17="","","0") | Q17: =IF($N17="","","0") | R17: =IF($N17="","","0") | X17: =IF($J17="","", LEFT($J17,3)&"_1p") | Y17: =IFERROR(M17,"") | Z17: =XLOOKUP(Y17,J:J,K:K) | AA17: =IF(Z17="","","ASL1") | AC17: =IF(X17="","","1") | AE17: =IF(X17="","","Chilled") | AG17: =B18 | AH17: =IFERROR( XLOOKUP(AG17,B:B,C:C),"") | AI17: =IFERROR(XLOOKUP(AH17,K:K,J:J),"") | AJ17: =AI17 | AK17: =IF(AJ17="","","1") | AL17: =IF(AK17="","","0") | AM17: =IF(AL17="","","0") | AP17: W21 | AQ17: 309 | AR17: CON-00-136634-3 | AS17: Zucchini-Paprika-Ratatouille | AT17: 404
J18: =IF(B19="","",B19&" - "&D19) | K18: =IFERROR(C19,"") | L18: 529 | M18: =IFERROR(J18,"") | N18: =IFERROR( XLOOKUP(M18,J:J,L:L),"") | O18: =IF($N18="","","0") | P18: =IF($N18="","","0") | Q18: =IF($N18="","","0") | R18: =IF($N18="","","0") | X18: =IF($J18="","", LEFT($J18,3)&"_1p") | Y18: =IFERROR(M18,"") | Z18: =XLOOKUP(Y18,J:J,K:K) | AA18: =IF(Z18="","","ASL1") | AC18: =IF(X18="","","1") | AE18: =IF(X18="","","Chilled") | AG18: =B19 | AH18: =IFERROR( XLOOKUP(AG18,B:B,C:C),"") | AI18: =IFERROR(XLOOKUP(AH18,K:K,J:J),"") | AJ18: =AI18 | AK18: =IF(AJ18="","","1") | AL18: =IF(AK18="","","0") | AM18: =IF(AL18="","","0") | AP18: W21 | AQ18: 310 | AR18: CON-00-136647-3 | AS18: Quinoa-Süßkartoffel-Erdnuss-Bowl | AT18: 315
J19: =IF(B20="","",B20&" - "&D20) | K19: =IFERROR(C20,"") | L19: 434 | M19: =IFERROR(J19,"") | N19: =IFERROR( XLOOKUP(M19,J:J,L:L),"") | O19: =IF($N19="","","0") | P19: =IF($N19="","","0") | Q19: =IF($N19="","","0") | R19: =IF($N19="","","0") | X19: =IF($J19="","", LEFT($J19,3)&"_1p") | Y19: =IFERROR(M19,"") | Z19: =XLOOKUP(Y19,J:J,K:K) | AA19: =IF(Z19="","","ASL1") | AC19: =IF(X19="","","1") | AE19: =IF(X19="","","Chilled") | AG19: =B20 | AH19: =IFERROR( XLOOKUP(AG19,B:B,C:C),"") | AI19: =IFERROR(XLOOKUP(AH19,K:K,J:J),"") | AJ19: =AI19 | AK19: =IF(AJ19="","","1") | AL19: =IF(AK19="","","0") | AM19: =IF(AL19="","","0") | AP19: W21 | AQ19: 311 | AR19: CON-00-136664-3 | AS19: Schweinefilet in Sonnentomaten-Sauce | AT19: 516
J20: =IF(B21="","",B21&" - "&D21) | K20: =IFERROR(C21,"") | L20: 952 | M20: =IFERROR(J20,"") | N20: =IFERROR( XLOOKUP(M20,J:J,L:L),"") | O20: =IF($N20="","","0") | P20: =IF($N20="","","0") | Q20: =IF($N20="","","0") | R20: =IF($N20="","","0") | X20: =IF($J20="","", LEFT($J20,3)&"_1p") | Y20: =IFERROR(M20,"") | Z20: =XLOOKUP(Y20,J:J,K:K) | AA20: =IF(Z20="","","ASL1") | AC20: =IF(X20="","","1") | AE20: =IF(X20="","","Chilled") | AG20: =B21 | AH20: =IFERROR( XLOOKUP(AG20,B:B,C:C),"") | AI20: =IFERROR(XLOOKUP(AH20,K:K,J:J),"") | AJ20: =AI20 | AK20: =IF(AJ20="","","1") | AL20: =IF(AK20="","","0") | AM20: =IF(AL20="","","0") | AP20: W21 | AQ20: 312 | AR20: CON-00-137745-2 | AS20: Lachs in Senf-Dill-Sauce | AT20: 1094
... J25: =IF(B26="","",B26&" - "&D26) | K25: =IFERROR(C26,"") | L25: 473 | M25: =IFERROR(J25,"") | N25: =IFERROR( XLOOKUP(M25,J:J,L:L),"") | O25: =IF($N25="","","0") | P25: =IF($N25="","","0") | Q25: =IF($N25="","","0") | R25: =IF($N25="","","0") | X25: =IF($J25="","", LEFT($J25,3)&"_1p") | Y25: =IFERROR(M25,"") | Z25: =XLOOKUP(Y25,J:J,K:K) | AA25: =IF(Z25="","","ASL1") | AC25: =IF(X25="","","1") | AE25: =IF(X25="","","Chilled") | AG25: =B26 | AH25: =IFERROR( XLOOKUP(AG25,B:B,C:C),"") | AI25: =IFERROR(XLOOKUP(AH25,K:K,J:J),"") | AJ25: =AI25 | AK25: =IF(AJ25="","","1") | AL25: =IF(AK25="","","0") | AM25: =IF(AL25="","","0") | AP25: W21 | AQ25: 317 | AR25: CON-00-139494-2 | AS25: Schweinefilet mit Artischocken und Spinat | AT25: 393
J26: =IF(B27="","",B27&" - "&D27) | K26: =IFERROR(C27,"") | L26: 292 | M26: =IFERROR(J26,"") | N26: =IFERROR( XLOOKUP(M26,J:J,L:L),"") | O26: =IF($N26="","","0") | P26: =IF($N26="","","0") | Q26: =IF($N26="","","0") | R26: =IF($N26="","","0") | U26: F32 | X26: =IF($J26="","", LEFT($J26,3)&"_1p") | Y26: =IFERROR(M26,"") | Z26: =XLOOKUP(Y26,J:J,K:K) | AA26: =IF(Z26="","","ASL1") | AC26: =IF(X26="","","1") | AE26: =IF(X26="","","Chilled") | AG26: =B27 | AH26: =IFERROR( XLOOKUP(AG26,B:B,C:C),"") | AI26: =IFERROR(XLOOKUP(AH26,K:K,J:J),"") | AJ26: =AI26 | AK26: =IF(AJ26="","","1") | AL26: =IF(AK26="","","0") | AM26: =IF(AL26="","","0") | AP26: W21 | AQ26: 318 | AR26: CON-00-138006-2 | AS26: Schweinefilet in Lauchcreme | AT26: 394
J27: =IF(B28="","",B28&" - "&D28) | K27: =IFERROR(C28,"") | M27: =IFERROR(J27,"") | N27: =IFERROR( XLOOKUP(M27,J:J,L:L),"") | O27: =IF($N27="","","0") | P27: =IF($N27="","","0") | Q27: =IF($N27="","","0") | R27: =IF($N27="","","0") | X27: =IF($J27="","", LEFT($J27,3)&"_1p") | Y27: =IFERROR(M27,"") | Z27: =XLOOKUP(Y27,J:J,K:K) | AA27: =IF(Z27="","","ASL1") | AC27: =IF(X27="","","1") | AE27: =IF(X27="","","Chilled") | AG27: =B28 | AH27: =IFERROR( XLOOKUP(AG27,B:B,C:C),"") | AI27: =IFERROR(XLOOKUP(AH27,K:K,J:J),"") | AJ27: =AI27 | AK27: =IF(AJ27="","","1") | AL27: =IF(AK27="","","0") | AM27: =IF(AL27="","","0") | AP27: W21 | AQ27: 806 | AR27: PTN-00-136930-3 | AS27: Gegrilltes Hähnchen mit Knoblauch-Kräutern | AT27: 67
J28: =IF(B29="","",B29&" - "&D29) | K28: =IFERROR(C29,"") | L28: {=IFERROR(XLOOKUP(K28,C:C,G:G),"")} | M28: =IFERROR(J28,"") | N28: =IFERROR( XLOOKUP(M28,J:J,L:L),"") | O28: =IF($N28="","","0") | P28: =IF($N28="","","0") | Q28: =IF($N28="","","0") | R28: =IF($N28="","","0") | X28: =IF($J28="","", LEFT($J28,3)&"_1p") | Y28: =IFERROR(M28,"") | Z28: =XLOOKUP(Y28,J:J,K:K) | AA28: =IF(Z28="","","ASL1") | AC28: =IF(X28="","","1") | AE28: =IF(X28="","","Chilled") | AG28: =B29 | AH28: =IFERROR( XLOOKUP(AG28,B:B,C:C),"") | AI28: =IFERROR(XLOOKUP(AH28,K:K,J:J),"") | AJ28: =AI28 | AK28: =IF(AJ28="","","1") | AL28: =IF(AK28="","","0") | AM28: =IF(AL28="","","0")
J29: =IF(B30="","",B30&" - "&D30) | K29: =IFERROR(C30,"") | L29: 66 | M29: =IFERROR(J29,"") | N29: =IFERROR( XLOOKUP(M29,J:J,L:L),"") | O29: =IF($N29="","","0") | P29: =IF($N29="","","0") | Q29: =IF($N29="","","0") | R29: =IF($N29="","","0") | U29: F98 | X29: =IF($J29="","", LEFT($J29,3)&"_1p") | Y29: =IFERROR(M29,"") | Z29: =XLOOKUP(Y29,J:J,K:K) | AA29: =IF(Z29="","","ASL1") | AC29: =IF(X29="","","1") | AE29: =IF(X29="","","Chilled") | AG29: =B30 | AH29: =IFERROR( XLOOKUP(AG29,B:B,C:C),"") | AI29: =IFERROR(XLOOKUP(AH29,K:K,J:J),"") | AJ29: =AI29 | AK29: =IF(AJ29="","","1") | AL29: =IF(AK29="","","0") | AM29: =IF(AL29="","","0")
J30: =IF(B31="","",B31&" - "&D31) | K30: =IFERROR(C31,"") | L30: 120 | M30: =IFERROR(J30,"") | N30: =IFERROR( XLOOKUP(M30,J:J,L:L),"") | O30: =IF($N30="","","0") | P30: =IF($N30="","","0") | Q30: =IF($N30="","","0") | R30: =IF($N30="","","0") | U30: F108 | X30: =IF($J30="","", LEFT($J30,3)&"_1p") | Y30: =IFERROR(M30,"") | Z30: =XLOOKUP(Y30,J:J,K:K) | AA30: =IF(Z30="","","ASL1") | AC30: =IF(X30="","","1") | AE30: =IF(X30="","","Chilled") | AG30: =B31 | AH30: =IFERROR( XLOOKUP(AG30,B:B,C:C),"") | AI30: =IFERROR(XLOOKUP(AH30,K:K,J:J),"") | AJ30: =AI30 | AK30: =IF(AJ30="","","1") | AL30: =IF(AK30="","","0") | AM30: =IF(AL30="","","0")
J31: =IF(B32="","",B32&" - "&D32) | K31: =IFERROR(C32,"") | L31: 58 | M31: =IFERROR(J31,"") | N31: =IFERROR( XLOOKUP(M31,J:J,L:L),"") | O31: =IF($N31="","","0") | P31: =IF($N31="","","0") | Q31: =IF($N31="","","0") | R31: =IF($N31="","","0") | U31: F123 | X31: =IF($J31="","", LEFT($J31,3)&"_1p") | Y31: =IFERROR(M31,"") | Z31: =XLOOKUP(Y31,J:J,K:K) | AA31: =IF(Z31="","","ASL1") | AC31: =IF(X31="","","1") | AE31: =IF(X31="","","Chilled") | AG31: =B32 | AH31: =IFERROR( XLOOKUP(AG31,B:B,C:C),"") | AI31: =IFERROR(XLOOKUP(AH31,K:K,J:J),"") | AJ31: =AI31 | AK31: =IF(AJ31="","","1") | AL31: =IF(AK31="","","0") | AM31: =IF(AL31="","","0")
J32: =IF(B33="","",B33&" - "&D33) | K32: =IFERROR(C33,"") | L32: 58 | M32: =IFERROR(J32,"") | N32: =IFERROR( XLOOKUP(M32,J:J,L:L),"") | O32: =IF($N32="","","0") | P32: =IF($N32="","","0") | Q32: =IF($N32="","","0") | R32: =IF($N32="","","0") | U32: F134 | X32: =IF($J32="","", LEFT($J32,3)&"_1p") | Y32: =IFERROR(M32,"") | Z32: =XLOOKUP(Y32,J:J,K:K) | AA32: =IF(Z32="","","ASL1") | AC32: =IF(X32="","","1") | AE32: =IF(X32="","","Chilled") | AG32: =B33 | AH32: =IFERROR( XLOOKUP(AG32,B:B,C:C),"") | AI32: =IFERROR(XLOOKUP(AH32,K:K,J:J),"") | AJ32: =AI32 | AK32: =IF(AJ32="","","1") | AL32: =IF(AK32="","","0") | AM32: =IF(AL32="","","0")
J33: =IF(B34="","",B34&" - "&D34) | K33: =IFERROR(C34,"") | L33: {=IFERROR(XLOOKUP(K33,C:C,G:G),"")} | M33: =IFERROR(J33,"") | N33: =IFERROR( XLOOKUP(M33,J:J,L:L),"") | O33: =IF($N33="","","0") | P33: =IF($N33="","","0") | Q33: =IF($N33="","","0") | R33: =IF($N33="","","0") | X33: =IF($J33="","", LEFT($J33,3)&"_1p") | Y33: =IFERROR(M33,"") | Z33: =XLOOKUP(Y33,J:J,K:K) | AA33: =IF(Z33="","","ASL1") | AC33: =IF(X33="","","1") | AE33: =IF(X33="","","Chilled") | AG33: =B34 | AH33: =IFERROR( XLOOKUP(AG33,B:B,C:C),"") | AI33: =IFERROR(XLOOKUP(AH33,K:K,J:J),"") | AJ33: =AI33 | AK33: =IF(AJ33="","","1") | AL33: =IF(AK33="","","0") | AM33: =IF(AL33="","","0")
J34: =IF(B35="","",B35&" - "&D35) | K34: =IFERROR(C35,"") | M34: =IFERROR(J34,"") | O34: =IF($N34="","","0") | P34: =IF($N34="","","0") | Q34: =IF($N34="","","0") | R34: =IF($N34="","","0") | X34: =IF($J34="","", LEFT($J34,3)&"_1p") | Y34: =IFERROR(M34,"") | Z34: =XLOOKUP(Y34,J:J,K:K) | AA34: =IF(Z34="","","ASL1") | AC34: =IF(X34="","","1") | AE34: =IF(X34="","","Chilled") | AG34: =B35 | AH34: =IFERROR( XLOOKUP(AG34,B:B,C:C),"") | AI34: =IFERROR(XLOOKUP(AH34,K:K,J:J),"") | AJ34: =AI34 | AK34: =IF(AJ34="","","1") | AL34: =IF(AK34="","","0") | AM34: =IF(AL34="","","0")
J35: =IF(B36="","",B36&" - "&D36) | K35: =IFERROR(C36,"") | M35: =IFERROR(J34,"") | O35: =IF($N35="","","0") | P35: =IF($N35="","","0") | Q35: =IF($N35="","","0") | R35: =IF($N35="","","0") | X35: =IF($J35="","", LEFT($J35,3)&"_1p") | Y35: =IFERROR(M35,"") | Z35: =XLOOKUP(Y35,J:J,K:K) | AA35: =IF(Z35="","","ASL1") | AC35: =IF(X35="","","1") | AE35: =IF(X35="","","Chilled") | AG35: =B36 | AH35: =IFERROR( XLOOKUP(AG35,B:B,C:C),"") | AI35: =IFERROR(XLOOKUP(AH35,K:K,J:J),"") | AJ35: =AI35 | AK35: =IF(AJ35="","","1") | AL35: =IF(AK35="","","0") | AM35: =IF(AL35="","","0")
J36: =IF(B37="","",B37&" - "&D37) | K36: =IFERROR(C37,"") | M36: =IFERROR(J35,"") | O36: =IF($N36="","","0") | P36: =IF($N36="","","0") | Q36: =IF($N36="","","0") | R36: =IF($N36="","","0") | X36: =IF($J36="","", LEFT($J36,3)&"_1p") | Y36: =IFERROR(M36,"") | Z36: =XLOOKUP(Y36,J:J,K:K) | AA36: =IF(Z36="","","ASL1") | AC36: =IF(X36="","","1") | AE36: =IF(X36="","","Chilled") | AG36: =B37 | AH36: =IFERROR( XLOOKUP(AG36,B:B,C:C),"") | AI36: =IFERROR(XLOOKUP(AH36,K:K,J:J),"") | AJ36: =AI36 | AK36: =IF(AJ36="","","1") | AL36: =IF(AK36="","","0") | AM36: =IF(AL36="","","0")
J37: =IF(B38="","",B38&" - "&D38) | K37: =IFERROR(C38,"") | M37: =IFERROR(J36,"") | O37: =IF($N37="","","0") | P37: =IF($N37="","","0") | Q37: =IF($N37="","","0") | R37: =IF($N37="","","0") | X37: =IF($J37="","", LEFT($J37,3)&"_1p") | Y37: =IFERROR(M37,"") | Z37: =XLOOKUP(Y37,J:J,K:K) | AA37: =IF(Z37="","","ASL1") | AC37: =IF(X37="","","1") | AE37: =IF(X37="","","Chilled") | AP37: Ice pro Box | AQ37: Anzahl | AR37: Icepack
J38: =IF(B39="","",B39&" - "&D39) | M38: =IFERROR(J37,"") | O38: =IF($N38="","","0") | P38: =IF($N38="","","0") | Q38: =IF($N38="","","0") | R38: =IF($N38="","","0") | X38: =IF($J38="","", LEFT($J38,3)&"_1p") | Y38: =IFERROR(M38,"") | Z38: =XLOOKUP(Y38,J:J,K:K) | AA38: =IF(Z38="","","ASL1") | AC38: =IF(X38="","","1") | AE38: =IF(X38="","","Chilled") | AP38: 6 | AQ38: 1963 | AR38: 5138 | AS38: 1
J39: =IF(B40="","",B40&" - "&D40) | O39: =IF($N39="","","0") | P39: =IF($N39="","","0") | Q39: =IF($N39="","","0") | R39: =IF($N39="","","0") | X39: =IF($J38="","", LEFT($J38,3)&"_1p") | Y39: =IFERROR(M39,"") | AA39: =IF(Z39="","","ASL1") | AC39: =IF(X39="","","1") | AE39: =IF(X39="","","Chilled") | AP39: 9 | AQ39: 422 | AR39: 422 | AS39: 2
J40: =IF(B41="","",B41&" - "&D41) | O40: =IF($N40="","","0") | P40: =IF($N40="","","0") | Q40: =IF($N40="","","0") | R40: =IF($N40="","","0") | X40: =IF($J39="","", LEFT($J39,3)&"_1p") | Y40: =IFERROR(M40,"") | AA40: =IF(Z40="","","ASL1") | AC40: =IF(X40="","","1") | AE40: =IF(X40="","","Chilled") | AP40: 12 | AQ40: 184 | AR40: 5138 | AS40: 3
O41: =IF($N41="","","0") | P41: =IF($N41="","","0") | Q41: =IF($N41="","","0") | R41: =IF($N41="","","0") | X41: =IF($J40="","", LEFT($J40,3)&"_1p") | Y41: =IFERROR(M41,"") | AA41: =IF(Z41="","","ASL1") | AC41: =IF(X41="","","1") | AE41: =IF(X41="","","Chilled")
O42: =IF($N42="","","0") | P42: =IF($N42="","","0") | Q42: =IF($N42="","","0") | R42: =IF($N42="","","0") | X42: =IF($J42="","", LEFT($J42,3)&"_1p") | Y42: =IFERROR(M42,"") | AA42: =IF(Z42="","","ASL1") | AC42: =IF(X42="","","1") | AE42: =IF(X42="","","Chilled")
O43: =IF($N43="","","0") | P43: =IF($N43="","","0") | Q43: =IF($N43="","","0") | R43: =IF($N43="","","0") | X43: =IF($J43="","", LEFT($J43,3)&"_1p") | Y43: =IFERROR(M43,"") | AA43: =IF(Z43="","","ASL1") | AC43: =IF(X43="","","1") | AE43: =IF(X43="","","Chilled")
O44: =IF($N44="","","0") | P44: =IF($N44="","","0") | Q44: =IF($N44="","","0") | R44: =IF($N44="","","0") | X44: =IF($J44="","", LEFT($J44,3)&"_1p") | Y44: =IFERROR(M44,"") | AA44: =IF(Z44="","","ASL1") | AC44: =IF(X44="","","1") | AE44: =IF(X44="","","Chilled")
O45: =IF($N45="","","0") | P45: =IF($N45="","","0") | Q45: =IF($N45="","","0") | R45: =IF($N45="","","0") | X45: =IF($J45="","", LEFT($J45,3)&"_1p") | Y45: =IFERROR(M45,"") | AA45: =IF(Z45="","","ASL1") | AC45: =IF(X45="","","1") | AE45: =IF(X45="","","Chilled")
O46: =IF($N46="","","0") | P46: =IF($N46="","","0") | Q46: =IF($N46="","","0") | R46: =IF($N46="","","0") | X46: =IF($J46="","", LEFT($J46,3)&"_1p") | Y46: =IFERROR(M46,"") | AA46: =IF(Z46="","","ASL1") | AC46: =IF(X46="","","1") | AE46: =IF(X46="","","Chilled")
...

Sheet CONTROL_CENTER
B2: HALO Verden - FACTOR | J2: Production Week
J3: 19
E5: NEW JOB | J5: Line Mapping
E6: timestamp | F6: 46141.4 | G6: UTC
E7: dag | F7: HALO rackplanning DACH VE | J7: Line | K7: Market | L7: Run?
E8: s3 | F8: HALO model rack_planning DACH VE | J8: ASL1 | K8: DACH | L8: TRUE
E9: status | F9: =IF(ISBLANK(F6), "Start a new job by pressing the button", IFERROR(IF(Text(VLOOKUP("start_time",result_solver_stats!A:B,2,false), "YYYY-MM-DD HH:MM:SS") - Text(F6, "YYYY-MM-DD HH:MM:SS") > 0, VLOOKUP("problem_status",result_solver_stats!A:B,2,false), "Job started, please wait"), "Job started, please wait")) -> done | G9: =IF(ISBLANK(F9), "", IF(F9 = "FEASIBLE", round((VLOOKUP("final_mip_gap", matching_solver_stats!A:B,2,false) - VLOOKUP("max_mip_gap", matching_solver_stats!A:B,2,false)) * 100,0) & "% deviation", "")) | J9: ASL2 | K9: NORDICS | L9: TRUE
C11: Copy this to the UI
C12: halo||rack_planning||dach_ve_factor
E13: Reporting | K13: SKUs | L13: ActivePickfaces | N13: noch/übrig
E14: =IFERROR(IF(F9 = "infeas", VLOOKUP("infeasibility_info", result_solver_stats!A:B,2,FALSE), VLOOKUP("error_reporting", result_solver_stats!A:B,2,FALSE)),"") | J14: DE | K14: =COUNTIF('HALO input'!N:N,"DACH") -> 61 | L14: =COUNTIFS(layout!I:I,TRUE,layout!B:B,"ASL1") -> 62 | M14: =IF(K14<=L14,":) thank you Shaurya",":( I am sad Shaurya") -> :) thank you Shaurya | N14: =L14-K14 -> 1
J15: NO | K15: =COUNTIF('HALO input'!N:N,"Nordics") -> 43 | L15: =COUNTIFS(layout!I:I,TRUE,layout!B:B,"ASL2") -> 44 | M15: =IF(K15<=L15,":) thank you Shaurya",":( I am sad Shaurya") -> :) thank you Shaurya | N15: =L15-K15 -> 1
C20: Export P2L check: | E20: =IFERROR(__xludf.DUMMYFUNCTION("IF(COUNTUNIQUE('HALO input'!A:A)=COUNTUNIQUE(Output_HALO!B:B), True, False)"),FALSE) -> FALSE | F20: All SKUs from HALO input are in HALO output
E21: =COUNTA(Rackfile_combined!A:A)=COUNTA(exportP2L!A:A) -> FALSE | F21: Rackfile_combined SKUs are the same as in exportP2L | J21: 3p | K21: 2 | L21: 3 | M21: 4
E22: =COUNTIF(PivotCheck__exportP2L!B:B,">1")=0 -> TRUE | F22: No pickface has more than 1 SKU in exportP2L | J22: 2p | K22: 5 | L22: 6 | M22: 7
J23: 3p | K23: 8 | L23: 9 | M23: 10
J24: 2p | K24: 11 | L24: 12 | M24: 13
J25: 3p | K25: 14 | L25: 15 | M25: 16
J26: 2p | K26: 17 | L26: 18 | M26: 19
B28: F_DE
B29: 300er | C29: Core
B30: 200er | C30: Addons
B31: 200er | C31: Free2Life
B32: F_NO
B33: 600er | C33: Core
B34: 700er | C34: Addons
B35: F_NL/BE
B36: 400er | C36: Core
B37: 500er | C37: Addons

Sheet Inputs Maite DE
A1: MANUELL EINTRAGEN | B1: Demand für Smoothies/Ice needs to be filled manually
T3: VolumeFile
T5: name | U5: demand_thursday | V5: demand_friday | W5: demand_saturday | X5: demand_sunday | Y5: demand_monday | Z5: station_constraint | AA5: level_constraint | AB5: pickface_constraint | AC5: separate_constraint
T6: IcePack1 | U6: =IFERROR(ROUNDUP( XLOOKUP(T6,Q:Q,S:S),0.1),"") -> 2194 | V6: 0 | W6: 0 | X6: 0 | Y6: 0 | AB6: F144 | AE6: RackFile_Combined
Q7: Converter TABLE | T7: IcePack2 | U7: =IFERROR(ROUNDUP( XLOOKUP(T7,Q:Q,S:S),0.1),"") -> 1887 | V7: 0 | W7: 0 | X7: 0 | Y7: 0 | AB7: F105
A8: Woche | B8: Rezept | C8: SKU | D8: Maitre Code | E8: Artikel | F8: wed -4wk | G8: wed -3wk | H8: wed -2wk | I8: wed-1wk | J8: Fri -1wk | K8: Mon | L8: Tues | M8: Weds | N8: Thurs | O8: order | Q8: =IF(B8="","",B8&" - "&E8) -> Rezept - Artikel | R8: SKU | S8: Target | T8: IcePack3 | U8: =IFERROR(ROUNDUP( XLOOKUP(T8,Q:Q,S:S),0.1),"") -> 2194 | V8: 0 | W8: 0 | X8: 0 | Y8: 0 | AB8: F127 | AE8: Recipe | AF8: Ingredient | AG8: SKU | AH8: Line | AI8: FlowRackPosition | AJ8: Quantity | AK8: ScanRegEx | AL8: StorageConditions
A9: =IFERROR(__xludf.DUMMYFUNCTION("FILTER('Maitre Inputs DENO_Stamm'!$B:$D,'Maitre Inputs DENO_Stamm'!$B:$B=""W""&CONTROL_CENTER!$J$3,'Maitre Inputs DENO_Stamm'!A:A=""DE"")"),"W19") -> W19 | B9: =IFERROR(__xludf.DUMMYFUNCTION("""COMPUTED_VALUE"""),301.0) -> 301 | C9: =IFERROR(__xludf.DUMMYFUNCTION("""COMPUTED_VALUE"""),"CON-00-136674-3") -> CON-00-136674-3 | D9: =IFERROR(__xludf.DUMMYFUNCTION("FILTER(RIGHT('Maitre Inputs DENO_Stamm'!$H:$H,6),'Maitre Inputs DENO_Stamm'!$B:$B=""W""&CONTROL_CENTER!$J$3,'Maitre Inputs DENO_Stamm'!A:A=""DE"")"),"565072") -> 565072 | E9: =IFERROR(__xludf.DUMMYFUNCTION("FILTER('Maitre Inputs DENO_Stamm'!F:F,'Maitre Inputs DENO_Stamm'!$B:$B=""W""&CONTROL_CENTER!$J$3,'Maitre Inputs DENO_Stamm'!A:A=""DE"")"),"Gegrilltes Hähnchen mit Ratatouille") -> Gegrilltes Hähnchen mit Ratatouille | F9: =IFERROR(__xludf.DUMMYFUNCTION("FILTER('Maitre Inputs DENO_Stamm'!J:S,'Maitre Inputs DENO_Stamm'!$B:$B=""W""&CONTROL_CENTER!$J$3,'Maitre Inputs DENO_Stamm'!A:A=""DE"")"),2603.0) -> 2603 | G9: =IFERROR(__xludf.DUMMYFUNCTION("""COMPUTED_VALUE"""),2473.0) -> 2473 | H9: =IFERROR(__xludf.DUMMYFUNCTION("""COMPUTED_VALUE"""),2722.0) -> 2722 | I9: =IFERROR(__xludf.DUMMYFUNCTION("""COMPUTED_VALUE"""),2659.0) -> 2659 | J9: =IFERROR(__xludf.DUMMYFUNCTION("""COMPUTED_VALUE"""),3014.0) -> 3014 | L9: =IFERROR(__xludf.DUMMYFUNCTION("""COMPUTED_VALUE"""),2993.0) -> 2993 | M9: =IFERROR(__xludf.DUMMYFUNCTION("""COMPUTED_VALUE"""),2993.0) -> 2993 | O9: =IFERROR(__xludf.DUMMYFUNCTION("""COMPUTED_VALUE"""),2982.0) -> 2982 | Q9: =IF(D9="","",D9&" - "&E9) -> 565072 - Gegrilltes Hähnchen mit Ratatouille | R9: =IFERROR(C9,"") -> CON-00-136674-3 | S9: =IFS(O9<>"",O9,AND(O9="",N9="",M9="",L9="",K9="",J9="",I9="",H9="",G9=""),F9,AND(O9="",N9="",M9="",L9="",K9="",J9="",I9="",H9=""),G9,AND(O9="",N9="",M9="",L9="",K9="",J9="",I9=""),H9,AND(O9="",N9="",M9="",L9="",K9="",J9=""), I9,AND(O9="",N9="",M9="",L9="",K9=""),J9,AND(O9="",N9="",M9="",L9=""), K9, AND(O9="",N9="",M9=""), L9,AND(O9="",N9=""), M9, AND(O9=""), N9) -> 2982 | T9: =IFERROR(Q9,"") -> 565072 - Gegrilltes Hähnchen mit Ratatouille | U9: =IFERROR(ROUNDUP( XLOOKUP(T9,Q:Q,S:S),0.1),"") -> 2982 | V9: =IF($U9="","","0") -> 0 | W9: =IF($U9="","","0") -> 0 | X9: =IF($U9="","","0") -> 0 | Y9: =IF($U9="","","0") -> 0 | AE9: =IF($B9="","", LEFT($B9,3)&"_1p") -> 301_1p | AF9: =IFERROR(T9,"") -> 565072 - Gegrilltes Hähnchen mit Ratatouille | AG9: =XLOOKUP(AF9,Q:Q,R:R) -> CON-00-136674-3 | AH9: =IF(AF9="","","ASL1") -> ASL1 | AJ9: =IF(AE9="","","1") -> 1 | AL9: =IF(AE9="","","Chilled") -> Chilled
A10: =IFERROR(__xludf.DUMMYFUNCTION("""COMPUTED_VALUE"""),"W19") -> W19 | B10: =IFERROR(__xludf.DUMMYFUNCTION("""COMPUTED_VALUE"""),302.0) -> 302 | C10: =IFERROR(__xludf.DUMMYFUNCTION("""COMPUTED_VALUE"""),"CON-00-152205-2") -> CON-00-152205-2 | D10: =IFERROR(__xludf.DUMMYFUNCTION("""COMPUTED_VALUE"""),"565209") -> 565209 | E10: =IFERROR(__xludf.DUMMYFUNCTION("""COMPUTED_VALUE"""),"Grünes Chili-Hähnchen mit Quinoa-Salsa") -> Grünes Chili-Hähnchen mit Quinoa-Salsa | F10: =IFERROR(__xludf.DUMMYFUNCTION("""COMPUTED_VALUE"""),1564.0) -> 1564 | G10: =IFERROR(__xludf.DUMMYFUNCTION("""COMPUTED_VALUE"""),1510.0) -> 1510 | H10: =IFERROR(__xludf.DUMMYFUNCTION("""COMPUTED_VALUE"""),1661.0) -> 1661 | I10: =IFERROR(__xludf.DUMMYFUNCTION("""COMPUTED_VALUE"""),1690.0) -> 1690 | J10: =IFERROR(__xludf.DUMMYFUNCTION("""COMPUTED_VALUE"""),1931.0) -> 1931 | L10: =IFERROR(__xludf.DUMMYFUNCTION("""COMPUTED_VALUE"""),1863.0) -> 1863 | M10: =IFERROR(__xludf.DUMMYFUNCTION("""COMPUTED_VALUE"""),1860.0) -> 1860 | O10: =IFERROR(__xludf.DUMMYFUNCTION("""COMPUTED_VALUE"""),1852.0) -> 1852 | Q10: =IF(D10="","",D10&" - "&E10) -> 565209 - Grünes Chili-Hähnchen mit Quinoa-Salsa | R10: =IFERROR(C10,"") -> CON-00-152205-2 | S10: =IFS(O10<>"",O10,AND(O10="",N10="",M10="",L10="",K10="",J10="",I10="",H10="",G10=""),F10,AND(O10="",N10="",M10="",L10="",K10="",J10="",I10="",H10=""),G10,AND(O10="",N10="",M10="",L10="",K10="",J10="",I10=""),H10,AND(O10="",N10="",M10="",L10="",K10="",J10=""), I10,AND(O10="",N10="",M10="",L10="",K10=""),J10,AND(O10="",N10="",M10="",L10=""), K10, AND(O10="",N10="",M10=""), L10,AND(O10="",N10=""), M10, AND(O10=""), N10) -> 1852 | T10: =IFERROR(Q10,"") -> 565209 - Grünes Chili-Hähnchen mit Quinoa-Salsa | U10: =IFERROR(ROUNDUP( XLOOKUP(T10,Q:Q,S:S),0.1),"") -> 1852 | V10: =IF($U10="","","0") -> 0 | W10: =IF($U10="","","0") -> 0 | X10: =IF($U10="","","0") -> 0 | Y10: =IF($U10="","","0") -> 0 | AE10: =IF($B10="","", LEFT($B10,3)&"_1p") -> 302_1p | AF10: =IFERROR(T10,"") -> 565209 - Grünes Chili-Hähnchen mit Quinoa-Salsa | AG10: =XLOOKUP(AF10,Q:Q,R:R) -> CON-00-152205-2 | AH10: =IF(AF10="","","ASL1") -> ASL1 | AJ10: =IF(AE10="","","1") -> 1 | AL10: =IF(AE10="","","Chilled") -> Chilled
A11: =IFERROR(__xludf.DUMMYFUNCTION("""COMPUTED_VALUE"""),"W19") -> W19 | B11: =IFERROR(__xludf.DUMMYFUNCTION("""COMPUTED_VALUE"""),303.0) -> 303 | C11: =IFERROR(__xludf.DUMMYFUNCTION("""COMPUTED_VALUE"""),"CON-00-136698-3") -> CON-00-136698-3 | D11: =IFERROR(__xludf.DUMMYFUNCTION("""COMPUTED_VALUE"""),"565309") -> 565309 | E11: =IFERROR(__xludf.DUMMYFUNCTION("""COMPUTED_VALUE"""),"Geschmortes Rind in Kräuterjus") -> Geschmortes Rind in Kräuterjus | F11: =IFERROR(__xludf.DUMMYFUNCTION("""COMPUTED_VALUE"""),0.0) -> 0 | G11: =IFERROR(__xludf.DUMMYFUNCTION("""COMPUTED_VALUE"""),0.0) -> 0 | H11: =IFERROR(__xludf.DUMMYFUNCTION("""COMPUTED_VALUE"""),0.0) -> 0 | I11: =IFERROR(__xludf.DUMMYFUNCTION("""COMPUTED_VALUE"""),1930.0) -> 1930 | J11: =IFERROR(__xludf.DUMMYFUNCTION("""COMPUTED_VALUE"""),2105.0) -> 2105 | L11: =IFERROR(__xludf.DUMMYFUNCTION("""COMPUTED_VALUE"""),2052.0) -> 2052 | M11: =IFERROR(__xludf.DUMMYFUNCTION("""COMPUTED_VALUE"""),2060.0) -> 2060 | O11: =IFERROR(__xludf.DUMMYFUNCTION("""COMPUTED_VALUE"""),2002.0) -> 2002 | Q11: =IF(D11="","",D11&" - "&E11) -> 565309 - Geschmortes Rind in Kräuterjus | R11: =IFERROR(C11,"") -> CON-00-136698-3 | S11: =IFS(O11<>"",O11,AND(O11="",N11="",M11="",L11="",K11="",J11="",I11="",H11="",G11=""),F11,AND(O11="",N11="",M11="",L11="",K11="",J11="",I11="",H11=""),G11,AND(O11="",N11="",M11="",L11="",K11="",J11="",I11=""),H11,AND(O11="",N11="",M11="",L11="",K11="",J11=""), I11,AND(O11="",N11="",M11="",L11="",K11=""),J11,AND(O11="",N11="",M11="",L11=""), K11, AND(O11="",N11="",M11=""), L11,AND(O11="",N11=""), M11, AND(O11=""), N11) -> 2002 | T11: =IFERROR(Q11,"") -> 565309 - Geschmortes Rind in Kräuterjus | U11: =IFERROR(ROUNDUP( XLOOKUP(T11,Q:Q,S:S),0.1),"") -> 2002 | V11: =IF($U11="","","0") -> 0 | W11: =IF($U11="","","0") -> 0 | X11: =IF($U11="","","0") -> 0 | Y11: =IF($U11="","","0") -> 0 | AE11: =IF($B11="","", LEFT($B11,3)&"_1p") -> 303_1p | AF11: =IFERROR(T11,"") -> 565309 - Geschmortes Rind in Kräuterjus | AG11: =XLOOKUP(AF11,Q:Q,R:R) -> CON-00-136698-3 | AH11: =IF(AF11="","","ASL1") -> ASL1 | AJ11: =IF(AE11="","","1") -> 1 | AL11: =IF(AE11="","","Chilled") -> Chilled
A12: =IFERROR(__xludf.DUMMYFUNCTION("""COMPUTED_VALUE"""),"W19") -> W19 | B12: =IFERROR(__xludf.DUMMYFUNCTION("""COMPUTED_VALUE"""),304.0) -> 304 | C12: =IFERROR(__xludf.DUMMYFUNCTION("""COMPUTED_VALUE"""),"CON-00-137745-2") -> CON-00-137745-2 | D12: =IFERROR(__xludf.DUMMYFUNCTION("""COMPUTED_VALUE"""),"565064") -> 565064 | E12: =IFERROR(__xludf.DUMMYFUNCTION("""COMPUTED_VALUE"""),"Lachs in Senf-Dill-Sauce") -> Lachs in Senf-Dill-Sauce | F12: =IFERROR(__xludf.DUMMYFUNCTION("""COMPUTED_VALUE"""),0.0) -> 0 | G12: =IFERROR(__xludf.DUMMYFUNCTION("""COMPUTED_VALUE"""),0.0) -> 0 | H12: =IFERROR(__xludf.DUMMYFUNCTION("""COMPUTED_VALUE"""),0.0) -> 0 | I12: =IFERROR(__xludf.DUMMYFUNCTION("""COMPUTED_VALUE"""),0.0) -> 0 | J12: =IFERROR(__xludf.DUMMYFUNCTION("""COMPUTED_VALUE"""),0.0) -> 0 | L12: =IFERROR(__xludf.DUMMYFUNCTION("""COMPUTED_VALUE"""),0.0) -> 0 | M12: =IFERROR(__xludf.DUMMYFUNCTION("""COMPUTED_VALUE"""),0.0) -> 0 | O12: =IFERROR(__xludf.DUMMYFUNCTION("""COMPUTED_VALUE"""),10.0) -> 10 | Q12: =IF(D12="","",D12&" - "&E12) -> 565064 - Lachs in Senf-Dill-Sauce | R12: =IFERROR(C12,"") -> CON-00-137745-2 | S12: =IFS(O12<>"",O12,AND(O12="",N12="",M12="",L12="",K12="",J12="",I12="",H12="",G12=""),F12,AND(O12="",N12="",M12="",L12="",K12="",J12="",I12="",H12=""),G12,AND(O12="",N12="",M12="",L12="",K12="",J12="",I12=""),H12,AND(O12="",N12="",M12="",L12="",K12="",J12=""), I12,AND(O12="",N12="",M12="",L12="",K12=""),J12,AND(O12="",N12="",M12="",L12=""), K12, AND(O12="",N12="",M12=""), L12,AND(O12="",N12=""), M12, AND(O12=""), N12) -> 10 | T12: =IFERROR(Q12,"") -> 565064 - Lachs in Senf-Dill-Sauce | U12: =IFERROR(ROUNDUP( XLOOKUP(T12,Q:Q,S:S),0.1),"") -> 10 | V12: =IF($U12="","","0") -> 0 | W12: =IF($U12="","","0") -> 0 | X12: =IF($U12="","","0") -> 0 | Y12: =IF($U12="","","0") -> 0 | AE12: =IF($B12="","", LEFT($B12,3)&"_1p") -> 304_1p | AF12: =IFERROR(T12,"") -> 565064 - Lachs in Senf-Dill-Sauce | AG12: =XLOOKUP(AF12,Q:Q,R:R) -> CON-00-137745-2 | AH12: =IF(AF12="","","ASL1") -> ASL1 | AJ12: =IF(AE12="","","1") -> 1 | AL12: =IF(AE12="","","Chilled") -> Chilled
A13: =IFERROR(__xludf.DUMMYFUNCTION("""COMPUTED_VALUE"""),"W19") -> W19 | B13: =IFERROR(__xludf.DUMMYFUNCTION("""COMPUTED_VALUE"""),305.0) -> 305 | C13: =IFERROR(__xludf.DUMMYFUNCTION("""COMPUTED_VALUE"""),"CON-00-150748-2") -> CON-00-150748-2 | D13: =IFERROR(__xludf.DUMMYFUNCTION("""COMPUTED_VALUE"""),"565178") -> 565178 | E13: =IFERROR(__xludf.DUMMYFUNCTION("""COMPUTED_VALUE"""),"Westafrikanisches Hähnchen-Erdnuss-Curry") -> Westafrikanisches Hähnchen-Erdnuss-Curry | F13: =IFERROR(__xludf.DUMMYFUNCTION("""COMPUTED_VALUE"""),1434.0) -> 1434 | G13: =IFERROR(__xludf.DUMMYFUNCTION("""COMPUTED_VALUE"""),1356.0) -> 1356 | H13: =IFERROR(__xludf.DUMMYFUNCTION("""COMPUTED_VALUE"""),1498.0) -> 1498 | I13: =IFERROR(__xludf.DUMMYFUNCTION("""COMPUTED_VALUE"""),2091.0) -> 2091 | J13: =IFERROR(__xludf.DUMMYFUNCTION("""COMPUTED_VALUE"""),2233.0) -> 2233 | L13: =IFERROR(__xludf.DUMMYFUNCTION("""COMPUTED_VALUE"""),2180.0) -> 2180 | M13: =IFERROR(__xludf.DUMMYFUNCTION("""COMPUTED_VALUE"""),2144.0) -> 2144 | O13: =IFERROR(__xludf.DUMMYFUNCTION("""COMPUTED_VALUE"""),2006.0) -> 2006 | Q13: =IF(D13="","",D13&" - "&E13) -> 565178 - Westafrikanisches Hähnchen-Erdnuss-Curry | R13: =IFERROR(C13,"") -> CON-00-150748-2 | S13: =IFS(O13<>"",O13,AND(O13="",N13="",M13="",L13="",K13="",J13="",I13="",H13="",G13=""),F13,AND(O13="",N13="",M13="",L13="",K13="",J13="",I13="",H13=""),G13,AND(O13="",N13="",M13="",L13="",K13="",J13="",I13=""),H13,AND(O13="",N13="",M13="",L13="",K13="",J13=""), I13,AND(O13="",N13="",M13="",L13="",K13=""),J13,AND(O13="",N13="",M13="",L13=""), K13, AND(O13="",N13="",M13=""), L13,AND(O13="",N13=""), M13, AND(O13=""), N13) -> 2006 | T13: =IFERROR(Q13,"") -> 565178 - Westafrikanisches Hähnchen-Erdnuss-Curry | U13: =IFERROR(ROUNDUP( XLOOKUP(T13,Q:Q,S:S),0.1),"") -> 2006 | V13: =IF($U13="","","0") -> 0 | W13: =IF($U13="","","0") -> 0 | X13: =IF($U13="","","0") -> 0 | Y13: =IF($U13="","","0") -> 0 | AE13: =IF($B13="","", LEFT($B13,3)&"_1p") -> 305_1p | AF13: =IFERROR(T13,"") -> 565178 - Westafrikanisches Hähnchen-Erdnuss-Curry | AG13: =XLOOKUP(AF13,Q:Q,R:R) -> CON-00-150748-2 | AH13: =IF(AF13="","","ASL1") -> ASL1 | AJ13: =IF(AE13="","","1") -> 1 | AL13: =IF(AE13="","","Chilled") -> Chilled
A14: =IFERROR(__xludf.DUMMYFUNCTION("""COMPUTED_VALUE"""),"W19") -> W19 | B14: =IFERROR(__xludf.DUMMYFUNCTION("""COMPUTED_VALUE"""),306.0) -> 306 | C14: =IFERROR(__xludf.DUMMYFUNCTION("""COMPUTED_VALUE"""),"CON-00-152025-2") -> CON-00-152025-2 | D14: =IFERROR(__xludf.DUMMYFUNCTION("""COMPUTED_VALUE"""),"565189") -> 565189 | E14: =IFERROR(__xludf.DUMMYFUNCTION("""COMPUTED_VALUE"""),"Lachs Piccata") -> Lachs Piccata | F14: =IFERROR(__xludf.DUMMYFUNCTION("""COMPUTED_VALUE"""),0.0) -> 0 | G14: =IFERROR(__xludf.DUMMYFUNCTION("""COMPUTED_VALUE"""),0.0) -> 0 | H14: =IFERROR(__xludf.DUMMYFUNCTION("""COMPUTED_VALUE"""),0.0) -> 0 | I14: =IFERROR(__xludf.DUMMYFUNCTION("""COMPUTED_VALUE"""),0.0) -> 0 | J14: =IFERROR(__xludf.DUMMYFUNCTION("""COMPUTED_VALUE"""),0.0) -> 0 | L14: =IFERROR(__xludf.DUMMYFUNCTION("""COMPUTED_VALUE"""),0.0) -> 0 | M14: =IFERROR(__xludf.DUMMYFUNCTION("""COMPUTED_VALUE"""),0.0) -> 0 | O14: =IFERROR(__xludf.DUMMYFUNCTION("""COMPUTED_VALUE"""),10.0) -> 10 | Q14: =IF(D14="","",D14&" - "&E14) -> 565189 - Lachs Piccata | R14: =IFERROR(C14,"") -> CON-00-152025-2 | S14: =IFS(O14<>"",O14,AND(O14="",N14="",M14="",L14="",K14="",J14="",I14="",H14="",G14=""),F14,AND(O14="",N14="",M14="",L14="",K14="",J14="",I14="",H14=""),G14,AND(O14="",N14="",M14="",L14="",K14="",J14="",I14=""),H14,AND(O14="",N14="",M14="",L14="",K14="",J14=""), I14,AND(O14="",N14="",M14="",L14="",K14=""),J14,AND(O14="",N14="",M14="",L14=""), K14, AND(O14="",N14="",M14=""), L14,AND(O14="",N14=""), M14, AND(O14=""), N14) -> 10 | T14: =IFERROR(Q14,"") -> 565189 - Lachs Piccata | U14: =IFERROR(ROUNDUP( XLOOKUP(T14,Q:Q,S:S),0.1),"") -> 10 | V14: =IF($U14="","","0") -> 0 | W14: =IF($U14="","","0") -> 0 | X14: =IF($U14="","","0") -> 0 | Y14: =IF($U14="","","0") -> 0 | AE14: =IF($B14="","", LEFT($B14,3)&"_1p") -> 306_1p | AF14: =IFERROR(T14,"") -> 565189 - Lachs Piccata | AG14: =XLOOKUP(AF14,Q:Q,R:R) -> CON-00-152025-2 | AH14: =IF(AF14="","","ASL1") -> ASL1 | AJ14: =IF(AE14="","","1") -> 1 | AL14: =IF(AE14="","","Chilled") -> Chilled
A15: =IFERROR(__xludf.DUMMYFUNCTION("""COMPUTED_VALUE"""),"W19") -> W19 | B15: =IFERROR(__xludf.DUMMYFUNCTION("""COMPUTED_VALUE"""),307.0) -> 307 | C15: =IFERROR(__xludf.DUMMYFUNCTION("""COMPUTED_VALUE"""),"CON-00-148220-2") -> CON-00-148220-2 | D15: =IFERROR(__xludf.DUMMYFUNCTION("""COMPUTED_VALUE"""),"565164") -> 565164 | E15: =IFERROR(__xludf.DUMMYFUNCTION("""COMPUTED_VALUE"""),"Hähnchen mit karamellisierten Zwiebeln & Emmentaler-Fondue") -> Hähnchen mit karamellisierten Zwiebeln & Emmentaler-Fondue | F15: =IFERROR(__xludf.DUMMYFUNCTION("""COMPUTED_VALUE"""),0.0) -> 0 | G15: =IFERROR(__xludf.DUMMYFUNCTION("""COMPUTED_VALUE"""),0.0) -> 0 | H15: =IFERROR(__xludf.DUMMYFUNCTION("""COMPUTED_VALUE"""),0.0) -> 0 | I15: =IFERROR(__xludf.DUMMYFUNCTION("""COMPUTED_VALUE"""),0.0) -> 0 | J15: =IFERROR(__xludf.DUMMYFUNCTION("""COMPUTED_VALUE"""),0.0) -> 0 | L15: =IFERROR(__xludf.DUMMYFUNCTION("""COMPUTED_VALUE"""),0.0) -> 0 | M15: =IFERROR(__xludf.DUMMYFUNCTION("""COMPUTED_VALUE"""),0.0) -> 0 | O15: =IFERROR(__xludf.DUMMYFUNCTION("""COMPUTED_VALUE"""),61.0) -> 61 | Q15: =IF(D15="","",D15&" - "&E15) -> 565164 - Hähnchen mit karamellisierten Zwiebeln & Emmentaler-Fondue | R15: =IFERROR(C15,"") -> CON-00-148220-2 | S15: =IFS(O15<>"",O15,AND(O15="",N15="",M15="",L15="",K15="",J15="",I15="",H15="",G15=""),F15,AND(O15="",N15="",M15="",L15="",K15="",J15="",I15="",H15=""),G15,AND(O15="",N15="",M15="",L15="",K15="",J15="",I15=""),H15,AND(O15="",N15="",M15="",L15="",K15="",J15=""), I15,AND(O15="",N15="",M15="",L15="",K15=""),J15,AND(O15="",N15="",M15="",L15=""), K15, AND(O15="",N15="",M15=""), L15,AND(O15="",N15=""), M15, AND(O15=""), N15) -> 61 | T15: =IFERROR(Q15,"") -> 565164 - Hähnchen mit karamellisierten Zwiebeln & Emmentaler-Fondue | U15: =IFERROR(ROUNDUP( XLOOKUP(T15,Q:Q,S:S),0.1),"") -> 61 | V15: =IF($U15="","","0") -> 0 | W15: =IF($U15="","","0") -> 0 | X15: =IF($U15="","","0") -> 0 | Y15: =IF($U15="","","0") -> 0 | AE15: =IF($B15="","", LEFT($B15,3)&"_1p") -> 307_1p | AF15: =IFERROR(T15,"") -> 565164 - Hähnchen mit karamellisierten Zwiebeln & Emmentaler-Fondue | AG15: =XLOOKUP(AF15,Q:Q,R:R) -> CON-00-148220-2 | AH15: =IF(AF15="","","ASL1") -> ASL1 | AJ15: =IF(AE15="","","1") -> 1 | AL15: =IF(AE15="","","Chilled") -> Chilled
A16: =IFERROR(__xludf.DUMMYFUNCTION("""COMPUTED_VALUE"""),"W19") -> W19 | B16: =IFERROR(__xludf.DUMMYFUNCTION("""COMPUTED_VALUE"""),308.0) -> 308 | C16: =IFERROR(__xludf.DUMMYFUNCTION("""COMPUTED_VALUE"""),"CON-00-136638-3") -> CON-00-136638-3 | D16: =IFERROR(__xludf.DUMMYFUNCTION("""COMPUTED_VALUE"""),"565043") -> 565043 | E16: =IFERROR(__xludf.DUMMYFUNCTION("""COMPUTED_VALUE"""),"Würziges Hähnchen mit Jalapeño, Limette und Cheddar") -> Würziges Hähnchen mit Jalapeño, Limette und Cheddar | F16: =IFERROR(__xludf.DUMMYFUNCTION("""COMPUTED_VALUE"""),1067.0) -> 1067 | G16: =IFERROR(__xludf.DUMMYFUNCTION("""COMPUTED_VALUE"""),997.0) -> 997 | H16: =IFERROR(__xludf.DUMMYFUNCTION("""COMPUTED_VALUE"""),1102.0) -> 1102 | I16: =IFERROR(__xludf.DUMMYFUNCTION("""COMPUTED_VALUE"""),1268.0) -> 1268 | J16: =IFERROR(__xludf.DUMMYFUNCTION("""COMPUTED_VALUE"""),1331.0) -> 1331 | L16: =IFERROR(__xludf.DUMMYFUNCTION("""COMPUTED_VALUE"""),1246.0) -> 1246 | M16: =IFERROR(__xludf.DUMMYFUNCTION("""COMPUTED_VALUE"""),1263.0) -> 1263 | O16: =IFERROR(__xludf.DUMMYFUNCTION("""COMPUTED_VALUE"""),1133.0) -> 1133 | Q16: =IF(D16="","",D16&" - "&E16) -> 565043 - Würziges Hähnchen mit Jalapeño, Limette und Cheddar | R16: =IFERROR(C16,"") -> CON-00-136638-3 | S16: =IFS(O16<>"",O16,AND(O16="",N16="",M16="",L16="",K16="",J16="",I16="",H16="",G16=""),F16,AND(O16="",N16="",M16="",L16="",K16="",J16="",I16="",H16=""),G16,AND(O16="",N16="",M16="",L16="",K16="",J16="",I16=""),H16,AND(O16="",N16="",M16="",L16="",K16="",J16=""), I16,AND(O16="",N16="",M16="",L16="",K16=""),J16,AND(O16="",N16="",M16="",L16=""), K16, AND(O16="",N16="",M16=""), L16,AND(O16="",N16=""), M16, AND(O16=""), N16) -> 1133 | T16: =IFERROR(Q16,"") -> 565043 - Würziges Hähnchen mit Jalapeño, Limette und Cheddar | U16: =IFERROR(ROUNDUP( XLOOKUP(T16,Q:Q,S:S),0.1),"") -> 1133 | V16: =IF($U16="","","0") -> 0 | W16: =IF($U16="","","0") -> 0 | X16: =IF($U16="","","0") -> 0 | Y16: =IF($U16="","","0") -> 0 | AE16: =IF($B16="","", LEFT($B16,3)&"_1p") -> 308_1p | AF16: =IFERROR(T16,"") -> 565043 - Würziges Hähnchen mit Jalapeño, Limette und Cheddar | AG16: =XLOOKUP(AF16,Q:Q,R:R) -> CON-00-136638-3 | AH16: =IF(AF16="","","ASL1") -> ASL1 | AJ16: =IF(AE16="","","1") -> 1 | AL16: =IF(AE16="","","Chilled") -> Chilled
A17: =IFERROR(__xludf.DUMMYFUNCTION("""COMPUTED_VALUE"""),"W19") -> W19 | B17: =IFERROR(__xludf.DUMMYFUNCTION("""COMPUTED_VALUE"""),309.0) -> 309 | C17: =IFERROR(__xludf.DUMMYFUNCTION("""COMPUTED_VALUE"""),"CON-00-136629-3") -> CON-00-136629-3 | D17: =IFERROR(__xludf.DUMMYFUNCTION("""COMPUTED_VALUE"""),"565244") -> 565244 | E17: =IFERROR(__xludf.DUMMYFUNCTION("""COMPUTED_VALUE"""),"Cremiges Tomaten-Risotto") -> Cremiges Tomaten-Risotto | F17: =IFERROR(__xludf.DUMMYFUNCTION("""COMPUTED_VALUE"""),279.0) -> 279 | G17: =IFERROR(__xludf.DUMMYFUNCTION("""COMPUTED_VALUE"""),272.0) -> 272 | H17: =IFERROR(__xludf.DUMMYFUNCTION("""COMPUTED_VALUE"""),296.0) -> 296 | I17: =IFERROR(__xludf.DUMMYFUNCTION("""COMPUTED_VALUE"""),317.0) -> 317 | J17: =IFERROR(__xludf.DUMMYFUNCTION("""COMPUTED_VALUE"""),333.0) -> 333 | L17: =IFERROR(__xludf.DUMMYFUNCTION("""COMPUTED_VALUE"""),326.0) -> 326 | M17: =IFERROR(__xludf.DUMMYFUNCTION("""COMPUTED_VALUE"""),330.0) -> 330 | O17: =IFERROR(__xludf.DUMMYFUNCTION("""COMPUTED_VALUE"""),368.0) -> 368 | Q17: =IF(D17="","",D17&" - "&E17) -> 565244 - Cremiges Tomaten-Risotto | R17: =IFERROR(C17,"") -> CON-00-136629-3 | S17: =IFS(O17<>"",O17,AND(O17="",N17="",M17="",L17="",K17="",J17="",I17="",H17="",G17=""),F17,AND(O17="",N17="",M17="",L17="",K17="",J17="",I17="",H17=""),G17,AND(O17="",N17="",M17="",L17="",K17="",J17="",I17=""),H17,AND(O17="",N17="",M17="",L17="",K17="",J17=""), I17,AND(O17="",N17="",M17="",L17="",K17=""),J17,AND(O17="",N17="",M17="",L17=""), K17, AND(O17="",N17="",M17=""), L17,AND(O17="",N17=""), M17, AND(O17=""), N17) -> 368 | T17: =IFERROR(Q17,"") -> 565244 - Cremiges Tomaten-Risotto | U17: =IFERROR(ROUNDUP( XLOOKUP(T17,Q:Q,S:S),0.1),"") -> 368 | V17: =IF($U17="","","0") -> 0 | W17: =IF($U17="","","0") -> 0 | X17: =IF($U17="","","0") -> 0 | Y17: =IF($U17="","","0") -> 0 | AE17: =IF($B17="","", LEFT($B17,3)&"_1p") -> 309_1p | AF17: =IFERROR(T17,"") -> 565244 - Cremiges Tomaten-Risotto | AG17: =XLOOKUP(AF17,Q:Q,R:R) -> CON-00-136629-3 | AH17: =IF(AF17="","","ASL1") -> ASL1 | AJ17: =IF(AE17="","","1") -> 1 | AL17: =IF(AE17="","","Chilled") -> Chilled
A18: =IFERROR(__xludf.DUMMYFUNCTION("""COMPUTED_VALUE"""),"W19") -> W19 | B18: =IFERROR(__xludf.DUMMYFUNCTION("""COMPUTED_VALUE"""),310.0) -> 310 | C18: =IFERROR(__xludf.DUMMYFUNCTION("""COMPUTED_VALUE"""),"CON-00-136634-3") -> CON-00-136634-3 | D18: =IFERROR(__xludf.DUMMYFUNCTION("""COMPUTED_VALUE"""),"565141") -> 565141 | E18: =IFERROR(__xludf.DUMMYFUNCTION("""COMPUTED_VALUE"""),"Zucchini-Paprika-Ratatouille") -> Zucchini-Paprika-Ratatouille | F18: =IFERROR(__xludf.DUMMYFUNCTION("""COMPUTED_VALUE"""),317.0) -> 317 | G18: =IFERROR(__xludf.DUMMYFUNCTION("""COMPUTED_VALUE"""),292.0) -> 292 | H18: =IFERROR(__xludf.DUMMYFUNCTION("""COMPUTED_VALUE"""),316.0) -> 316 | I18: =IFERROR(__xludf.DUMMYFUNCTION("""COMPUTED_VALUE"""),280.0) -> 280 | J18: =IFERROR(__xludf.DUMMYFUNCTION("""COMPUTED_VALUE"""),314.0) -> 314 | L18: =IFERROR(__xludf.DUMMYFUNCTION("""COMPUTED_VALUE"""),293.0) -> 293 | M18: =IFERROR(__xludf.DUMMYFUNCTION("""COMPUTED_VALUE"""),282.0) -> 282 | O18: =IFERROR(__xludf.DUMMYFUNCTION("""COMPUTED_VALUE"""),298.0) -> 298 | Q18: =IF(D18="","",D18&" - "&E18) -> 565141 - Zucchini-Paprika-Ratatouille | R18: =IFERROR(C18,"") -> CON-00-136634-3 | S18: =IFS(O18<>"",O18,AND(O18="",N18="",M18="",L18="",K18="",J18="",I18="",H18="",G18=""),F18,AND(O18="",N18="",M18="",L18="",K18="",J18="",I18="",H18=""),G18,AND(O18="",N18="",M18="",L18="",K18="",J18="",I18=""),H18,AND(O18="",N18="",M18="",L18="",K18="",J18=""), I18,AND(O18="",N18="",M18="",L18="",K18=""),J18,AND(O18="",N18="",M18="",L18=""), K18, AND(O18="",N18="",M18=""), L18,AND(O18="",N18=""), M18, AND(O18=""), N18) -> 298 | T18: =IFERROR(Q18,"") -> 565141 - Zucchini-Paprika-Ratatouille | U18: =IFERROR(ROUNDUP( XLOOKUP(T18,Q:Q,S:S),0.1),"") -> 298 | V18: =IF($U18="","","0") -> 0 | W18: =IF($U18="","","0") -> 0 | X18: =IF($U18="","","0") -> 0 | Y18: =IF($U18="","","0") -> 0 | AE18: =IF($B18="","", LEFT($B18,3)&"_1p") -> 310_1p | AF18: =IFERROR(T18,"") -> 565141 - Zucchini-Paprika-Ratatouille | AG18: =XLOOKUP(AF18,Q:Q,R:R) -> CON-00-136634-3 | AH18: =IF(AF18="","","ASL1") -> ASL1 | AJ18: =IF(AE18="","","1") -> 1 | AL18: =IF(AE18="","","Chilled") -> Chilled
A19: =IFERROR(__xludf.DUMMYFUNCTION("""COMPUTED_VALUE"""),"W19") -> W19 | B19: =IFERROR(__xludf.DUMMYFUNCTION("""COMPUTED_VALUE"""),311.0) -> 311 | C19: =IFERROR(__xludf.DUMMYFUNCTION("""COMPUTED_VALUE"""),"CON-00-136637-3") -> CON-00-136637-3 | D19: =IFERROR(__xludf.DUMMYFUNCTION("""COMPUTED_VALUE"""),"565143") -> 565143 | E19: =IFERROR(__xludf.DUMMYFUNCTION("""COMPUTED_VALUE"""),"Schweinefilet in cremiger Knoblauch-Senf-Sauce") -> Schweinefilet in cremiger Knoblauch-Senf-Sauce | F19: =IFERROR(__xludf.DUMMYFUNCTION("""COMPUTED_VALUE"""),419.0) -> 419 | G19: =IFERROR(__xludf.DUMMYFUNCTION("""COMPUTED_VALUE"""),315.0) -> 315 | H19: =IFERROR(__xludf.DUMMYFUNCTION("""COMPUTED_VALUE"""),344.0) -> 344 | I19: =IFERROR(__xludf.DUMMYFUNCTION("""COMPUTED_VALUE"""),464.0) -> 464 | J19: =IFERROR(__xludf.DUMMYFUNCTION("""COMPUTED_VALUE"""),606.0) -> 606 | L19: =IFERROR(__xludf.DUMMYFUNCTION("""COMPUTED_VALUE"""),598.0) -> 598 | M19: =IFERROR(__xludf.DUMMYFUNCTION("""COMPUTED_VALUE"""),626.0) -> 626 | O19: =IFERROR(__xludf.DUMMYFUNCTION("""COMPUTED_VALUE"""),517.0) -> 517 | Q19: =IF(D19="","",D19&" - "&E19) -> 565143 - Schweinefilet in cremiger Knoblauch-Senf-Sauce | R19: =IFERROR(C19,"") -> CON-00-136637-3 | S19: =IFS(O19<>"",O19,AND(O19="",N19="",M19="",L19="",K19="",J19="",I19="",H19="",G19=""),F19,AND(O19="",N19="",M19="",L19="",K19="",J19="",I19="",H19=""),G19,AND(O19="",N19="",M19="",L19="",K19="",J19="",I19=""),H19,AND(O19="",N19="",M19="",L19="",K19="",J19=""), I19,AND(O19="",N19="",M19="",L19="",K19=""),J19,AND(O19="",N19="",M19="",L19=""), K19, AND(O19="",N19="",M19=""), L19,AND(O19="",N19=""), M19, AND(O19=""), N19) -> 517 | T19: =IFERROR(Q19,"") -> 565143 - Schweinefilet in cremiger Knoblauch-Senf-Sauce | U19: =IFERROR(ROUNDUP( XLOOKUP(T19,Q:Q,S:S),0.1),"") -> 517 | V19: =IF($U19="","","0") -> 0 | W19: =IF($U19="","","0") -> 0 | X19: =IF($U19="","","0") -> 0 | Y19: =IF($U19="","","0") -> 0 | AE19: =IF($B19="","", LEFT($B19,3)&"_1p") -> 311_1p | AF19: =IFERROR(T19,"") -> 565143 - Schweinefilet in cremiger Knoblauch-Senf-Sauce | AG19: =XLOOKUP(AF19,Q:Q,R:R) -> CON-00-136637-3 | AH19: =IF(AF19="","","ASL1") -> ASL1 | AJ19: =IF(AE19="","","1") -> 1 | AL19: =IF(AE19="","","Chilled") -> Chilled
A20: =IFERROR(__xludf.DUMMYFUNCTION("""COMPUTED_VALUE"""),"W19") -> W19 | B20: =IFERROR(__xludf.DUMMYFUNCTION("""COMPUTED_VALUE"""),312.0) -> 312 | C20: =IFERROR(__xludf.DUMMYFUNCTION("""COMPUTED_VALUE"""),"CON-00-151278-2") -> CON-00-151278-2 | D20: =IFERROR(__xludf.DUMMYFUNCTION("""COMPUTED_VALUE"""),"565196") -> 565196 | E20: =IFERROR(__xludf.DUMMYFUNCTION("""COMPUTED_VALUE"""),"Ají Verde Lachs") -> Ají Verde Lachs | F20: =IFERROR(__xludf.DUMMYFUNCTION("""COMPUTED_VALUE"""),0.0) -> 0 | G20: =IFERROR(__xludf.DUMMYFUNCTION("""COMPUTED_VALUE"""),1272.0) -> 1272 | H20: =IFERROR(__xludf.DUMMYFUNCTION("""COMPUTED_VALUE"""),1396.0) -> 1396 | I20: =IFERROR(__xludf.DUMMYFUNCTION("""COMPUTED_VALUE"""),1217.0) -> 1217 | J20: =IFERROR(__xludf.DUMMYFUNCTION("""COMPUTED_VALUE"""),1282.0) -> 1282 | L20: =IFERROR(__xludf.DUMMYFUNCTION("""COMPUTED_VALUE"""),1282.0) -> 1282 | M20: =IFERROR(__xludf.DUMMYFUNCTION("""COMPUTED_VALUE"""),1238.0) -> 1238 | O20: =IFERROR(__xludf.DUMMYFUNCTION("""COMPUTED_VALUE"""),1180.0) -> 1180 | Q20: =IF(D20="","",D20&" - "&E20) -> 565196 - Ají Verde Lachs | R20: =IFERROR(C20,"") -> CON-00-151278-2 | S20: =IFS(O20<>"",O20,AND(O20="",N20="",M20="",L20="",K20="",J20="",I20="",H20="",G20=""),F20,AND(O20="",N20="",M20="",L20="",K20="",J20="",I20="",H20=""),G20,AND(O20="",N20="",M20="",L20="",K20="",J20="",I20=""),H20,AND(O20="",N20="",M20="",L20="",K20="",J20=""), I20,AND(O20="",N20="",M20="",L20="",K20=""),J20,AND(O20="",N20="",M20="",L20=""), K20, AND(O20="",N20="",M20=""), L20,AND(O20="",N20=""), M20, AND(O20=""), N20) -> 1180 | T20: =IFERROR(Q20,"") -> 565196 - Ají Verde Lachs | U20: =IFERROR(ROUNDUP( XLOOKUP(T20,Q:Q,S:S),0.1),"") -> 1180 | V20: =IF($U20="","","0") -> 0 | W20: =IF($U20="","","0") -> 0 | X20: =IF($U20="","","0") -> 0 | Y20: =IF($U20="","","0") -> 0 | AE20: =IF($B20="","", LEFT($B20,3)&"_1p") -> 312_1p | AF20: =IFERROR(T20,"") -> 565196 - Ají Verde Lachs | AG20: =XLOOKUP(AF20,Q:Q,R:R) -> CON-00-151278-2 | AH20: =IF(AF20="","","ASL1") -> ASL1 | AJ20: =IF(AE20="","","1") -> 1 | AL20: =IF(AE20="","","Chilled") -> Chilled
A21: =IFERROR(__xludf.DUMMYFUNCTION("""COMPUTED_VALUE"""),"W19") -> W19 | B21: =IFERROR(__xludf.DUMMYFUNCTION("""COMPUTED_VALUE"""),313.0) -> 313 | C21: =IFERROR(__xludf.DUMMYFUNCTION("""COMPUTED_VALUE"""),"CON-00-138152-2") -> CON-00-138152-2 | D21: =IFERROR(__xludf.DUMMYFUNCTION("""COMPUTED_VALUE"""),"565130") -> 565130 | E21: =IFERROR(__xludf.DUMMYFUNCTION("""COMPUTED_VALUE"""),"Pulled Pork mit roter Chilisauce") -> Pulled Pork mit roter Chilisauce | H21: =IFERROR(__xludf.DUMMYFUNCTION("""COMPUTED_VALUE"""),1536.0) -> 1536 | I21: =IFERROR(__xludf.DUMMYFUNCTION("""COMPUTED_VALUE"""),1163.0) -> 1163 | J21: =IFERROR(__xludf.DUMMYFUNCTION("""COMPUTED_VALUE"""),1313.0) -> 1313 | L21: =IFERROR(__xludf.DUMMYFUNCTION("""COMPUTED_VALUE"""),1276.0) -> 1276 | M21: =IFERROR(__xludf.DUMMYFUNCTION("""COMPUTED_VALUE"""),1272.0) -> 1272 | O21: =IFERROR(__xludf.DUMMYFUNCTION("""COMPUTED_VALUE"""),1195.0) -> 1195 | Q21: =IF(D21="","",D21&" - "&E21) -> 565130 - Pulled Pork mit roter Chilisauce | R21: =IFERROR(C21,"") -> CON-00-138152-2 | S21: =IFS(O21<>"",O21,AND(O21="",N21="",M21="",L21="",K21="",J21="",I21="",H21="",G21=""),F21,AND(O21="",N21="",M21="",L21="",K21="",J21="",I21="",H21=""),G21,AND(O21="",N21="",M21="",L21="",K21="",J21="",I21=""),H21,AND(O21="",N21="",M21="",L21="",K21="",J21=""), I21,AND(O21="",N21="",M21="",L21="",K21=""),J21,AND(O21="",N21="",M21="",L21=""), K21, AND(O21="",N21="",M21=""), L21,AND(O21="",N21=""), M21, AND(O21=""), N21) -> 1195 | T21: =IFERROR(Q21,"") -> 565130 - Pulled Pork mit roter Chilisauce | U21: =IFERROR(ROUNDUP( XLOOKUP(T21,Q:Q,S:S),0.1),"") -> 1195 | V21: =IF($U21="","","0") -> 0 | W21: =IF($U21="","","0") -> 0 | X21: =IF($U21="","","0") -> 0 | Y21: =IF($U21="","","0") -> 0 | AE21: =IF($B21="","", LEFT($B21,3)&"_1p") -> 313_1p | AF21: =IFERROR(T21,"") -> 565130 - Pulled Pork mit roter Chilisauce | AG21: =XLOOKUP(AF21,Q:Q,R:R) -> CON-00-138152-2 | AH21: =IF(AF21="","","ASL1") -> ASL1 | AJ21: =IF(AE21="","","1") -> 1 | AL21: =IF(AE21="","","Chilled") -> Chilled
A22: =IFERROR(__xludf.DUMMYFUNCTION("""COMPUTED_VALUE"""),"W19") -> W19 | B22: =IFERROR(__xludf.DUMMYFUNCTION("""COMPUTED_VALUE"""),314.0) -> 314 | C22: =IFERROR(__xludf.DUMMYFUNCTION("""COMPUTED_VALUE"""),"CON-00-152024-2") -> CON-00-152024-2 | D22: =IFERROR(__xludf.DUMMYFUNCTION("""COMPUTED_VALUE"""),"565211") -> 565211 | E22: =IFERROR(__xludf.DUMMYFUNCTION("""COMPUTED_VALUE"""),"Gegrilltes Hähnchen in Ingwer-Knoblauch-Marinade") -> Gegrilltes Hähnchen in Ingwer-Knoblauch-Marinade | H22: =IFERROR(__xludf.DUMMYFUNCTION("""COMPUTED_VALUE"""),749.0) -> 749 | I22: =IFERROR(__xludf.DUMMYFUNCTION("""COMPUTED_VALUE"""),547.0) -> 547 | J22: =IFERROR(__xludf.DUMMYFUNCTION("""COMPUTED_VALUE"""),668.0) -> 668 | L22: =IFERROR(__xludf.DUMMYFUNCTION("""COMPUTED_VALUE"""),670.0) -> 670 | M22: =IFERROR(__xludf.DUMMYFUNCTION("""COMPUTED_VALUE"""),694.0) -> 694 | O22: =IFERROR(__xludf.DUMMYFUNCTION("""COMPUTED_VALUE"""),627.0) -> 627 | Q22: =IF(D22="","",D22&" - "&E22) -> 565211 - Gegrilltes Hähnchen in Ingwer-Knoblauch-Marinade | R22: =IFERROR(C22,"") -> CON-00-152024-2 | S22: =IFS(O22<>"",O22,AND(O22="",N22="",M22="",L22="",K22="",J22="",I22="",H22="",G22=""),F22,AND(O22="",N22="",M22="",L22="",K22="",J22="",I22="",H22=""),G22,AND(O22="",N22="",M22="",L22="",K22="",J22="",I22=""),H22,AND(O22="",N22="",M22="",L22="",K22="",J22=""), I22,AND(O22="",N22="",M22="",L22="",K22=""),J22,AND(O22="",N22="",M22="",L22=""), K22, AND(O22="",N22="",M22=""), L22,AND(O22="",N22=""), M22, AND(O22=""), N22) -> 627 | T22: =IFERROR(Q22,"") -> 565211 - Gegrilltes Hähnchen in Ingwer-Knoblauch-Marinade | U22: =IFERROR(ROUNDUP( XLOOKUP(T22,Q:Q,S:S),0.1),"") -> 627 | V22: =IF($U22="","","0") -> 0 | W22: =IF($U22="","","0") -> 0 | X22: =IF($U22="","","0") -> 0 | Y22: =IF($U22="","","0") -> 0 | AE22: =IF($B22="","", LEFT($B22,3)&"_1p") -> 314_1p | AF22: =IFERROR(T22,"") -> 565211 - Gegrilltes Hähnchen in Ingwer-Knoblauch-Marinade | AG22: =XLOOKUP(AF22,Q:Q,R:R) -> CON-00-152024-2 | AH22: =IF(AF22="","","ASL1") -> ASL1 | AJ22: =IF(AE22="","","1") -> 1 | AL22: =IF(AE22="","","Chilled") -> Chilled
A23: =IFERROR(__xludf.DUMMYFUNCTION("""COMPUTED_VALUE"""),"W19") -> W19 | B23: =IFERROR(__xludf.DUMMYFUNCTION("""COMPUTED_VALUE"""),315.0) -> 315 | C23: =IFERROR(__xludf.DUMMYFUNCTION("""COMPUTED_VALUE"""),"CON-00-136694-3") -> CON-00-136694-3 | D23: =IFERROR(__xludf.DUMMYFUNCTION("""COMPUTED_VALUE"""),"565091") -> 565091 | E23: =IFERROR(__xludf.DUMMYFUNCTION("""COMPUTED_VALUE"""),"Scharfes Rinderhack mit Jalapeños") -> Scharfes Rinderhack mit Jalapeños | F23: =IFERROR(__xludf.DUMMYFUNCTION("""COMPUTED_VALUE"""),759.0) -> 759 | G23: =IFERROR(__xludf.DUMMYFUNCTION("""COMPUTED_VALUE"""),763.0) -> 763 | H23: =IFERROR(__xludf.DUMMYFUNCTION("""COMPUTED_VALUE"""),836.0) -> 836 | I23: =IFERROR(__xludf.DUMMYFUNCTION("""COMPUTED_VALUE"""),538.0) -> 538 | J23: =IFERROR(__xludf.DUMMYFUNCTION("""COMPUTED_VALUE"""),644.0) -> 644 | L23: =IFERROR(__xludf.DUMMYFUNCTION("""COMPUTED_VALUE"""),678.0) -> 678 | M23: =IFERROR(__xludf.DUMMYFUNCTION("""COMPUTED_VALUE"""),693.0) -> 693 | O23: =IFERROR(__xludf.DUMMYFUNCTION("""COMPUTED_VALUE"""),561.0) -> 561 | Q23: =IF(D23="","",D23&" - "&E23) -> 565091 - Scharfes Rinderhack mit Jalapeños | R23: =IFERROR(C23,"") -> CON-00-136694-3 | S23: =IFS(O23<>"",O23,AND(O23="",N23="",M23="",L23="",K23="",J23="",I23="",H23="",G23=""),F23,AND(O23="",N23="",M23="",L23="",K23="",J23="",I23="",H23=""),G23,AND(O23="",N23="",M23="",L23="",K23="",J23="",I23=""),H23,AND(O23="",N23="",M23="",L23="",K23="",J23=""), I23,AND(O23="",N23="",M23="",L23="",K23=""),J23,AND(O23="",N23="",M23="",L23=""), K23, AND(O23="",N23="",M23=""), L23,AND(O23="",N23=""), M23, AND(O23=""), N23) -> 561 | T23: =IFERROR(Q23,"") -> 565091 - Scharfes Rinderhack mit Jalapeños | U23: =IFERROR(ROUNDUP( XLOOKUP(T23,Q:Q,S:S),0.1),"") -> 561 | V23: =IF($U23="","","0") -> 0 | W23: =IF($U23="","","0") -> 0 | X23: =IF($U23="","","0") -> 0 | Y23: =IF($U23="","","0") -> 0 | AE23: =IF($B23="","", LEFT($B23,3)&"_1p") -> 315_1p | AF23: =IFERROR(T23,"") -> 565091 - Scharfes Rinderhack mit Jalapeños | AG23: =XLOOKUP(AF23,Q:Q,R:R) -> CON-00-136694-3 | AH23: =IF(AF23="","","ASL1") -> ASL1 | AJ23: =IF(AE23="","","1") -> 1 | AL23: =IF(AE23="","","Chilled") -> Chilled
A24: =IFERROR(__xludf.DUMMYFUNCTION("""COMPUTED_VALUE"""),"W19") -> W19 | B24: =IFERROR(__xludf.DUMMYFUNCTION("""COMPUTED_VALUE"""),316.0) -> 316 | C24: =IFERROR(__xludf.DUMMYFUNCTION("""COMPUTED_VALUE"""),"CON-00-154547-2") -> CON-00-154547-2 | D24: =IFERROR(__xludf.DUMMYFUNCTION("""COMPUTED_VALUE"""),"565221") -> 565221 | E24: =IFERROR(__xludf.DUMMYFUNCTION("""COMPUTED_VALUE"""),"Lachs-Bowl mit Zitrus-Miso") -> Lachs-Bowl mit Zitrus-Miso | H24: =IFERROR(__xludf.DUMMYFUNCTION("""COMPUTED_VALUE"""),533.0) -> 533 | I24: =IFERROR(__xludf.DUMMYFUNCTION("""COMPUTED_VALUE"""),727.0) -> 727 | J24: =IFERROR(__xludf.DUMMYFUNCTION("""COMPUTED_VALUE"""),810.0) -> 810 | L24: =IFERROR(__xludf.DUMMYFUNCTION("""COMPUTED_VALUE"""),773.0) -> 773 | M24: =IFERROR(__xludf.DUMMYFUNCTION("""COMPUTED_VALUE"""),773.0) -> 773 | O24: =IFERROR(__xludf.DUMMYFUNCTION("""COMPUTED_VALUE"""),695.0) -> 695 | Q24: =IF(D24="","",D24&" - "&E24) -> 565221 - Lachs-Bowl mit Zitrus-Miso | R24: =IFERROR(C24,"") -> CON-00-154547-2 | S24: =IFS(O24<>"",O24,AND(O24="",N24="",M24="",L24="",K24="",J24="",I24="",H24="",G24=""),F24,AND(O24="",N24="",M24="",L24="",K24="",J24="",I24="",H24=""),G24,AND(O24="",N24="",M24="",L24="",K24="",J24="",I24=""),H24,AND(O24="",N24="",M24="",L24="",K24="",J24=""), I24,AND(O24="",N24="",M24="",L24="",K24=""),J24,AND(O24="",N24="",M24="",L24=""), K24, AND(O24="",N24="",M24=""), L24,AND(O24="",N24=""), M24, AND(O24=""), N24) -> 695 | T24: =IFERROR(Q24,"") -> 565221 - Lachs-Bowl mit Zitrus-Miso | U24: =IFERROR(ROUNDUP( XLOOKUP(T24,Q:Q,S:S),0.1),"") -> 695 | V24: =IF($U24="","","0") -> 0 | W24: =IF($U24="","","0") -> 0 | X24: =IF($U24="","","0") -> 0 | Y24: =IF($U24="","","0") -> 0 | AE24: =IF($B24="","", LEFT($B24,3)&"_1p") -> 316_1p | AF24: =IFERROR(T24,"") -> 565221 - Lachs-Bowl mit Zitrus-Miso | AG24: =XLOOKUP(AF24,Q:Q,R:R) -> CON-00-154547-2 | AH24: =IF(AF24="","","ASL1") -> ASL1 | AJ24: =IF(AE24="","","1") -> 1 | AL24: =IF(AE24="","","Chilled") -> Chilled
